[2025-06-11T06:52:12.396+0000] {processor.py:186} INFO - Started process (PID=1046) to work on /opt/airflow/dags/create_postgres_app.py
[2025-06-11T06:52:12.399+0000] {processor.py:914} INFO - Processing file /opt/airflow/dags/create_postgres_app.py for tasks to queue
[2025-06-11T06:52:12.405+0000] {logging_mixin.py:190} INFO - [2025-06-11T06:52:12.404+0000] {dagbag.py:588} INFO - Filling up the DagBag from /opt/airflow/dags/create_postgres_app.py
[2025-06-11T06:52:12.467+0000] {logging_mixin.py:190} INFO - [2025-06-11T06:52:12.452+0000] {dagbag.py:387} ERROR - Failed to import: /opt/airflow/dags/create_postgres_app.py
Traceback (most recent call last):
  File "/home/airflow/.local/lib/python3.12/site-packages/airflow/models/dagbag.py", line 383, in parse
    loader.exec_module(new_module)
  File "<frozen importlib._bootstrap_external>", line 995, in exec_module
  File "<frozen importlib._bootstrap>", line 488, in _call_with_frames_removed
  File "/opt/airflow/dags/create_postgres_app.py", line 8, in <module>
    'start_date': datetime(2025, 6, 11),
                  ^^^^^^^^^^^^^^^^^^^^^
TypeError: 'module' object is not callable. Did you mean: 'datetime.datetime(...)'?
[2025-06-11T06:52:12.472+0000] {processor.py:927} WARNING - No viable dags retrieved from /opt/airflow/dags/create_postgres_app.py
[2025-06-11T06:52:12.547+0000] {processor.py:208} INFO - Processing /opt/airflow/dags/create_postgres_app.py took 0.168 seconds
[2025-06-11T06:52:44.012+0000] {processor.py:186} INFO - Started process (PID=1058) to work on /opt/airflow/dags/create_postgres_app.py
[2025-06-11T06:52:44.039+0000] {processor.py:914} INFO - Processing file /opt/airflow/dags/create_postgres_app.py for tasks to queue
[2025-06-11T06:52:44.061+0000] {logging_mixin.py:190} INFO - [2025-06-11T06:52:44.059+0000] {dagbag.py:588} INFO - Filling up the DagBag from /opt/airflow/dags/create_postgres_app.py
[2025-06-11T06:52:44.984+0000] {logging_mixin.py:190} INFO - [2025-06-11T06:52:44.897+0000] {dagbag.py:387} ERROR - Failed to import: /opt/airflow/dags/create_postgres_app.py
Traceback (most recent call last):
  File "/home/airflow/.local/lib/python3.12/site-packages/airflow/models/dagbag.py", line 383, in parse
    loader.exec_module(new_module)
  File "<frozen importlib._bootstrap_external>", line 995, in exec_module
  File "<frozen importlib._bootstrap>", line 488, in _call_with_frames_removed
  File "/opt/airflow/dags/create_postgres_app.py", line 8, in <module>
    'start_date': datetime(2025, 6, 11),
                  ^^^^^^^^^^^^^^^^^^^^^
TypeError: 'module' object is not callable. Did you mean: 'datetime.datetime(...)'?
[2025-06-11T06:52:44.996+0000] {processor.py:927} WARNING - No viable dags retrieved from /opt/airflow/dags/create_postgres_app.py
[2025-06-11T06:52:45.169+0000] {processor.py:208} INFO - Processing /opt/airflow/dags/create_postgres_app.py took 1.224 seconds
[2025-06-11T06:53:15.921+0000] {processor.py:186} INFO - Started process (PID=1070) to work on /opt/airflow/dags/create_postgres_app.py
[2025-06-11T06:53:15.925+0000] {processor.py:914} INFO - Processing file /opt/airflow/dags/create_postgres_app.py for tasks to queue
[2025-06-11T06:53:15.941+0000] {logging_mixin.py:190} INFO - [2025-06-11T06:53:15.940+0000] {dagbag.py:588} INFO - Filling up the DagBag from /opt/airflow/dags/create_postgres_app.py
[2025-06-11T06:53:16.018+0000] {logging_mixin.py:190} INFO - [2025-06-11T06:53:15.984+0000] {dagbag.py:387} ERROR - Failed to import: /opt/airflow/dags/create_postgres_app.py
Traceback (most recent call last):
  File "/home/airflow/.local/lib/python3.12/site-packages/airflow/models/dagbag.py", line 383, in parse
    loader.exec_module(new_module)
  File "<frozen importlib._bootstrap_external>", line 995, in exec_module
  File "<frozen importlib._bootstrap>", line 488, in _call_with_frames_removed
  File "/opt/airflow/dags/create_postgres_app.py", line 8, in <module>
    'start_date': datetime(2025, 6, 11),
                  ^^^^^^^^^^^^^^^^^^^^^
TypeError: 'module' object is not callable. Did you mean: 'datetime.datetime(...)'?
[2025-06-11T06:53:16.026+0000] {processor.py:927} WARNING - No viable dags retrieved from /opt/airflow/dags/create_postgres_app.py
[2025-06-11T06:53:16.115+0000] {processor.py:208} INFO - Processing /opt/airflow/dags/create_postgres_app.py took 0.240 seconds
[2025-06-11T06:53:46.745+0000] {processor.py:186} INFO - Started process (PID=1080) to work on /opt/airflow/dags/create_postgres_app.py
[2025-06-11T06:53:46.750+0000] {processor.py:914} INFO - Processing file /opt/airflow/dags/create_postgres_app.py for tasks to queue
[2025-06-11T06:53:46.768+0000] {logging_mixin.py:190} INFO - [2025-06-11T06:53:46.767+0000] {dagbag.py:588} INFO - Filling up the DagBag from /opt/airflow/dags/create_postgres_app.py
[2025-06-11T06:53:46.978+0000] {logging_mixin.py:190} INFO - [2025-06-11T06:53:46.962+0000] {dagbag.py:387} ERROR - Failed to import: /opt/airflow/dags/create_postgres_app.py
Traceback (most recent call last):
  File "/home/airflow/.local/lib/python3.12/site-packages/airflow/models/dagbag.py", line 383, in parse
    loader.exec_module(new_module)
  File "<frozen importlib._bootstrap_external>", line 995, in exec_module
  File "<frozen importlib._bootstrap>", line 488, in _call_with_frames_removed
  File "/opt/airflow/dags/create_postgres_app.py", line 8, in <module>
    'start_date': datetime(2025, 6, 11),
                  ^^^^^^^^^^^^^^^^^^^^^
TypeError: 'module' object is not callable. Did you mean: 'datetime.datetime(...)'?
[2025-06-11T06:53:46.989+0000] {processor.py:927} WARNING - No viable dags retrieved from /opt/airflow/dags/create_postgres_app.py
[2025-06-11T06:53:47.093+0000] {processor.py:208} INFO - Processing /opt/airflow/dags/create_postgres_app.py took 0.381 seconds
[2025-06-11T06:54:18.179+0000] {processor.py:186} INFO - Started process (PID=1092) to work on /opt/airflow/dags/create_postgres_app.py
[2025-06-11T06:54:18.188+0000] {processor.py:914} INFO - Processing file /opt/airflow/dags/create_postgres_app.py for tasks to queue
[2025-06-11T06:54:18.210+0000] {logging_mixin.py:190} INFO - [2025-06-11T06:54:18.209+0000] {dagbag.py:588} INFO - Filling up the DagBag from /opt/airflow/dags/create_postgres_app.py
[2025-06-11T06:54:18.380+0000] {logging_mixin.py:190} INFO - [2025-06-11T06:54:18.342+0000] {dagbag.py:387} ERROR - Failed to import: /opt/airflow/dags/create_postgres_app.py
Traceback (most recent call last):
  File "/home/airflow/.local/lib/python3.12/site-packages/airflow/models/dagbag.py", line 383, in parse
    loader.exec_module(new_module)
  File "<frozen importlib._bootstrap_external>", line 995, in exec_module
  File "<frozen importlib._bootstrap>", line 488, in _call_with_frames_removed
  File "/opt/airflow/dags/create_postgres_app.py", line 8, in <module>
    'start_date': datetime(2025, 6, 11),
                  ^^^^^^^^^^^^^^^^^^^^^
TypeError: 'module' object is not callable. Did you mean: 'datetime.datetime(...)'?
[2025-06-11T06:54:18.397+0000] {processor.py:927} WARNING - No viable dags retrieved from /opt/airflow/dags/create_postgres_app.py
[2025-06-11T06:54:18.515+0000] {processor.py:208} INFO - Processing /opt/airflow/dags/create_postgres_app.py took 0.391 seconds
[2025-06-11T06:54:49.087+0000] {processor.py:186} INFO - Started process (PID=1104) to work on /opt/airflow/dags/create_postgres_app.py
[2025-06-11T06:54:49.091+0000] {processor.py:914} INFO - Processing file /opt/airflow/dags/create_postgres_app.py for tasks to queue
[2025-06-11T06:54:49.099+0000] {logging_mixin.py:190} INFO - [2025-06-11T06:54:49.098+0000] {dagbag.py:588} INFO - Filling up the DagBag from /opt/airflow/dags/create_postgres_app.py
[2025-06-11T06:54:49.150+0000] {logging_mixin.py:190} INFO - [2025-06-11T06:54:49.132+0000] {dagbag.py:387} ERROR - Failed to import: /opt/airflow/dags/create_postgres_app.py
Traceback (most recent call last):
  File "/home/airflow/.local/lib/python3.12/site-packages/airflow/models/dagbag.py", line 383, in parse
    loader.exec_module(new_module)
  File "<frozen importlib._bootstrap_external>", line 995, in exec_module
  File "<frozen importlib._bootstrap>", line 488, in _call_with_frames_removed
  File "/opt/airflow/dags/create_postgres_app.py", line 8, in <module>
    'start_date': datetime(2025, 6, 11),
                  ^^^^^^^^^^^^^^^^^^^^^
TypeError: 'module' object is not callable. Did you mean: 'datetime.datetime(...)'?
[2025-06-11T06:54:49.154+0000] {processor.py:927} WARNING - No viable dags retrieved from /opt/airflow/dags/create_postgres_app.py
[2025-06-11T06:54:49.216+0000] {processor.py:208} INFO - Processing /opt/airflow/dags/create_postgres_app.py took 0.175 seconds
[2025-06-11T06:55:19.608+0000] {processor.py:186} INFO - Started process (PID=1116) to work on /opt/airflow/dags/create_postgres_app.py
[2025-06-11T06:55:19.611+0000] {processor.py:914} INFO - Processing file /opt/airflow/dags/create_postgres_app.py for tasks to queue
[2025-06-11T06:55:19.619+0000] {logging_mixin.py:190} INFO - [2025-06-11T06:55:19.618+0000] {dagbag.py:588} INFO - Filling up the DagBag from /opt/airflow/dags/create_postgres_app.py
[2025-06-11T06:55:19.655+0000] {logging_mixin.py:190} INFO - [2025-06-11T06:55:19.645+0000] {dagbag.py:387} ERROR - Failed to import: /opt/airflow/dags/create_postgres_app.py
Traceback (most recent call last):
  File "/home/airflow/.local/lib/python3.12/site-packages/airflow/models/dagbag.py", line 383, in parse
    loader.exec_module(new_module)
  File "<frozen importlib._bootstrap_external>", line 995, in exec_module
  File "<frozen importlib._bootstrap>", line 488, in _call_with_frames_removed
  File "/opt/airflow/dags/create_postgres_app.py", line 8, in <module>
    'start_date': datetime(2025, 6, 11),
                  ^^^^^^^^^^^^^^^^^^^^^
TypeError: 'module' object is not callable. Did you mean: 'datetime.datetime(...)'?
[2025-06-11T06:55:19.659+0000] {processor.py:927} WARNING - No viable dags retrieved from /opt/airflow/dags/create_postgres_app.py
[2025-06-11T06:55:19.727+0000] {processor.py:208} INFO - Processing /opt/airflow/dags/create_postgres_app.py took 0.140 seconds
[2025-06-11T06:55:49.898+0000] {processor.py:186} INFO - Started process (PID=1128) to work on /opt/airflow/dags/create_postgres_app.py
[2025-06-11T06:55:49.901+0000] {processor.py:914} INFO - Processing file /opt/airflow/dags/create_postgres_app.py for tasks to queue
[2025-06-11T06:55:49.910+0000] {logging_mixin.py:190} INFO - [2025-06-11T06:55:49.909+0000] {dagbag.py:588} INFO - Filling up the DagBag from /opt/airflow/dags/create_postgres_app.py
[2025-06-11T06:55:49.957+0000] {logging_mixin.py:190} INFO - [2025-06-11T06:55:49.945+0000] {dagbag.py:387} ERROR - Failed to import: /opt/airflow/dags/create_postgres_app.py
Traceback (most recent call last):
  File "/home/airflow/.local/lib/python3.12/site-packages/airflow/models/dagbag.py", line 383, in parse
    loader.exec_module(new_module)
  File "<frozen importlib._bootstrap_external>", line 995, in exec_module
  File "<frozen importlib._bootstrap>", line 488, in _call_with_frames_removed
  File "/opt/airflow/dags/create_postgres_app.py", line 8, in <module>
    'start_date': datetime(2025, 6, 11),
                  ^^^^^^^^^^^^^^^^^^^^^
TypeError: 'module' object is not callable. Did you mean: 'datetime.datetime(...)'?
[2025-06-11T06:55:49.961+0000] {processor.py:927} WARNING - No viable dags retrieved from /opt/airflow/dags/create_postgres_app.py
[2025-06-11T06:55:50.019+0000] {processor.py:208} INFO - Processing /opt/airflow/dags/create_postgres_app.py took 0.140 seconds
[2025-06-11T06:56:03.148+0000] {processor.py:186} INFO - Started process (PID=1131) to work on /opt/airflow/dags/create_postgres_app.py
[2025-06-11T06:56:03.152+0000] {processor.py:914} INFO - Processing file /opt/airflow/dags/create_postgres_app.py for tasks to queue
[2025-06-11T06:56:03.162+0000] {logging_mixin.py:190} INFO - [2025-06-11T06:56:03.161+0000] {dagbag.py:588} INFO - Filling up the DagBag from /opt/airflow/dags/create_postgres_app.py
[2025-06-11T06:56:03.240+0000] {logging_mixin.py:190} INFO - [2025-06-11T06:56:03.227+0000] {dagbag.py:387} ERROR - Failed to import: /opt/airflow/dags/create_postgres_app.py
Traceback (most recent call last):
  File "/home/airflow/.local/lib/python3.12/site-packages/airflow/models/dagbag.py", line 383, in parse
    loader.exec_module(new_module)
  File "<frozen importlib._bootstrap_external>", line 995, in exec_module
  File "<frozen importlib._bootstrap>", line 488, in _call_with_frames_removed
  File "/opt/airflow/dags/create_postgres_app.py", line 8, in <module>
    'start_date': datetime(2025, 6, 11),
                  ^^^^^^^^^^^^^^^^^^^^^
TypeError: 'module' object is not callable. Did you mean: 'datetime.datetime(...)'?
[2025-06-11T06:56:03.244+0000] {processor.py:927} WARNING - No viable dags retrieved from /opt/airflow/dags/create_postgres_app.py
[2025-06-11T06:56:03.307+0000] {processor.py:208} INFO - Processing /opt/airflow/dags/create_postgres_app.py took 0.185 seconds
[2025-06-11T06:56:33.969+0000] {processor.py:186} INFO - Started process (PID=1144) to work on /opt/airflow/dags/create_postgres_app.py
[2025-06-11T06:56:33.975+0000] {processor.py:914} INFO - Processing file /opt/airflow/dags/create_postgres_app.py for tasks to queue
[2025-06-11T06:56:33.986+0000] {logging_mixin.py:190} INFO - [2025-06-11T06:56:33.985+0000] {dagbag.py:588} INFO - Filling up the DagBag from /opt/airflow/dags/create_postgres_app.py
[2025-06-11T06:56:34.049+0000] {logging_mixin.py:190} INFO - [2025-06-11T06:56:34.034+0000] {dagbag.py:387} ERROR - Failed to import: /opt/airflow/dags/create_postgres_app.py
Traceback (most recent call last):
  File "/home/airflow/.local/lib/python3.12/site-packages/airflow/models/dagbag.py", line 383, in parse
    loader.exec_module(new_module)
  File "<frozen importlib._bootstrap_external>", line 995, in exec_module
  File "<frozen importlib._bootstrap>", line 488, in _call_with_frames_removed
  File "/opt/airflow/dags/create_postgres_app.py", line 8, in <module>
    'start_date': datetime(2025, 6, 11),
                  ^^^^^^^^^^^^^^^^^^^^^
TypeError: 'module' object is not callable. Did you mean: 'datetime.datetime(...)'?
[2025-06-11T06:56:34.054+0000] {processor.py:927} WARNING - No viable dags retrieved from /opt/airflow/dags/create_postgres_app.py
[2025-06-11T06:56:34.195+0000] {processor.py:208} INFO - Processing /opt/airflow/dags/create_postgres_app.py took 0.270 seconds
[2025-06-11T06:57:04.825+0000] {processor.py:186} INFO - Started process (PID=1156) to work on /opt/airflow/dags/create_postgres_app.py
[2025-06-11T06:57:04.829+0000] {processor.py:914} INFO - Processing file /opt/airflow/dags/create_postgres_app.py for tasks to queue
[2025-06-11T06:57:04.840+0000] {logging_mixin.py:190} INFO - [2025-06-11T06:57:04.838+0000] {dagbag.py:588} INFO - Filling up the DagBag from /opt/airflow/dags/create_postgres_app.py
[2025-06-11T06:57:04.955+0000] {logging_mixin.py:190} INFO - [2025-06-11T06:57:04.919+0000] {dagbag.py:387} ERROR - Failed to import: /opt/airflow/dags/create_postgres_app.py
Traceback (most recent call last):
  File "/home/airflow/.local/lib/python3.12/site-packages/airflow/models/dagbag.py", line 383, in parse
    loader.exec_module(new_module)
  File "<frozen importlib._bootstrap_external>", line 995, in exec_module
  File "<frozen importlib._bootstrap>", line 488, in _call_with_frames_removed
  File "/opt/airflow/dags/create_postgres_app.py", line 8, in <module>
    'start_date': datetime(2025, 6, 11),
                  ^^^^^^^^^^^^^^^^^^^^^
TypeError: 'module' object is not callable. Did you mean: 'datetime.datetime(...)'?
[2025-06-11T06:57:04.960+0000] {processor.py:927} WARNING - No viable dags retrieved from /opt/airflow/dags/create_postgres_app.py
[2025-06-11T06:57:05.071+0000] {processor.py:208} INFO - Processing /opt/airflow/dags/create_postgres_app.py took 0.276 seconds
[2025-06-11T06:57:36.929+0000] {processor.py:186} INFO - Started process (PID=1175) to work on /opt/airflow/dags/create_postgres_app.py
[2025-06-11T06:57:37.008+0000] {processor.py:914} INFO - Processing file /opt/airflow/dags/create_postgres_app.py for tasks to queue
[2025-06-11T06:57:37.108+0000] {logging_mixin.py:190} INFO - [2025-06-11T06:57:37.107+0000] {dagbag.py:588} INFO - Filling up the DagBag from /opt/airflow/dags/create_postgres_app.py
[2025-06-11T06:57:37.426+0000] {logging_mixin.py:190} INFO - [2025-06-11T06:57:37.357+0000] {dagbag.py:387} ERROR - Failed to import: /opt/airflow/dags/create_postgres_app.py
Traceback (most recent call last):
  File "/home/airflow/.local/lib/python3.12/site-packages/airflow/models/dagbag.py", line 383, in parse
    loader.exec_module(new_module)
  File "<frozen importlib._bootstrap_external>", line 995, in exec_module
  File "<frozen importlib._bootstrap>", line 488, in _call_with_frames_removed
  File "/opt/airflow/dags/create_postgres_app.py", line 8, in <module>
    'start_date': datetime(2025, 6, 11),
                  ^^^^^^^^^^^^^^^^^^^^^
TypeError: 'module' object is not callable. Did you mean: 'datetime.datetime(...)'?
[2025-06-11T06:57:37.447+0000] {processor.py:927} WARNING - No viable dags retrieved from /opt/airflow/dags/create_postgres_app.py
[2025-06-11T06:57:37.721+0000] {processor.py:208} INFO - Processing /opt/airflow/dags/create_postgres_app.py took 0.976 seconds
[2025-06-11T06:58:08.328+0000] {processor.py:186} INFO - Started process (PID=1188) to work on /opt/airflow/dags/create_postgres_app.py
[2025-06-11T06:58:08.331+0000] {processor.py:914} INFO - Processing file /opt/airflow/dags/create_postgres_app.py for tasks to queue
[2025-06-11T06:58:08.337+0000] {logging_mixin.py:190} INFO - [2025-06-11T06:58:08.336+0000] {dagbag.py:588} INFO - Filling up the DagBag from /opt/airflow/dags/create_postgres_app.py
[2025-06-11T06:58:08.379+0000] {logging_mixin.py:190} INFO - [2025-06-11T06:58:08.369+0000] {dagbag.py:387} ERROR - Failed to import: /opt/airflow/dags/create_postgres_app.py
Traceback (most recent call last):
  File "/home/airflow/.local/lib/python3.12/site-packages/airflow/models/dagbag.py", line 383, in parse
    loader.exec_module(new_module)
  File "<frozen importlib._bootstrap_external>", line 995, in exec_module
  File "<frozen importlib._bootstrap>", line 488, in _call_with_frames_removed
  File "/opt/airflow/dags/create_postgres_app.py", line 8, in <module>
    'start_date': datetime(2025, 6, 11),
                  ^^^^^^^^^^^^^^^^^^^^^
TypeError: 'module' object is not callable. Did you mean: 'datetime.datetime(...)'?
[2025-06-11T06:58:08.382+0000] {processor.py:927} WARNING - No viable dags retrieved from /opt/airflow/dags/create_postgres_app.py
[2025-06-11T06:58:08.428+0000] {processor.py:208} INFO - Processing /opt/airflow/dags/create_postgres_app.py took 0.114 seconds
[2025-06-11T06:58:38.675+0000] {processor.py:186} INFO - Started process (PID=1200) to work on /opt/airflow/dags/create_postgres_app.py
[2025-06-11T06:58:38.677+0000] {processor.py:914} INFO - Processing file /opt/airflow/dags/create_postgres_app.py for tasks to queue
[2025-06-11T06:58:38.685+0000] {logging_mixin.py:190} INFO - [2025-06-11T06:58:38.684+0000] {dagbag.py:588} INFO - Filling up the DagBag from /opt/airflow/dags/create_postgres_app.py
[2025-06-11T06:58:38.731+0000] {logging_mixin.py:190} INFO - [2025-06-11T06:58:38.713+0000] {dagbag.py:387} ERROR - Failed to import: /opt/airflow/dags/create_postgres_app.py
Traceback (most recent call last):
  File "/home/airflow/.local/lib/python3.12/site-packages/airflow/models/dagbag.py", line 383, in parse
    loader.exec_module(new_module)
  File "<frozen importlib._bootstrap_external>", line 995, in exec_module
  File "<frozen importlib._bootstrap>", line 488, in _call_with_frames_removed
  File "/opt/airflow/dags/create_postgres_app.py", line 8, in <module>
    'start_date': datetime(2025, 6, 11),
                  ^^^^^^^^^^^^^^^^^^^^^
TypeError: 'module' object is not callable. Did you mean: 'datetime.datetime(...)'?
[2025-06-11T06:58:38.736+0000] {processor.py:927} WARNING - No viable dags retrieved from /opt/airflow/dags/create_postgres_app.py
[2025-06-11T06:58:38.810+0000] {processor.py:208} INFO - Processing /opt/airflow/dags/create_postgres_app.py took 0.156 seconds
[2025-06-11T06:59:09.468+0000] {processor.py:186} INFO - Started process (PID=1210) to work on /opt/airflow/dags/create_postgres_app.py
[2025-06-11T06:59:09.471+0000] {processor.py:914} INFO - Processing file /opt/airflow/dags/create_postgres_app.py for tasks to queue
[2025-06-11T06:59:09.479+0000] {logging_mixin.py:190} INFO - [2025-06-11T06:59:09.478+0000] {dagbag.py:588} INFO - Filling up the DagBag from /opt/airflow/dags/create_postgres_app.py
[2025-06-11T06:59:09.521+0000] {logging_mixin.py:190} INFO - [2025-06-11T06:59:09.511+0000] {dagbag.py:387} ERROR - Failed to import: /opt/airflow/dags/create_postgres_app.py
Traceback (most recent call last):
  File "/home/airflow/.local/lib/python3.12/site-packages/airflow/models/dagbag.py", line 383, in parse
    loader.exec_module(new_module)
  File "<frozen importlib._bootstrap_external>", line 995, in exec_module
  File "<frozen importlib._bootstrap>", line 488, in _call_with_frames_removed
  File "/opt/airflow/dags/create_postgres_app.py", line 8, in <module>
    'start_date': datetime(2025, 6, 11),
                  ^^^^^^^^^^^^^^^^^^^^^
TypeError: 'module' object is not callable. Did you mean: 'datetime.datetime(...)'?
[2025-06-11T06:59:09.524+0000] {processor.py:927} WARNING - No viable dags retrieved from /opt/airflow/dags/create_postgres_app.py
[2025-06-11T06:59:09.587+0000] {processor.py:208} INFO - Processing /opt/airflow/dags/create_postgres_app.py took 0.147 seconds
[2025-06-11T06:59:40.459+0000] {processor.py:186} INFO - Started process (PID=1222) to work on /opt/airflow/dags/create_postgres_app.py
[2025-06-11T06:59:40.463+0000] {processor.py:914} INFO - Processing file /opt/airflow/dags/create_postgres_app.py for tasks to queue
[2025-06-11T06:59:40.471+0000] {logging_mixin.py:190} INFO - [2025-06-11T06:59:40.470+0000] {dagbag.py:588} INFO - Filling up the DagBag from /opt/airflow/dags/create_postgres_app.py
[2025-06-11T06:59:40.525+0000] {logging_mixin.py:190} INFO - [2025-06-11T06:59:40.511+0000] {dagbag.py:387} ERROR - Failed to import: /opt/airflow/dags/create_postgres_app.py
Traceback (most recent call last):
  File "/home/airflow/.local/lib/python3.12/site-packages/airflow/models/dagbag.py", line 383, in parse
    loader.exec_module(new_module)
  File "<frozen importlib._bootstrap_external>", line 995, in exec_module
  File "<frozen importlib._bootstrap>", line 488, in _call_with_frames_removed
  File "/opt/airflow/dags/create_postgres_app.py", line 8, in <module>
    'start_date': datetime(2025, 6, 11),
                  ^^^^^^^^^^^^^^^^^^^^^
TypeError: 'module' object is not callable. Did you mean: 'datetime.datetime(...)'?
[2025-06-11T06:59:40.530+0000] {processor.py:927} WARNING - No viable dags retrieved from /opt/airflow/dags/create_postgres_app.py
[2025-06-11T06:59:40.598+0000] {processor.py:208} INFO - Processing /opt/airflow/dags/create_postgres_app.py took 0.161 seconds
[2025-06-11T07:00:11.235+0000] {processor.py:186} INFO - Started process (PID=1234) to work on /opt/airflow/dags/create_postgres_app.py
[2025-06-11T07:00:11.238+0000] {processor.py:914} INFO - Processing file /opt/airflow/dags/create_postgres_app.py for tasks to queue
[2025-06-11T07:00:11.245+0000] {logging_mixin.py:190} INFO - [2025-06-11T07:00:11.244+0000] {dagbag.py:588} INFO - Filling up the DagBag from /opt/airflow/dags/create_postgres_app.py
[2025-06-11T07:00:11.282+0000] {logging_mixin.py:190} INFO - [2025-06-11T07:00:11.273+0000] {dagbag.py:387} ERROR - Failed to import: /opt/airflow/dags/create_postgres_app.py
Traceback (most recent call last):
  File "/home/airflow/.local/lib/python3.12/site-packages/airflow/models/dagbag.py", line 383, in parse
    loader.exec_module(new_module)
  File "<frozen importlib._bootstrap_external>", line 995, in exec_module
  File "<frozen importlib._bootstrap>", line 488, in _call_with_frames_removed
  File "/opt/airflow/dags/create_postgres_app.py", line 8, in <module>
    'start_date': datetime(2025, 6, 11),
                  ^^^^^^^^^^^^^^^^^^^^^
TypeError: 'module' object is not callable. Did you mean: 'datetime.datetime(...)'?
[2025-06-11T07:00:11.286+0000] {processor.py:927} WARNING - No viable dags retrieved from /opt/airflow/dags/create_postgres_app.py
[2025-06-11T07:00:11.353+0000] {processor.py:208} INFO - Processing /opt/airflow/dags/create_postgres_app.py took 0.136 seconds
[2025-06-11T07:00:41.564+0000] {processor.py:186} INFO - Started process (PID=1246) to work on /opt/airflow/dags/create_postgres_app.py
[2025-06-11T07:00:41.568+0000] {processor.py:914} INFO - Processing file /opt/airflow/dags/create_postgres_app.py for tasks to queue
[2025-06-11T07:00:41.578+0000] {logging_mixin.py:190} INFO - [2025-06-11T07:00:41.577+0000] {dagbag.py:588} INFO - Filling up the DagBag from /opt/airflow/dags/create_postgres_app.py
[2025-06-11T07:00:41.626+0000] {logging_mixin.py:190} INFO - [2025-06-11T07:00:41.615+0000] {dagbag.py:387} ERROR - Failed to import: /opt/airflow/dags/create_postgres_app.py
Traceback (most recent call last):
  File "/home/airflow/.local/lib/python3.12/site-packages/airflow/models/dagbag.py", line 383, in parse
    loader.exec_module(new_module)
  File "<frozen importlib._bootstrap_external>", line 995, in exec_module
  File "<frozen importlib._bootstrap>", line 488, in _call_with_frames_removed
  File "/opt/airflow/dags/create_postgres_app.py", line 8, in <module>
    'start_date': datetime(2025, 6, 11),
                  ^^^^^^^^^^^^^^^^^^^^^
TypeError: 'module' object is not callable. Did you mean: 'datetime.datetime(...)'?
[2025-06-11T07:00:41.630+0000] {processor.py:927} WARNING - No viable dags retrieved from /opt/airflow/dags/create_postgres_app.py
[2025-06-11T07:00:41.709+0000] {processor.py:208} INFO - Processing /opt/airflow/dags/create_postgres_app.py took 0.163 seconds
[2025-06-11T07:01:12.051+0000] {processor.py:186} INFO - Started process (PID=1258) to work on /opt/airflow/dags/create_postgres_app.py
[2025-06-11T07:01:12.058+0000] {processor.py:914} INFO - Processing file /opt/airflow/dags/create_postgres_app.py for tasks to queue
[2025-06-11T07:01:12.070+0000] {logging_mixin.py:190} INFO - [2025-06-11T07:01:12.069+0000] {dagbag.py:588} INFO - Filling up the DagBag from /opt/airflow/dags/create_postgres_app.py
[2025-06-11T07:01:12.121+0000] {logging_mixin.py:190} INFO - [2025-06-11T07:01:12.111+0000] {dagbag.py:387} ERROR - Failed to import: /opt/airflow/dags/create_postgres_app.py
Traceback (most recent call last):
  File "/home/airflow/.local/lib/python3.12/site-packages/airflow/models/dagbag.py", line 383, in parse
    loader.exec_module(new_module)
  File "<frozen importlib._bootstrap_external>", line 995, in exec_module
  File "<frozen importlib._bootstrap>", line 488, in _call_with_frames_removed
  File "/opt/airflow/dags/create_postgres_app.py", line 8, in <module>
    'start_date': datetime(2025, 6, 11),
                  ^^^^^^^^^^^^^^^^^^^^^
TypeError: 'module' object is not callable. Did you mean: 'datetime.datetime(...)'?
[2025-06-11T07:01:12.126+0000] {processor.py:927} WARNING - No viable dags retrieved from /opt/airflow/dags/create_postgres_app.py
[2025-06-11T07:01:12.189+0000] {processor.py:208} INFO - Processing /opt/airflow/dags/create_postgres_app.py took 0.164 seconds
[2025-06-11T07:01:42.693+0000] {processor.py:186} INFO - Started process (PID=1270) to work on /opt/airflow/dags/create_postgres_app.py
[2025-06-11T07:01:42.701+0000] {processor.py:914} INFO - Processing file /opt/airflow/dags/create_postgres_app.py for tasks to queue
[2025-06-11T07:01:42.716+0000] {logging_mixin.py:190} INFO - [2025-06-11T07:01:42.715+0000] {dagbag.py:588} INFO - Filling up the DagBag from /opt/airflow/dags/create_postgres_app.py
[2025-06-11T07:01:42.781+0000] {logging_mixin.py:190} INFO - [2025-06-11T07:01:42.767+0000] {dagbag.py:387} ERROR - Failed to import: /opt/airflow/dags/create_postgres_app.py
Traceback (most recent call last):
  File "/home/airflow/.local/lib/python3.12/site-packages/airflow/models/dagbag.py", line 383, in parse
    loader.exec_module(new_module)
  File "<frozen importlib._bootstrap_external>", line 995, in exec_module
  File "<frozen importlib._bootstrap>", line 488, in _call_with_frames_removed
  File "/opt/airflow/dags/create_postgres_app.py", line 8, in <module>
    'start_date': datetime(2025, 6, 11),
                  ^^^^^^^^^^^^^^^^^^^^^
TypeError: 'module' object is not callable. Did you mean: 'datetime.datetime(...)'?
[2025-06-11T07:01:42.808+0000] {processor.py:927} WARNING - No viable dags retrieved from /opt/airflow/dags/create_postgres_app.py
[2025-06-11T07:01:42.927+0000] {processor.py:208} INFO - Processing /opt/airflow/dags/create_postgres_app.py took 0.279 seconds
[2025-06-11T07:02:13.606+0000] {processor.py:186} INFO - Started process (PID=1282) to work on /opt/airflow/dags/create_postgres_app.py
[2025-06-11T07:02:13.609+0000] {processor.py:914} INFO - Processing file /opt/airflow/dags/create_postgres_app.py for tasks to queue
[2025-06-11T07:02:13.618+0000] {logging_mixin.py:190} INFO - [2025-06-11T07:02:13.617+0000] {dagbag.py:588} INFO - Filling up the DagBag from /opt/airflow/dags/create_postgres_app.py
[2025-06-11T07:02:13.659+0000] {logging_mixin.py:190} INFO - [2025-06-11T07:02:13.650+0000] {dagbag.py:387} ERROR - Failed to import: /opt/airflow/dags/create_postgres_app.py
Traceback (most recent call last):
  File "/home/airflow/.local/lib/python3.12/site-packages/airflow/models/dagbag.py", line 383, in parse
    loader.exec_module(new_module)
  File "<frozen importlib._bootstrap_external>", line 995, in exec_module
  File "<frozen importlib._bootstrap>", line 488, in _call_with_frames_removed
  File "/opt/airflow/dags/create_postgres_app.py", line 8, in <module>
    'start_date': datetime(2025, 6, 11),
                  ^^^^^^^^^^^^^^^^^^^^^
TypeError: 'module' object is not callable. Did you mean: 'datetime.datetime(...)'?
[2025-06-11T07:02:13.663+0000] {processor.py:927} WARNING - No viable dags retrieved from /opt/airflow/dags/create_postgres_app.py
[2025-06-11T07:02:13.722+0000] {processor.py:208} INFO - Processing /opt/airflow/dags/create_postgres_app.py took 0.135 seconds
[2025-06-11T07:02:43.977+0000] {processor.py:186} INFO - Started process (PID=1294) to work on /opt/airflow/dags/create_postgres_app.py
[2025-06-11T07:02:43.980+0000] {processor.py:914} INFO - Processing file /opt/airflow/dags/create_postgres_app.py for tasks to queue
[2025-06-11T07:02:43.988+0000] {logging_mixin.py:190} INFO - [2025-06-11T07:02:43.987+0000] {dagbag.py:588} INFO - Filling up the DagBag from /opt/airflow/dags/create_postgres_app.py
[2025-06-11T07:02:44.025+0000] {logging_mixin.py:190} INFO - [2025-06-11T07:02:44.016+0000] {dagbag.py:387} ERROR - Failed to import: /opt/airflow/dags/create_postgres_app.py
Traceback (most recent call last):
  File "/home/airflow/.local/lib/python3.12/site-packages/airflow/models/dagbag.py", line 383, in parse
    loader.exec_module(new_module)
  File "<frozen importlib._bootstrap_external>", line 995, in exec_module
  File "<frozen importlib._bootstrap>", line 488, in _call_with_frames_removed
  File "/opt/airflow/dags/create_postgres_app.py", line 8, in <module>
    'start_date': datetime(2025, 6, 11),
                  ^^^^^^^^^^^^^^^^^^^^^
TypeError: 'module' object is not callable. Did you mean: 'datetime.datetime(...)'?
[2025-06-11T07:02:44.029+0000] {processor.py:927} WARNING - No viable dags retrieved from /opt/airflow/dags/create_postgres_app.py
[2025-06-11T07:02:44.081+0000] {processor.py:208} INFO - Processing /opt/airflow/dags/create_postgres_app.py took 0.123 seconds
[2025-06-11T07:03:15.158+0000] {processor.py:186} INFO - Started process (PID=1306) to work on /opt/airflow/dags/create_postgres_app.py
[2025-06-11T07:03:15.161+0000] {processor.py:914} INFO - Processing file /opt/airflow/dags/create_postgres_app.py for tasks to queue
[2025-06-11T07:03:15.169+0000] {logging_mixin.py:190} INFO - [2025-06-11T07:03:15.168+0000] {dagbag.py:588} INFO - Filling up the DagBag from /opt/airflow/dags/create_postgres_app.py
[2025-06-11T07:03:15.214+0000] {logging_mixin.py:190} INFO - [2025-06-11T07:03:15.201+0000] {dagbag.py:387} ERROR - Failed to import: /opt/airflow/dags/create_postgres_app.py
Traceback (most recent call last):
  File "/home/airflow/.local/lib/python3.12/site-packages/airflow/models/dagbag.py", line 383, in parse
    loader.exec_module(new_module)
  File "<frozen importlib._bootstrap_external>", line 995, in exec_module
  File "<frozen importlib._bootstrap>", line 488, in _call_with_frames_removed
  File "/opt/airflow/dags/create_postgres_app.py", line 8, in <module>
    'start_date': datetime(2025, 6, 11),
                  ^^^^^^^^^^^^^^^^^^^^^
TypeError: 'module' object is not callable. Did you mean: 'datetime.datetime(...)'?
[2025-06-11T07:03:15.218+0000] {processor.py:927} WARNING - No viable dags retrieved from /opt/airflow/dags/create_postgres_app.py
[2025-06-11T07:03:15.272+0000] {processor.py:208} INFO - Processing /opt/airflow/dags/create_postgres_app.py took 0.131 seconds
[2025-06-11T07:03:45.411+0000] {processor.py:186} INFO - Started process (PID=1317) to work on /opt/airflow/dags/create_postgres_app.py
[2025-06-11T07:03:45.414+0000] {processor.py:914} INFO - Processing file /opt/airflow/dags/create_postgres_app.py for tasks to queue
[2025-06-11T07:03:45.421+0000] {logging_mixin.py:190} INFO - [2025-06-11T07:03:45.420+0000] {dagbag.py:588} INFO - Filling up the DagBag from /opt/airflow/dags/create_postgres_app.py
[2025-06-11T07:03:45.467+0000] {logging_mixin.py:190} INFO - [2025-06-11T07:03:45.450+0000] {dagbag.py:387} ERROR - Failed to import: /opt/airflow/dags/create_postgres_app.py
Traceback (most recent call last):
  File "/home/airflow/.local/lib/python3.12/site-packages/airflow/models/dagbag.py", line 383, in parse
    loader.exec_module(new_module)
  File "<frozen importlib._bootstrap_external>", line 995, in exec_module
  File "<frozen importlib._bootstrap>", line 488, in _call_with_frames_removed
  File "/opt/airflow/dags/create_postgres_app.py", line 8, in <module>
    'start_date': datetime(2025, 6, 11),
                  ^^^^^^^^^^^^^^^^^^^^^
TypeError: 'module' object is not callable. Did you mean: 'datetime.datetime(...)'?
[2025-06-11T07:03:45.471+0000] {processor.py:927} WARNING - No viable dags retrieved from /opt/airflow/dags/create_postgres_app.py
[2025-06-11T07:03:45.542+0000] {processor.py:208} INFO - Processing /opt/airflow/dags/create_postgres_app.py took 0.150 seconds
[2025-06-11T07:04:16.399+0000] {processor.py:186} INFO - Started process (PID=1329) to work on /opt/airflow/dags/create_postgres_app.py
[2025-06-11T07:04:16.422+0000] {processor.py:914} INFO - Processing file /opt/airflow/dags/create_postgres_app.py for tasks to queue
[2025-06-11T07:04:16.456+0000] {logging_mixin.py:190} INFO - [2025-06-11T07:04:16.442+0000] {dagbag.py:588} INFO - Filling up the DagBag from /opt/airflow/dags/create_postgres_app.py
[2025-06-11T07:04:16.540+0000] {logging_mixin.py:190} INFO - [2025-06-11T07:04:16.510+0000] {dagbag.py:387} ERROR - Failed to import: /opt/airflow/dags/create_postgres_app.py
Traceback (most recent call last):
  File "/home/airflow/.local/lib/python3.12/site-packages/airflow/models/dagbag.py", line 383, in parse
    loader.exec_module(new_module)
  File "<frozen importlib._bootstrap_external>", line 995, in exec_module
  File "<frozen importlib._bootstrap>", line 488, in _call_with_frames_removed
  File "/opt/airflow/dags/create_postgres_app.py", line 8, in <module>
    'start_date': datetime(2025, 6, 11),
                  ^^^^^^^^^^^^^^^^^^^^^
TypeError: 'module' object is not callable. Did you mean: 'datetime.datetime(...)'?
[2025-06-11T07:04:16.545+0000] {processor.py:927} WARNING - No viable dags retrieved from /opt/airflow/dags/create_postgres_app.py
[2025-06-11T07:04:16.711+0000] {processor.py:208} INFO - Processing /opt/airflow/dags/create_postgres_app.py took 0.351 seconds
[2025-06-11T07:04:47.267+0000] {processor.py:186} INFO - Started process (PID=1340) to work on /opt/airflow/dags/create_postgres_app.py
[2025-06-11T07:04:47.270+0000] {processor.py:914} INFO - Processing file /opt/airflow/dags/create_postgres_app.py for tasks to queue
[2025-06-11T07:04:47.278+0000] {logging_mixin.py:190} INFO - [2025-06-11T07:04:47.277+0000] {dagbag.py:588} INFO - Filling up the DagBag from /opt/airflow/dags/create_postgres_app.py
[2025-06-11T07:04:47.323+0000] {logging_mixin.py:190} INFO - [2025-06-11T07:04:47.312+0000] {dagbag.py:387} ERROR - Failed to import: /opt/airflow/dags/create_postgres_app.py
Traceback (most recent call last):
  File "/home/airflow/.local/lib/python3.12/site-packages/airflow/models/dagbag.py", line 383, in parse
    loader.exec_module(new_module)
  File "<frozen importlib._bootstrap_external>", line 995, in exec_module
  File "<frozen importlib._bootstrap>", line 488, in _call_with_frames_removed
  File "/opt/airflow/dags/create_postgres_app.py", line 8, in <module>
    'start_date': datetime(2025, 6, 11),
                  ^^^^^^^^^^^^^^^^^^^^^
TypeError: 'module' object is not callable. Did you mean: 'datetime.datetime(...)'?
[2025-06-11T07:04:47.327+0000] {processor.py:927} WARNING - No viable dags retrieved from /opt/airflow/dags/create_postgres_app.py
[2025-06-11T07:04:47.396+0000] {processor.py:208} INFO - Processing /opt/airflow/dags/create_postgres_app.py took 0.155 seconds
[2025-06-11T07:05:17.516+0000] {processor.py:186} INFO - Started process (PID=1353) to work on /opt/airflow/dags/create_postgres_app.py
[2025-06-11T07:05:17.521+0000] {processor.py:914} INFO - Processing file /opt/airflow/dags/create_postgres_app.py for tasks to queue
[2025-06-11T07:05:17.529+0000] {logging_mixin.py:190} INFO - [2025-06-11T07:05:17.528+0000] {dagbag.py:588} INFO - Filling up the DagBag from /opt/airflow/dags/create_postgres_app.py
[2025-06-11T07:05:17.584+0000] {logging_mixin.py:190} INFO - [2025-06-11T07:05:17.569+0000] {dagbag.py:387} ERROR - Failed to import: /opt/airflow/dags/create_postgres_app.py
Traceback (most recent call last):
  File "/home/airflow/.local/lib/python3.12/site-packages/airflow/models/dagbag.py", line 383, in parse
    loader.exec_module(new_module)
  File "<frozen importlib._bootstrap_external>", line 995, in exec_module
  File "<frozen importlib._bootstrap>", line 488, in _call_with_frames_removed
  File "/opt/airflow/dags/create_postgres_app.py", line 8, in <module>
    'start_date': datetime(2025, 6, 11),
                  ^^^^^^^^^^^^^^^^^^^^^
TypeError: 'module' object is not callable. Did you mean: 'datetime.datetime(...)'?
[2025-06-11T07:05:17.588+0000] {processor.py:927} WARNING - No viable dags retrieved from /opt/airflow/dags/create_postgres_app.py
[2025-06-11T07:05:17.694+0000] {processor.py:208} INFO - Processing /opt/airflow/dags/create_postgres_app.py took 0.202 seconds
[2025-06-11T07:05:48.063+0000] {processor.py:186} INFO - Started process (PID=1365) to work on /opt/airflow/dags/create_postgres_app.py
[2025-06-11T07:05:48.066+0000] {processor.py:914} INFO - Processing file /opt/airflow/dags/create_postgres_app.py for tasks to queue
[2025-06-11T07:05:48.071+0000] {logging_mixin.py:190} INFO - [2025-06-11T07:05:48.071+0000] {dagbag.py:588} INFO - Filling up the DagBag from /opt/airflow/dags/create_postgres_app.py
[2025-06-11T07:05:48.112+0000] {logging_mixin.py:190} INFO - [2025-06-11T07:05:48.102+0000] {dagbag.py:387} ERROR - Failed to import: /opt/airflow/dags/create_postgres_app.py
Traceback (most recent call last):
  File "/home/airflow/.local/lib/python3.12/site-packages/airflow/models/dagbag.py", line 383, in parse
    loader.exec_module(new_module)
  File "<frozen importlib._bootstrap_external>", line 995, in exec_module
  File "<frozen importlib._bootstrap>", line 488, in _call_with_frames_removed
  File "/opt/airflow/dags/create_postgres_app.py", line 8, in <module>
    'start_date': datetime(2025, 6, 11),
                  ^^^^^^^^^^^^^^^^^^^^^
TypeError: 'module' object is not callable. Did you mean: 'datetime.datetime(...)'?
[2025-06-11T07:05:48.116+0000] {processor.py:927} WARNING - No viable dags retrieved from /opt/airflow/dags/create_postgres_app.py
[2025-06-11T07:05:48.166+0000] {processor.py:208} INFO - Processing /opt/airflow/dags/create_postgres_app.py took 0.119 seconds
[2025-06-11T07:06:18.784+0000] {processor.py:186} INFO - Started process (PID=1377) to work on /opt/airflow/dags/create_postgres_app.py
[2025-06-11T07:06:18.787+0000] {processor.py:914} INFO - Processing file /opt/airflow/dags/create_postgres_app.py for tasks to queue
[2025-06-11T07:06:18.794+0000] {logging_mixin.py:190} INFO - [2025-06-11T07:06:18.793+0000] {dagbag.py:588} INFO - Filling up the DagBag from /opt/airflow/dags/create_postgres_app.py
[2025-06-11T07:06:18.828+0000] {logging_mixin.py:190} INFO - [2025-06-11T07:06:18.820+0000] {dagbag.py:387} ERROR - Failed to import: /opt/airflow/dags/create_postgres_app.py
Traceback (most recent call last):
  File "/home/airflow/.local/lib/python3.12/site-packages/airflow/models/dagbag.py", line 383, in parse
    loader.exec_module(new_module)
  File "<frozen importlib._bootstrap_external>", line 995, in exec_module
  File "<frozen importlib._bootstrap>", line 488, in _call_with_frames_removed
  File "/opt/airflow/dags/create_postgres_app.py", line 8, in <module>
    'start_date': datetime(2025, 6, 11),
                  ^^^^^^^^^^^^^^^^^^^^^
TypeError: 'module' object is not callable. Did you mean: 'datetime.datetime(...)'?
[2025-06-11T07:06:18.830+0000] {processor.py:927} WARNING - No viable dags retrieved from /opt/airflow/dags/create_postgres_app.py
[2025-06-11T07:06:18.875+0000] {processor.py:208} INFO - Processing /opt/airflow/dags/create_postgres_app.py took 0.111 seconds
[2025-06-11T07:06:49.037+0000] {processor.py:186} INFO - Started process (PID=1389) to work on /opt/airflow/dags/create_postgres_app.py
[2025-06-11T07:06:49.041+0000] {processor.py:914} INFO - Processing file /opt/airflow/dags/create_postgres_app.py for tasks to queue
[2025-06-11T07:06:49.048+0000] {logging_mixin.py:190} INFO - [2025-06-11T07:06:49.047+0000] {dagbag.py:588} INFO - Filling up the DagBag from /opt/airflow/dags/create_postgres_app.py
[2025-06-11T07:06:49.083+0000] {logging_mixin.py:190} INFO - [2025-06-11T07:06:49.074+0000] {dagbag.py:387} ERROR - Failed to import: /opt/airflow/dags/create_postgres_app.py
Traceback (most recent call last):
  File "/home/airflow/.local/lib/python3.12/site-packages/airflow/models/dagbag.py", line 383, in parse
    loader.exec_module(new_module)
  File "<frozen importlib._bootstrap_external>", line 995, in exec_module
  File "<frozen importlib._bootstrap>", line 488, in _call_with_frames_removed
  File "/opt/airflow/dags/create_postgres_app.py", line 8, in <module>
    'start_date': datetime(2025, 6, 11),
                  ^^^^^^^^^^^^^^^^^^^^^
TypeError: 'module' object is not callable. Did you mean: 'datetime.datetime(...)'?
[2025-06-11T07:06:49.087+0000] {processor.py:927} WARNING - No viable dags retrieved from /opt/airflow/dags/create_postgres_app.py
[2025-06-11T07:06:49.145+0000] {processor.py:208} INFO - Processing /opt/airflow/dags/create_postgres_app.py took 0.130 seconds
[2025-06-11T07:07:19.700+0000] {processor.py:186} INFO - Started process (PID=1401) to work on /opt/airflow/dags/create_postgres_app.py
[2025-06-11T07:07:19.702+0000] {processor.py:914} INFO - Processing file /opt/airflow/dags/create_postgres_app.py for tasks to queue
[2025-06-11T07:07:19.709+0000] {logging_mixin.py:190} INFO - [2025-06-11T07:07:19.708+0000] {dagbag.py:588} INFO - Filling up the DagBag from /opt/airflow/dags/create_postgres_app.py
[2025-06-11T07:07:19.752+0000] {logging_mixin.py:190} INFO - [2025-06-11T07:07:19.738+0000] {dagbag.py:387} ERROR - Failed to import: /opt/airflow/dags/create_postgres_app.py
Traceback (most recent call last):
  File "/home/airflow/.local/lib/python3.12/site-packages/airflow/models/dagbag.py", line 383, in parse
    loader.exec_module(new_module)
  File "<frozen importlib._bootstrap_external>", line 995, in exec_module
  File "<frozen importlib._bootstrap>", line 488, in _call_with_frames_removed
  File "/opt/airflow/dags/create_postgres_app.py", line 8, in <module>
    'start_date': datetime(2025, 6, 11),
                  ^^^^^^^^^^^^^^^^^^^^^
TypeError: 'module' object is not callable. Did you mean: 'datetime.datetime(...)'?
[2025-06-11T07:07:19.758+0000] {processor.py:927} WARNING - No viable dags retrieved from /opt/airflow/dags/create_postgres_app.py
[2025-06-11T07:07:19.808+0000] {processor.py:208} INFO - Processing /opt/airflow/dags/create_postgres_app.py took 0.125 seconds
[2025-06-11T07:07:50.512+0000] {processor.py:186} INFO - Started process (PID=1413) to work on /opt/airflow/dags/create_postgres_app.py
[2025-06-11T07:07:50.514+0000] {processor.py:914} INFO - Processing file /opt/airflow/dags/create_postgres_app.py for tasks to queue
[2025-06-11T07:07:50.521+0000] {logging_mixin.py:190} INFO - [2025-06-11T07:07:50.521+0000] {dagbag.py:588} INFO - Filling up the DagBag from /opt/airflow/dags/create_postgres_app.py
[2025-06-11T07:07:50.559+0000] {logging_mixin.py:190} INFO - [2025-06-11T07:07:50.551+0000] {dagbag.py:387} ERROR - Failed to import: /opt/airflow/dags/create_postgres_app.py
Traceback (most recent call last):
  File "/home/airflow/.local/lib/python3.12/site-packages/airflow/models/dagbag.py", line 383, in parse
    loader.exec_module(new_module)
  File "<frozen importlib._bootstrap_external>", line 995, in exec_module
  File "<frozen importlib._bootstrap>", line 488, in _call_with_frames_removed
  File "/opt/airflow/dags/create_postgres_app.py", line 8, in <module>
    'start_date': datetime(2025, 6, 11),
                  ^^^^^^^^^^^^^^^^^^^^^
TypeError: 'module' object is not callable. Did you mean: 'datetime.datetime(...)'?
[2025-06-11T07:07:50.562+0000] {processor.py:927} WARNING - No viable dags retrieved from /opt/airflow/dags/create_postgres_app.py
[2025-06-11T07:07:50.609+0000] {processor.py:208} INFO - Processing /opt/airflow/dags/create_postgres_app.py took 0.113 seconds
[2025-06-11T07:08:21.060+0000] {processor.py:186} INFO - Started process (PID=1425) to work on /opt/airflow/dags/create_postgres_app.py
[2025-06-11T07:08:21.063+0000] {processor.py:914} INFO - Processing file /opt/airflow/dags/create_postgres_app.py for tasks to queue
[2025-06-11T07:08:21.073+0000] {logging_mixin.py:190} INFO - [2025-06-11T07:08:21.072+0000] {dagbag.py:588} INFO - Filling up the DagBag from /opt/airflow/dags/create_postgres_app.py
[2025-06-11T07:08:21.129+0000] {logging_mixin.py:190} INFO - [2025-06-11T07:08:21.115+0000] {dagbag.py:387} ERROR - Failed to import: /opt/airflow/dags/create_postgres_app.py
Traceback (most recent call last):
  File "/home/airflow/.local/lib/python3.12/site-packages/airflow/models/dagbag.py", line 383, in parse
    loader.exec_module(new_module)
  File "<frozen importlib._bootstrap_external>", line 995, in exec_module
  File "<frozen importlib._bootstrap>", line 488, in _call_with_frames_removed
  File "/opt/airflow/dags/create_postgres_app.py", line 8, in <module>
    'start_date': datetime(2025, 6, 11),
                  ^^^^^^^^^^^^^^^^^^^^^
TypeError: 'module' object is not callable. Did you mean: 'datetime.datetime(...)'?
[2025-06-11T07:08:21.133+0000] {processor.py:927} WARNING - No viable dags retrieved from /opt/airflow/dags/create_postgres_app.py
[2025-06-11T07:08:21.194+0000] {processor.py:208} INFO - Processing /opt/airflow/dags/create_postgres_app.py took 0.154 seconds
[2025-06-11T10:08:37.055+0000] {processor.py:186} INFO - Started process (PID=1427) to work on /opt/airflow/dags/create_postgres_app.py
[2025-06-11T10:08:37.065+0000] {processor.py:914} INFO - Processing file /opt/airflow/dags/create_postgres_app.py for tasks to queue
[2025-06-11T10:08:37.091+0000] {logging_mixin.py:190} INFO - [2025-06-11T10:08:37.089+0000] {dagbag.py:588} INFO - Filling up the DagBag from /opt/airflow/dags/create_postgres_app.py
[2025-06-11T10:08:37.731+0000] {logging_mixin.py:190} INFO - [2025-06-11T10:08:37.507+0000] {dagbag.py:387} ERROR - Failed to import: /opt/airflow/dags/create_postgres_app.py
Traceback (most recent call last):
  File "/home/airflow/.local/lib/python3.12/site-packages/airflow/models/dagbag.py", line 383, in parse
    loader.exec_module(new_module)
  File "<frozen importlib._bootstrap_external>", line 995, in exec_module
  File "<frozen importlib._bootstrap>", line 488, in _call_with_frames_removed
  File "/opt/airflow/dags/create_postgres_app.py", line 8, in <module>
    'start_date': datetime(2025, 6, 11),
                  ^^^^^^^^^^^^^^^^^^^^^
TypeError: 'module' object is not callable. Did you mean: 'datetime.datetime(...)'?
[2025-06-11T10:08:37.803+0000] {processor.py:927} WARNING - No viable dags retrieved from /opt/airflow/dags/create_postgres_app.py
[2025-06-11T10:08:37.940+0000] {processor.py:208} INFO - Processing /opt/airflow/dags/create_postgres_app.py took 0.944 seconds
