[2025-06-18T02:48:17.726+0000] {processor.py:186} INFO - Started process (PID=402) to work on /opt/airflow/dags/create_postgres_app.py
[2025-06-18T02:48:17.742+0000] {processor.py:914} INFO - Processing file /opt/airflow/dags/create_postgres_app.py for tasks to queue
[2025-06-18T02:48:17.756+0000] {logging_mixin.py:190} INFO - [2025-06-18T02:48:17.752+0000] {dagbag.py:588} INFO - Filling up the DagBag from /opt/airflow/dags/create_postgres_app.py
[2025-06-18T02:48:18.017+0000] {logging_mixin.py:190} INFO - [2025-06-18T02:48:17.917+0000] {dagbag.py:387} ERROR - Failed to import: /opt/airflow/dags/create_postgres_app.py
Traceback (most recent call last):
  File "/home/airflow/.local/lib/python3.12/site-packages/airflow/models/dagbag.py", line 383, in parse
    loader.exec_module(new_module)
  File "<frozen importlib._bootstrap_external>", line 995, in exec_module
  File "<frozen importlib._bootstrap>", line 488, in _call_with_frames_removed
  File "/opt/airflow/dags/create_postgres_app.py", line 8, in <module>
    'start_date': datetime(2025, 6, 11),
                  ^^^^^^^^^^^^^^^^^^^^^
TypeError: 'module' object is not callable. Did you mean: 'datetime.datetime(...)'?
[2025-06-18T02:48:18.087+0000] {processor.py:927} WARNING - No viable dags retrieved from /opt/airflow/dags/create_postgres_app.py
[2025-06-18T02:48:18.309+0000] {processor.py:208} INFO - Processing /opt/airflow/dags/create_postgres_app.py took 0.649 seconds
[2025-06-18T04:58:53.933+0000] {processor.py:186} INFO - Started process (PID=408) to work on /opt/airflow/dags/create_postgres_app.py
[2025-06-18T04:58:53.949+0000] {processor.py:914} INFO - Processing file /opt/airflow/dags/create_postgres_app.py for tasks to queue
[2025-06-18T04:58:53.969+0000] {logging_mixin.py:190} INFO - [2025-06-18T04:58:53.966+0000] {dagbag.py:588} INFO - Filling up the DagBag from /opt/airflow/dags/create_postgres_app.py
[2025-06-18T04:58:54.247+0000] {logging_mixin.py:190} INFO - [2025-06-18T04:58:54.184+0000] {dagbag.py:387} ERROR - Failed to import: /opt/airflow/dags/create_postgres_app.py
Traceback (most recent call last):
  File "/home/airflow/.local/lib/python3.12/site-packages/airflow/models/dagbag.py", line 383, in parse
    loader.exec_module(new_module)
  File "<frozen importlib._bootstrap_external>", line 995, in exec_module
  File "<frozen importlib._bootstrap>", line 488, in _call_with_frames_removed
  File "/opt/airflow/dags/create_postgres_app.py", line 8, in <module>
    'start_date': datetime(2025, 6, 11),
                  ^^^^^^^^^^^^^^^^^^^^^
TypeError: 'module' object is not callable. Did you mean: 'datetime.datetime(...)'?
[2025-06-18T04:58:54.263+0000] {processor.py:927} WARNING - No viable dags retrieved from /opt/airflow/dags/create_postgres_app.py
[2025-06-18T04:58:54.558+0000] {processor.py:208} INFO - Processing /opt/airflow/dags/create_postgres_app.py took 0.768 seconds
[2025-06-18T04:59:25.277+0000] {processor.py:186} INFO - Started process (PID=417) to work on /opt/airflow/dags/create_postgres_app.py
[2025-06-18T04:59:25.305+0000] {processor.py:914} INFO - Processing file /opt/airflow/dags/create_postgres_app.py for tasks to queue
[2025-06-18T04:59:25.315+0000] {logging_mixin.py:190} INFO - [2025-06-18T04:59:25.312+0000] {dagbag.py:588} INFO - Filling up the DagBag from /opt/airflow/dags/create_postgres_app.py
[2025-06-18T04:59:25.554+0000] {logging_mixin.py:190} INFO - [2025-06-18T04:59:25.526+0000] {dagbag.py:387} ERROR - Failed to import: /opt/airflow/dags/create_postgres_app.py
Traceback (most recent call last):
  File "/home/airflow/.local/lib/python3.12/site-packages/airflow/models/dagbag.py", line 383, in parse
    loader.exec_module(new_module)
  File "<frozen importlib._bootstrap_external>", line 995, in exec_module
  File "<frozen importlib._bootstrap>", line 488, in _call_with_frames_removed
  File "/opt/airflow/dags/create_postgres_app.py", line 8, in <module>
    'start_date': datetime(2025, 6, 11),
                  ^^^^^^^^^^^^^^^^^^^^^
TypeError: 'module' object is not callable. Did you mean: 'datetime.datetime(...)'?
[2025-06-18T04:59:25.583+0000] {processor.py:927} WARNING - No viable dags retrieved from /opt/airflow/dags/create_postgres_app.py
[2025-06-18T04:59:25.764+0000] {processor.py:208} INFO - Processing /opt/airflow/dags/create_postgres_app.py took 0.551 seconds
[2025-06-18T04:59:56.489+0000] {processor.py:186} INFO - Started process (PID=429) to work on /opt/airflow/dags/create_postgres_app.py
[2025-06-18T04:59:56.495+0000] {processor.py:914} INFO - Processing file /opt/airflow/dags/create_postgres_app.py for tasks to queue
[2025-06-18T04:59:56.502+0000] {logging_mixin.py:190} INFO - [2025-06-18T04:59:56.498+0000] {dagbag.py:588} INFO - Filling up the DagBag from /opt/airflow/dags/create_postgres_app.py
[2025-06-18T04:59:56.587+0000] {logging_mixin.py:190} INFO - [2025-06-18T04:59:56.568+0000] {dagbag.py:387} ERROR - Failed to import: /opt/airflow/dags/create_postgres_app.py
Traceback (most recent call last):
  File "/home/airflow/.local/lib/python3.12/site-packages/airflow/models/dagbag.py", line 383, in parse
    loader.exec_module(new_module)
  File "<frozen importlib._bootstrap_external>", line 995, in exec_module
  File "<frozen importlib._bootstrap>", line 488, in _call_with_frames_removed
  File "/opt/airflow/dags/create_postgres_app.py", line 8, in <module>
    'start_date': datetime(2025, 6, 11),
                  ^^^^^^^^^^^^^^^^^^^^^
TypeError: 'module' object is not callable. Did you mean: 'datetime.datetime(...)'?
[2025-06-18T04:59:56.597+0000] {processor.py:927} WARNING - No viable dags retrieved from /opt/airflow/dags/create_postgres_app.py
[2025-06-18T04:59:56.743+0000] {processor.py:208} INFO - Processing /opt/airflow/dags/create_postgres_app.py took 0.304 seconds
[2025-06-18T05:00:27.264+0000] {processor.py:186} INFO - Started process (PID=440) to work on /opt/airflow/dags/create_postgres_app.py
[2025-06-18T05:00:27.271+0000] {processor.py:914} INFO - Processing file /opt/airflow/dags/create_postgres_app.py for tasks to queue
[2025-06-18T05:00:27.287+0000] {logging_mixin.py:190} INFO - [2025-06-18T05:00:27.278+0000] {dagbag.py:588} INFO - Filling up the DagBag from /opt/airflow/dags/create_postgres_app.py
[2025-06-18T05:00:27.400+0000] {logging_mixin.py:190} INFO - [2025-06-18T05:00:27.362+0000] {dagbag.py:387} ERROR - Failed to import: /opt/airflow/dags/create_postgres_app.py
Traceback (most recent call last):
  File "/home/airflow/.local/lib/python3.12/site-packages/airflow/models/dagbag.py", line 383, in parse
    loader.exec_module(new_module)
  File "<frozen importlib._bootstrap_external>", line 995, in exec_module
  File "<frozen importlib._bootstrap>", line 488, in _call_with_frames_removed
  File "/opt/airflow/dags/create_postgres_app.py", line 8, in <module>
    'start_date': datetime(2025, 6, 11),
                  ^^^^^^^^^^^^^^^^^^^^^
TypeError: 'module' object is not callable. Did you mean: 'datetime.datetime(...)'?
[2025-06-18T05:00:27.409+0000] {processor.py:927} WARNING - No viable dags retrieved from /opt/airflow/dags/create_postgres_app.py
[2025-06-18T05:00:27.614+0000] {processor.py:208} INFO - Processing /opt/airflow/dags/create_postgres_app.py took 0.436 seconds
[2025-06-18T05:00:59.713+0000] {processor.py:186} INFO - Started process (PID=459) to work on /opt/airflow/dags/create_postgres_app.py
[2025-06-18T05:00:59.749+0000] {processor.py:914} INFO - Processing file /opt/airflow/dags/create_postgres_app.py for tasks to queue
[2025-06-18T05:00:59.771+0000] {logging_mixin.py:190} INFO - [2025-06-18T05:00:59.770+0000] {dagbag.py:588} INFO - Filling up the DagBag from /opt/airflow/dags/create_postgres_app.py
[2025-06-18T05:01:01.386+0000] {logging_mixin.py:190} INFO - [2025-06-18T05:01:01.226+0000] {dagbag.py:387} ERROR - Failed to import: /opt/airflow/dags/create_postgres_app.py
Traceback (most recent call last):
  File "/home/airflow/.local/lib/python3.12/site-packages/airflow/models/dagbag.py", line 383, in parse
    loader.exec_module(new_module)
  File "<frozen importlib._bootstrap_external>", line 995, in exec_module
  File "<frozen importlib._bootstrap>", line 488, in _call_with_frames_removed
  File "/opt/airflow/dags/create_postgres_app.py", line 8, in <module>
    'start_date': datetime(2025, 6, 11),
                  ^^^^^^^^^^^^^^^^^^^^^
TypeError: 'module' object is not callable. Did you mean: 'datetime.datetime(...)'?
[2025-06-18T05:01:01.410+0000] {processor.py:927} WARNING - No viable dags retrieved from /opt/airflow/dags/create_postgres_app.py
[2025-06-18T05:01:01.608+0000] {processor.py:208} INFO - Processing /opt/airflow/dags/create_postgres_app.py took 2.009 seconds
[2025-06-18T05:01:32.139+0000] {processor.py:186} INFO - Started process (PID=471) to work on /opt/airflow/dags/create_postgres_app.py
[2025-06-18T05:01:32.142+0000] {processor.py:914} INFO - Processing file /opt/airflow/dags/create_postgres_app.py for tasks to queue
[2025-06-18T05:01:32.174+0000] {logging_mixin.py:190} INFO - [2025-06-18T05:01:32.173+0000] {dagbag.py:588} INFO - Filling up the DagBag from /opt/airflow/dags/create_postgres_app.py
[2025-06-18T05:01:32.262+0000] {logging_mixin.py:190} INFO - [2025-06-18T05:01:32.247+0000] {dagbag.py:387} ERROR - Failed to import: /opt/airflow/dags/create_postgres_app.py
Traceback (most recent call last):
  File "/home/airflow/.local/lib/python3.12/site-packages/airflow/models/dagbag.py", line 383, in parse
    loader.exec_module(new_module)
  File "<frozen importlib._bootstrap_external>", line 995, in exec_module
  File "<frozen importlib._bootstrap>", line 488, in _call_with_frames_removed
  File "/opt/airflow/dags/create_postgres_app.py", line 8, in <module>
    'start_date': datetime(2025, 6, 11),
                  ^^^^^^^^^^^^^^^^^^^^^
TypeError: 'module' object is not callable. Did you mean: 'datetime.datetime(...)'?
[2025-06-18T05:01:32.271+0000] {processor.py:927} WARNING - No viable dags retrieved from /opt/airflow/dags/create_postgres_app.py
[2025-06-18T05:01:32.367+0000] {processor.py:208} INFO - Processing /opt/airflow/dags/create_postgres_app.py took 0.262 seconds
[2025-06-18T05:02:02.617+0000] {processor.py:186} INFO - Started process (PID=483) to work on /opt/airflow/dags/create_postgres_app.py
[2025-06-18T05:02:02.620+0000] {processor.py:914} INFO - Processing file /opt/airflow/dags/create_postgres_app.py for tasks to queue
[2025-06-18T05:02:02.625+0000] {logging_mixin.py:190} INFO - [2025-06-18T05:02:02.623+0000] {dagbag.py:588} INFO - Filling up the DagBag from /opt/airflow/dags/create_postgres_app.py
[2025-06-18T05:02:02.707+0000] {logging_mixin.py:190} INFO - [2025-06-18T05:02:02.683+0000] {dagbag.py:387} ERROR - Failed to import: /opt/airflow/dags/create_postgres_app.py
Traceback (most recent call last):
  File "/home/airflow/.local/lib/python3.12/site-packages/airflow/models/dagbag.py", line 383, in parse
    loader.exec_module(new_module)
  File "<frozen importlib._bootstrap_external>", line 995, in exec_module
  File "<frozen importlib._bootstrap>", line 488, in _call_with_frames_removed
  File "/opt/airflow/dags/create_postgres_app.py", line 8, in <module>
    'start_date': datetime(2025, 6, 11),
                  ^^^^^^^^^^^^^^^^^^^^^
TypeError: 'module' object is not callable. Did you mean: 'datetime.datetime(...)'?
[2025-06-18T05:02:02.714+0000] {processor.py:927} WARNING - No viable dags retrieved from /opt/airflow/dags/create_postgres_app.py
[2025-06-18T05:02:02.807+0000] {processor.py:208} INFO - Processing /opt/airflow/dags/create_postgres_app.py took 0.218 seconds
[2025-06-18T05:02:33.061+0000] {processor.py:186} INFO - Started process (PID=495) to work on /opt/airflow/dags/create_postgres_app.py
[2025-06-18T05:02:33.064+0000] {processor.py:914} INFO - Processing file /opt/airflow/dags/create_postgres_app.py for tasks to queue
[2025-06-18T05:02:33.069+0000] {logging_mixin.py:190} INFO - [2025-06-18T05:02:33.068+0000] {dagbag.py:588} INFO - Filling up the DagBag from /opt/airflow/dags/create_postgres_app.py
[2025-06-18T05:02:33.144+0000] {logging_mixin.py:190} INFO - [2025-06-18T05:02:33.125+0000] {dagbag.py:387} ERROR - Failed to import: /opt/airflow/dags/create_postgres_app.py
Traceback (most recent call last):
  File "/home/airflow/.local/lib/python3.12/site-packages/airflow/models/dagbag.py", line 383, in parse
    loader.exec_module(new_module)
  File "<frozen importlib._bootstrap_external>", line 995, in exec_module
  File "<frozen importlib._bootstrap>", line 488, in _call_with_frames_removed
  File "/opt/airflow/dags/create_postgres_app.py", line 8, in <module>
    'start_date': datetime(2025, 6, 11),
                  ^^^^^^^^^^^^^^^^^^^^^
TypeError: 'module' object is not callable. Did you mean: 'datetime.datetime(...)'?
[2025-06-18T05:02:33.149+0000] {processor.py:927} WARNING - No viable dags retrieved from /opt/airflow/dags/create_postgres_app.py
[2025-06-18T05:02:33.210+0000] {processor.py:208} INFO - Processing /opt/airflow/dags/create_postgres_app.py took 0.170 seconds
[2025-06-18T05:03:03.458+0000] {processor.py:186} INFO - Started process (PID=507) to work on /opt/airflow/dags/create_postgres_app.py
[2025-06-18T05:03:03.461+0000] {processor.py:914} INFO - Processing file /opt/airflow/dags/create_postgres_app.py for tasks to queue
[2025-06-18T05:03:03.465+0000] {logging_mixin.py:190} INFO - [2025-06-18T05:03:03.464+0000] {dagbag.py:588} INFO - Filling up the DagBag from /opt/airflow/dags/create_postgres_app.py
[2025-06-18T05:03:03.525+0000] {logging_mixin.py:190} INFO - [2025-06-18T05:03:03.512+0000] {dagbag.py:387} ERROR - Failed to import: /opt/airflow/dags/create_postgres_app.py
Traceback (most recent call last):
  File "/home/airflow/.local/lib/python3.12/site-packages/airflow/models/dagbag.py", line 383, in parse
    loader.exec_module(new_module)
  File "<frozen importlib._bootstrap_external>", line 995, in exec_module
  File "<frozen importlib._bootstrap>", line 488, in _call_with_frames_removed
  File "/opt/airflow/dags/create_postgres_app.py", line 8, in <module>
    'start_date': datetime(2025, 6, 11),
                  ^^^^^^^^^^^^^^^^^^^^^
TypeError: 'module' object is not callable. Did you mean: 'datetime.datetime(...)'?
[2025-06-18T05:03:03.529+0000] {processor.py:927} WARNING - No viable dags retrieved from /opt/airflow/dags/create_postgres_app.py
[2025-06-18T05:03:03.573+0000] {processor.py:208} INFO - Processing /opt/airflow/dags/create_postgres_app.py took 0.131 seconds
[2025-06-18T05:03:34.672+0000] {processor.py:186} INFO - Started process (PID=519) to work on /opt/airflow/dags/create_postgres_app.py
[2025-06-18T05:03:34.684+0000] {processor.py:914} INFO - Processing file /opt/airflow/dags/create_postgres_app.py for tasks to queue
[2025-06-18T05:03:34.696+0000] {logging_mixin.py:190} INFO - [2025-06-18T05:03:34.691+0000] {dagbag.py:588} INFO - Filling up the DagBag from /opt/airflow/dags/create_postgres_app.py
[2025-06-18T05:03:34.931+0000] {logging_mixin.py:190} INFO - [2025-06-18T05:03:34.895+0000] {dagbag.py:387} ERROR - Failed to import: /opt/airflow/dags/create_postgres_app.py
Traceback (most recent call last):
  File "/home/airflow/.local/lib/python3.12/site-packages/airflow/models/dagbag.py", line 383, in parse
    loader.exec_module(new_module)
  File "<frozen importlib._bootstrap_external>", line 995, in exec_module
  File "<frozen importlib._bootstrap>", line 488, in _call_with_frames_removed
  File "/opt/airflow/dags/create_postgres_app.py", line 8, in <module>
    'start_date': datetime(2025, 6, 11),
                  ^^^^^^^^^^^^^^^^^^^^^
TypeError: 'module' object is not callable. Did you mean: 'datetime.datetime(...)'?
[2025-06-18T05:03:34.945+0000] {processor.py:927} WARNING - No viable dags retrieved from /opt/airflow/dags/create_postgres_app.py
[2025-06-18T05:03:35.049+0000] {processor.py:208} INFO - Processing /opt/airflow/dags/create_postgres_app.py took 0.422 seconds
[2025-06-18T05:04:05.227+0000] {processor.py:186} INFO - Started process (PID=531) to work on /opt/airflow/dags/create_postgres_app.py
[2025-06-18T05:04:05.231+0000] {processor.py:914} INFO - Processing file /opt/airflow/dags/create_postgres_app.py for tasks to queue
[2025-06-18T05:04:05.235+0000] {logging_mixin.py:190} INFO - [2025-06-18T05:04:05.234+0000] {dagbag.py:588} INFO - Filling up the DagBag from /opt/airflow/dags/create_postgres_app.py
[2025-06-18T05:04:05.296+0000] {logging_mixin.py:190} INFO - [2025-06-18T05:04:05.283+0000] {dagbag.py:387} ERROR - Failed to import: /opt/airflow/dags/create_postgres_app.py
Traceback (most recent call last):
  File "/home/airflow/.local/lib/python3.12/site-packages/airflow/models/dagbag.py", line 383, in parse
    loader.exec_module(new_module)
  File "<frozen importlib._bootstrap_external>", line 995, in exec_module
  File "<frozen importlib._bootstrap>", line 488, in _call_with_frames_removed
  File "/opt/airflow/dags/create_postgres_app.py", line 8, in <module>
    'start_date': datetime(2025, 6, 11),
                  ^^^^^^^^^^^^^^^^^^^^^
TypeError: 'module' object is not callable. Did you mean: 'datetime.datetime(...)'?
[2025-06-18T05:04:05.302+0000] {processor.py:927} WARNING - No viable dags retrieved from /opt/airflow/dags/create_postgres_app.py
[2025-06-18T05:04:05.349+0000] {processor.py:208} INFO - Processing /opt/airflow/dags/create_postgres_app.py took 0.141 seconds
[2025-06-18T05:04:36.240+0000] {processor.py:186} INFO - Started process (PID=543) to work on /opt/airflow/dags/create_postgres_app.py
[2025-06-18T05:04:36.244+0000] {processor.py:914} INFO - Processing file /opt/airflow/dags/create_postgres_app.py for tasks to queue
[2025-06-18T05:04:36.250+0000] {logging_mixin.py:190} INFO - [2025-06-18T05:04:36.249+0000] {dagbag.py:588} INFO - Filling up the DagBag from /opt/airflow/dags/create_postgres_app.py
[2025-06-18T05:04:36.318+0000] {logging_mixin.py:190} INFO - [2025-06-18T05:04:36.303+0000] {dagbag.py:387} ERROR - Failed to import: /opt/airflow/dags/create_postgres_app.py
Traceback (most recent call last):
  File "/home/airflow/.local/lib/python3.12/site-packages/airflow/models/dagbag.py", line 383, in parse
    loader.exec_module(new_module)
  File "<frozen importlib._bootstrap_external>", line 995, in exec_module
  File "<frozen importlib._bootstrap>", line 488, in _call_with_frames_removed
  File "/opt/airflow/dags/create_postgres_app.py", line 8, in <module>
    'start_date': datetime(2025, 6, 11),
                  ^^^^^^^^^^^^^^^^^^^^^
TypeError: 'module' object is not callable. Did you mean: 'datetime.datetime(...)'?
[2025-06-18T05:04:36.325+0000] {processor.py:927} WARNING - No viable dags retrieved from /opt/airflow/dags/create_postgres_app.py
[2025-06-18T05:04:36.378+0000] {processor.py:208} INFO - Processing /opt/airflow/dags/create_postgres_app.py took 0.159 seconds
[2025-06-18T05:05:06.634+0000] {processor.py:186} INFO - Started process (PID=554) to work on /opt/airflow/dags/create_postgres_app.py
[2025-06-18T05:05:06.637+0000] {processor.py:914} INFO - Processing file /opt/airflow/dags/create_postgres_app.py for tasks to queue
[2025-06-18T05:05:06.642+0000] {logging_mixin.py:190} INFO - [2025-06-18T05:05:06.641+0000] {dagbag.py:588} INFO - Filling up the DagBag from /opt/airflow/dags/create_postgres_app.py
[2025-06-18T05:05:06.796+0000] {logging_mixin.py:190} INFO - [2025-06-18T05:05:06.778+0000] {dagbag.py:387} ERROR - Failed to import: /opt/airflow/dags/create_postgres_app.py
Traceback (most recent call last):
  File "/home/airflow/.local/lib/python3.12/site-packages/airflow/models/dagbag.py", line 383, in parse
    loader.exec_module(new_module)
  File "<frozen importlib._bootstrap_external>", line 995, in exec_module
  File "<frozen importlib._bootstrap>", line 488, in _call_with_frames_removed
  File "/opt/airflow/dags/create_postgres_app.py", line 8, in <module>
    'start_date': datetime(2025, 6, 11),
                  ^^^^^^^^^^^^^^^^^^^^^
TypeError: 'module' object is not callable. Did you mean: 'datetime.datetime(...)'?
[2025-06-18T05:05:06.809+0000] {processor.py:927} WARNING - No viable dags retrieved from /opt/airflow/dags/create_postgres_app.py
[2025-06-18T05:05:06.910+0000] {processor.py:208} INFO - Processing /opt/airflow/dags/create_postgres_app.py took 0.300 seconds
[2025-06-18T05:05:37.634+0000] {processor.py:186} INFO - Started process (PID=567) to work on /opt/airflow/dags/create_postgres_app.py
[2025-06-18T05:05:37.645+0000] {processor.py:914} INFO - Processing file /opt/airflow/dags/create_postgres_app.py for tasks to queue
[2025-06-18T05:05:37.650+0000] {logging_mixin.py:190} INFO - [2025-06-18T05:05:37.649+0000] {dagbag.py:588} INFO - Filling up the DagBag from /opt/airflow/dags/create_postgres_app.py
[2025-06-18T05:05:37.711+0000] {logging_mixin.py:190} INFO - [2025-06-18T05:05:37.698+0000] {dagbag.py:387} ERROR - Failed to import: /opt/airflow/dags/create_postgres_app.py
Traceback (most recent call last):
  File "/home/airflow/.local/lib/python3.12/site-packages/airflow/models/dagbag.py", line 383, in parse
    loader.exec_module(new_module)
  File "<frozen importlib._bootstrap_external>", line 995, in exec_module
  File "<frozen importlib._bootstrap>", line 488, in _call_with_frames_removed
  File "/opt/airflow/dags/create_postgres_app.py", line 8, in <module>
    'start_date': datetime(2025, 6, 11),
                  ^^^^^^^^^^^^^^^^^^^^^
TypeError: 'module' object is not callable. Did you mean: 'datetime.datetime(...)'?
[2025-06-18T05:05:37.717+0000] {processor.py:927} WARNING - No viable dags retrieved from /opt/airflow/dags/create_postgres_app.py
[2025-06-18T05:05:37.779+0000] {processor.py:208} INFO - Processing /opt/airflow/dags/create_postgres_app.py took 0.171 seconds
[2025-06-18T05:06:08.314+0000] {processor.py:186} INFO - Started process (PID=579) to work on /opt/airflow/dags/create_postgres_app.py
[2025-06-18T05:06:08.319+0000] {processor.py:914} INFO - Processing file /opt/airflow/dags/create_postgres_app.py for tasks to queue
[2025-06-18T05:06:08.325+0000] {logging_mixin.py:190} INFO - [2025-06-18T05:06:08.323+0000] {dagbag.py:588} INFO - Filling up the DagBag from /opt/airflow/dags/create_postgres_app.py
[2025-06-18T05:06:08.391+0000] {logging_mixin.py:190} INFO - [2025-06-18T05:06:08.373+0000] {dagbag.py:387} ERROR - Failed to import: /opt/airflow/dags/create_postgres_app.py
Traceback (most recent call last):
  File "/home/airflow/.local/lib/python3.12/site-packages/airflow/models/dagbag.py", line 383, in parse
    loader.exec_module(new_module)
  File "<frozen importlib._bootstrap_external>", line 995, in exec_module
  File "<frozen importlib._bootstrap>", line 488, in _call_with_frames_removed
  File "/opt/airflow/dags/create_postgres_app.py", line 8, in <module>
    'start_date': datetime(2025, 6, 11),
                  ^^^^^^^^^^^^^^^^^^^^^
TypeError: 'module' object is not callable. Did you mean: 'datetime.datetime(...)'?
[2025-06-18T05:06:08.395+0000] {processor.py:927} WARNING - No viable dags retrieved from /opt/airflow/dags/create_postgres_app.py
[2025-06-18T05:06:08.586+0000] {processor.py:208} INFO - Processing /opt/airflow/dags/create_postgres_app.py took 0.296 seconds
[2025-06-18T05:06:39.462+0000] {processor.py:186} INFO - Started process (PID=592) to work on /opt/airflow/dags/create_postgres_app.py
[2025-06-18T05:06:39.466+0000] {processor.py:914} INFO - Processing file /opt/airflow/dags/create_postgres_app.py for tasks to queue
[2025-06-18T05:06:39.470+0000] {logging_mixin.py:190} INFO - [2025-06-18T05:06:39.469+0000] {dagbag.py:588} INFO - Filling up the DagBag from /opt/airflow/dags/create_postgres_app.py
[2025-06-18T05:06:39.529+0000] {logging_mixin.py:190} INFO - [2025-06-18T05:06:39.515+0000] {dagbag.py:387} ERROR - Failed to import: /opt/airflow/dags/create_postgres_app.py
Traceback (most recent call last):
  File "/home/airflow/.local/lib/python3.12/site-packages/airflow/models/dagbag.py", line 383, in parse
    loader.exec_module(new_module)
  File "<frozen importlib._bootstrap_external>", line 995, in exec_module
  File "<frozen importlib._bootstrap>", line 488, in _call_with_frames_removed
  File "/opt/airflow/dags/create_postgres_app.py", line 8, in <module>
    'start_date': datetime(2025, 6, 11),
                  ^^^^^^^^^^^^^^^^^^^^^
TypeError: 'module' object is not callable. Did you mean: 'datetime.datetime(...)'?
[2025-06-18T05:06:39.534+0000] {processor.py:927} WARNING - No viable dags retrieved from /opt/airflow/dags/create_postgres_app.py
[2025-06-18T05:06:39.585+0000] {processor.py:208} INFO - Processing /opt/airflow/dags/create_postgres_app.py took 0.148 seconds
[2025-06-18T05:07:10.007+0000] {processor.py:186} INFO - Started process (PID=604) to work on /opt/airflow/dags/create_postgres_app.py
[2025-06-18T05:07:10.014+0000] {processor.py:914} INFO - Processing file /opt/airflow/dags/create_postgres_app.py for tasks to queue
[2025-06-18T05:07:10.020+0000] {logging_mixin.py:190} INFO - [2025-06-18T05:07:10.019+0000] {dagbag.py:588} INFO - Filling up the DagBag from /opt/airflow/dags/create_postgres_app.py
[2025-06-18T05:07:10.084+0000] {logging_mixin.py:190} INFO - [2025-06-18T05:07:10.072+0000] {dagbag.py:387} ERROR - Failed to import: /opt/airflow/dags/create_postgres_app.py
Traceback (most recent call last):
  File "/home/airflow/.local/lib/python3.12/site-packages/airflow/models/dagbag.py", line 383, in parse
    loader.exec_module(new_module)
  File "<frozen importlib._bootstrap_external>", line 995, in exec_module
  File "<frozen importlib._bootstrap>", line 488, in _call_with_frames_removed
  File "/opt/airflow/dags/create_postgres_app.py", line 8, in <module>
    'start_date': datetime(2025, 6, 11),
                  ^^^^^^^^^^^^^^^^^^^^^
TypeError: 'module' object is not callable. Did you mean: 'datetime.datetime(...)'?
[2025-06-18T05:07:10.088+0000] {processor.py:927} WARNING - No viable dags retrieved from /opt/airflow/dags/create_postgres_app.py
[2025-06-18T05:07:10.199+0000] {processor.py:208} INFO - Processing /opt/airflow/dags/create_postgres_app.py took 0.226 seconds
[2025-06-18T05:07:40.673+0000] {processor.py:186} INFO - Started process (PID=616) to work on /opt/airflow/dags/create_postgres_app.py
[2025-06-18T05:07:40.676+0000] {processor.py:914} INFO - Processing file /opt/airflow/dags/create_postgres_app.py for tasks to queue
[2025-06-18T05:07:40.681+0000] {logging_mixin.py:190} INFO - [2025-06-18T05:07:40.680+0000] {dagbag.py:588} INFO - Filling up the DagBag from /opt/airflow/dags/create_postgres_app.py
[2025-06-18T05:07:40.742+0000] {logging_mixin.py:190} INFO - [2025-06-18T05:07:40.728+0000] {dagbag.py:387} ERROR - Failed to import: /opt/airflow/dags/create_postgres_app.py
Traceback (most recent call last):
  File "/home/airflow/.local/lib/python3.12/site-packages/airflow/models/dagbag.py", line 383, in parse
    loader.exec_module(new_module)
  File "<frozen importlib._bootstrap_external>", line 995, in exec_module
  File "<frozen importlib._bootstrap>", line 488, in _call_with_frames_removed
  File "/opt/airflow/dags/create_postgres_app.py", line 8, in <module>
    'start_date': datetime(2025, 6, 11),
                  ^^^^^^^^^^^^^^^^^^^^^
TypeError: 'module' object is not callable. Did you mean: 'datetime.datetime(...)'?
[2025-06-18T05:07:40.750+0000] {processor.py:927} WARNING - No viable dags retrieved from /opt/airflow/dags/create_postgres_app.py
[2025-06-18T05:07:40.805+0000] {processor.py:208} INFO - Processing /opt/airflow/dags/create_postgres_app.py took 0.150 seconds
[2025-06-18T05:08:11.440+0000] {processor.py:186} INFO - Started process (PID=628) to work on /opt/airflow/dags/create_postgres_app.py
[2025-06-18T05:08:11.444+0000] {processor.py:914} INFO - Processing file /opt/airflow/dags/create_postgres_app.py for tasks to queue
[2025-06-18T05:08:11.449+0000] {logging_mixin.py:190} INFO - [2025-06-18T05:08:11.448+0000] {dagbag.py:588} INFO - Filling up the DagBag from /opt/airflow/dags/create_postgres_app.py
[2025-06-18T05:08:11.502+0000] {logging_mixin.py:190} INFO - [2025-06-18T05:08:11.488+0000] {dagbag.py:387} ERROR - Failed to import: /opt/airflow/dags/create_postgres_app.py
Traceback (most recent call last):
  File "/home/airflow/.local/lib/python3.12/site-packages/airflow/models/dagbag.py", line 383, in parse
    loader.exec_module(new_module)
  File "<frozen importlib._bootstrap_external>", line 995, in exec_module
  File "<frozen importlib._bootstrap>", line 488, in _call_with_frames_removed
  File "/opt/airflow/dags/create_postgres_app.py", line 8, in <module>
    'start_date': datetime(2025, 6, 11),
                  ^^^^^^^^^^^^^^^^^^^^^
TypeError: 'module' object is not callable. Did you mean: 'datetime.datetime(...)'?
[2025-06-18T05:08:11.508+0000] {processor.py:927} WARNING - No viable dags retrieved from /opt/airflow/dags/create_postgres_app.py
[2025-06-18T05:08:11.568+0000] {processor.py:208} INFO - Processing /opt/airflow/dags/create_postgres_app.py took 0.149 seconds
[2025-06-18T05:08:42.001+0000] {processor.py:186} INFO - Started process (PID=640) to work on /opt/airflow/dags/create_postgres_app.py
[2025-06-18T05:08:42.005+0000] {processor.py:914} INFO - Processing file /opt/airflow/dags/create_postgres_app.py for tasks to queue
[2025-06-18T05:08:42.013+0000] {logging_mixin.py:190} INFO - [2025-06-18T05:08:42.011+0000] {dagbag.py:588} INFO - Filling up the DagBag from /opt/airflow/dags/create_postgres_app.py
[2025-06-18T05:08:42.077+0000] {logging_mixin.py:190} INFO - [2025-06-18T05:08:42.062+0000] {dagbag.py:387} ERROR - Failed to import: /opt/airflow/dags/create_postgres_app.py
Traceback (most recent call last):
  File "/home/airflow/.local/lib/python3.12/site-packages/airflow/models/dagbag.py", line 383, in parse
    loader.exec_module(new_module)
  File "<frozen importlib._bootstrap_external>", line 995, in exec_module
  File "<frozen importlib._bootstrap>", line 488, in _call_with_frames_removed
  File "/opt/airflow/dags/create_postgres_app.py", line 8, in <module>
    'start_date': datetime(2025, 6, 11),
                  ^^^^^^^^^^^^^^^^^^^^^
TypeError: 'module' object is not callable. Did you mean: 'datetime.datetime(...)'?
[2025-06-18T05:08:42.082+0000] {processor.py:927} WARNING - No viable dags retrieved from /opt/airflow/dags/create_postgres_app.py
[2025-06-18T05:08:42.184+0000] {processor.py:208} INFO - Processing /opt/airflow/dags/create_postgres_app.py took 0.215 seconds
[2025-06-18T05:09:13.215+0000] {processor.py:186} INFO - Started process (PID=652) to work on /opt/airflow/dags/create_postgres_app.py
[2025-06-18T05:09:13.229+0000] {processor.py:914} INFO - Processing file /opt/airflow/dags/create_postgres_app.py for tasks to queue
[2025-06-18T05:09:13.239+0000] {logging_mixin.py:190} INFO - [2025-06-18T05:09:13.238+0000] {dagbag.py:588} INFO - Filling up the DagBag from /opt/airflow/dags/create_postgres_app.py
[2025-06-18T05:09:13.440+0000] {logging_mixin.py:190} INFO - [2025-06-18T05:09:13.343+0000] {dagbag.py:387} ERROR - Failed to import: /opt/airflow/dags/create_postgres_app.py
Traceback (most recent call last):
  File "/home/airflow/.local/lib/python3.12/site-packages/airflow/models/dagbag.py", line 383, in parse
    loader.exec_module(new_module)
  File "<frozen importlib._bootstrap_external>", line 995, in exec_module
  File "<frozen importlib._bootstrap>", line 488, in _call_with_frames_removed
  File "/opt/airflow/dags/create_postgres_app.py", line 8, in <module>
    'start_date': datetime(2025, 6, 11),
                  ^^^^^^^^^^^^^^^^^^^^^
TypeError: 'module' object is not callable. Did you mean: 'datetime.datetime(...)'?
[2025-06-18T05:09:13.501+0000] {processor.py:927} WARNING - No viable dags retrieved from /opt/airflow/dags/create_postgres_app.py
[2025-06-18T05:09:13.705+0000] {processor.py:208} INFO - Processing /opt/airflow/dags/create_postgres_app.py took 0.531 seconds
[2025-06-18T05:09:44.088+0000] {processor.py:186} INFO - Started process (PID=664) to work on /opt/airflow/dags/create_postgres_app.py
[2025-06-18T05:09:44.091+0000] {processor.py:914} INFO - Processing file /opt/airflow/dags/create_postgres_app.py for tasks to queue
[2025-06-18T05:09:44.095+0000] {logging_mixin.py:190} INFO - [2025-06-18T05:09:44.094+0000] {dagbag.py:588} INFO - Filling up the DagBag from /opt/airflow/dags/create_postgres_app.py
[2025-06-18T05:09:44.168+0000] {logging_mixin.py:190} INFO - [2025-06-18T05:09:44.155+0000] {dagbag.py:387} ERROR - Failed to import: /opt/airflow/dags/create_postgres_app.py
Traceback (most recent call last):
  File "/home/airflow/.local/lib/python3.12/site-packages/airflow/models/dagbag.py", line 383, in parse
    loader.exec_module(new_module)
  File "<frozen importlib._bootstrap_external>", line 995, in exec_module
  File "<frozen importlib._bootstrap>", line 488, in _call_with_frames_removed
  File "/opt/airflow/dags/create_postgres_app.py", line 8, in <module>
    'start_date': datetime(2025, 6, 11),
                  ^^^^^^^^^^^^^^^^^^^^^
TypeError: 'module' object is not callable. Did you mean: 'datetime.datetime(...)'?
[2025-06-18T05:09:44.174+0000] {processor.py:927} WARNING - No viable dags retrieved from /opt/airflow/dags/create_postgres_app.py
[2025-06-18T05:09:44.259+0000] {processor.py:208} INFO - Processing /opt/airflow/dags/create_postgres_app.py took 0.189 seconds
[2025-06-18T05:10:14.696+0000] {processor.py:186} INFO - Started process (PID=676) to work on /opt/airflow/dags/create_postgres_app.py
[2025-06-18T05:10:14.699+0000] {processor.py:914} INFO - Processing file /opt/airflow/dags/create_postgres_app.py for tasks to queue
[2025-06-18T05:10:14.710+0000] {logging_mixin.py:190} INFO - [2025-06-18T05:10:14.707+0000] {dagbag.py:588} INFO - Filling up the DagBag from /opt/airflow/dags/create_postgres_app.py
[2025-06-18T05:10:14.985+0000] {logging_mixin.py:190} INFO - [2025-06-18T05:10:14.969+0000] {dagbag.py:387} ERROR - Failed to import: /opt/airflow/dags/create_postgres_app.py
Traceback (most recent call last):
  File "/home/airflow/.local/lib/python3.12/site-packages/airflow/models/dagbag.py", line 383, in parse
    loader.exec_module(new_module)
  File "<frozen importlib._bootstrap_external>", line 995, in exec_module
  File "<frozen importlib._bootstrap>", line 488, in _call_with_frames_removed
  File "/opt/airflow/dags/create_postgres_app.py", line 8, in <module>
    'start_date': datetime(2025, 6, 11),
                  ^^^^^^^^^^^^^^^^^^^^^
TypeError: 'module' object is not callable. Did you mean: 'datetime.datetime(...)'?
[2025-06-18T05:10:14.992+0000] {processor.py:927} WARNING - No viable dags retrieved from /opt/airflow/dags/create_postgres_app.py
[2025-06-18T05:10:15.052+0000] {processor.py:208} INFO - Processing /opt/airflow/dags/create_postgres_app.py took 0.389 seconds
