[2025-05-30T04:38:17.722+0000] {processor.py:186} INFO - Started process (PID=828) to work on /opt/airflow/dags/data_quality.py
[2025-05-30T04:38:17.746+0000] {processor.py:914} INFO - Processing file /opt/airflow/dags/data_quality.py for tasks to queue
[2025-05-30T04:38:17.764+0000] {logging_mixin.py:190} INFO - [2025-05-30T04:38:17.763+0000] {dagbag.py:588} INFO - Filling up the DagBag from /opt/airflow/dags/data_quality.py
[2025-05-30T04:38:21.012+0000] {logging_mixin.py:190} INFO - [2025-05-30T04:38:20.983+0000] {dagbag.py:484} ERROR - Failed to bag_dag: /opt/airflow/dags/data_quality.py
Traceback (most recent call last):
  File "/home/airflow/.local/lib/python3.12/site-packages/airflow/timetables/_cron.py", line 102, in validate
    croniter(self._expression)
  File "/home/airflow/.local/lib/python3.12/site-packages/croniter/croniter.py", line 271, in __init__
    self.expanded, self.nth_weekday_of_month = self.expand(
                                               ^^^^^^^^^^^^
  File "/home/airflow/.local/lib/python3.12/site-packages/croniter/croniter.py", line 1032, in expand
    return cls._expand(expr_format, hash_id=hash_id,
           ^^^^^^^^^^^^^^^^^^^^^^^^^^^^^^^^^^^^^^^^^
  File "/home/airflow/.local/lib/python3.12/site-packages/croniter/croniter.py", line 834, in _expand
    raise CroniterBadCronError(cls.bad_length)
croniter.croniter.CroniterBadCronError: Exactly 5, 6 or 7 columns has to be specified for iterator expression.

During handling of the above exception, another exception occurred:

Traceback (most recent call last):
  File "/home/airflow/.local/lib/python3.12/site-packages/airflow/models/dagbag.py", line 479, in _process_modules
    dag.validate()
  File "/home/airflow/.local/lib/python3.12/site-packages/airflow/models/dag.py", line 845, in validate
    self.timetable.validate()
  File "/home/airflow/.local/lib/python3.12/site-packages/airflow/timetables/_cron.py", line 104, in validate
    raise AirflowTimetableInvalid(str(e))
airflow.exceptions.AirflowTimetableInvalid: Exactly 5, 6 or 7 columns has to be specified for iterator expression.
[2025-05-30T04:38:21.018+0000] {processor.py:927} WARNING - No viable dags retrieved from /opt/airflow/dags/data_quality.py
[2025-05-30T04:38:21.165+0000] {processor.py:208} INFO - Processing /opt/airflow/dags/data_quality.py took 3.492 seconds
[2025-05-30T04:38:51.691+0000] {processor.py:186} INFO - Started process (PID=841) to work on /opt/airflow/dags/data_quality.py
[2025-05-30T04:38:51.696+0000] {processor.py:914} INFO - Processing file /opt/airflow/dags/data_quality.py for tasks to queue
[2025-05-30T04:38:51.709+0000] {logging_mixin.py:190} INFO - [2025-05-30T04:38:51.707+0000] {dagbag.py:588} INFO - Filling up the DagBag from /opt/airflow/dags/data_quality.py
[2025-05-30T04:38:53.158+0000] {logging_mixin.py:190} INFO - [2025-05-30T04:38:53.151+0000] {dagbag.py:484} ERROR - Failed to bag_dag: /opt/airflow/dags/data_quality.py
Traceback (most recent call last):
  File "/home/airflow/.local/lib/python3.12/site-packages/airflow/timetables/_cron.py", line 102, in validate
    croniter(self._expression)
  File "/home/airflow/.local/lib/python3.12/site-packages/croniter/croniter.py", line 271, in __init__
    self.expanded, self.nth_weekday_of_month = self.expand(
                                               ^^^^^^^^^^^^
  File "/home/airflow/.local/lib/python3.12/site-packages/croniter/croniter.py", line 1032, in expand
    return cls._expand(expr_format, hash_id=hash_id,
           ^^^^^^^^^^^^^^^^^^^^^^^^^^^^^^^^^^^^^^^^^
  File "/home/airflow/.local/lib/python3.12/site-packages/croniter/croniter.py", line 834, in _expand
    raise CroniterBadCronError(cls.bad_length)
croniter.croniter.CroniterBadCronError: Exactly 5, 6 or 7 columns has to be specified for iterator expression.

During handling of the above exception, another exception occurred:

Traceback (most recent call last):
  File "/home/airflow/.local/lib/python3.12/site-packages/airflow/models/dagbag.py", line 479, in _process_modules
    dag.validate()
  File "/home/airflow/.local/lib/python3.12/site-packages/airflow/models/dag.py", line 845, in validate
    self.timetable.validate()
  File "/home/airflow/.local/lib/python3.12/site-packages/airflow/timetables/_cron.py", line 104, in validate
    raise AirflowTimetableInvalid(str(e))
airflow.exceptions.AirflowTimetableInvalid: Exactly 5, 6 or 7 columns has to be specified for iterator expression.
[2025-05-30T04:38:53.159+0000] {processor.py:927} WARNING - No viable dags retrieved from /opt/airflow/dags/data_quality.py
[2025-05-30T04:38:53.212+0000] {processor.py:208} INFO - Processing /opt/airflow/dags/data_quality.py took 1.546 seconds
[2025-05-30T04:39:24.187+0000] {processor.py:186} INFO - Started process (PID=855) to work on /opt/airflow/dags/data_quality.py
[2025-05-30T04:39:24.190+0000] {processor.py:914} INFO - Processing file /opt/airflow/dags/data_quality.py for tasks to queue
[2025-05-30T04:39:24.197+0000] {logging_mixin.py:190} INFO - [2025-05-30T04:39:24.196+0000] {dagbag.py:588} INFO - Filling up the DagBag from /opt/airflow/dags/data_quality.py
[2025-05-30T04:39:25.153+0000] {logging_mixin.py:190} INFO - [2025-05-30T04:39:25.146+0000] {dagbag.py:484} ERROR - Failed to bag_dag: /opt/airflow/dags/data_quality.py
Traceback (most recent call last):
  File "/home/airflow/.local/lib/python3.12/site-packages/airflow/timetables/_cron.py", line 102, in validate
    croniter(self._expression)
  File "/home/airflow/.local/lib/python3.12/site-packages/croniter/croniter.py", line 271, in __init__
    self.expanded, self.nth_weekday_of_month = self.expand(
                                               ^^^^^^^^^^^^
  File "/home/airflow/.local/lib/python3.12/site-packages/croniter/croniter.py", line 1032, in expand
    return cls._expand(expr_format, hash_id=hash_id,
           ^^^^^^^^^^^^^^^^^^^^^^^^^^^^^^^^^^^^^^^^^
  File "/home/airflow/.local/lib/python3.12/site-packages/croniter/croniter.py", line 834, in _expand
    raise CroniterBadCronError(cls.bad_length)
croniter.croniter.CroniterBadCronError: Exactly 5, 6 or 7 columns has to be specified for iterator expression.

During handling of the above exception, another exception occurred:

Traceback (most recent call last):
  File "/home/airflow/.local/lib/python3.12/site-packages/airflow/models/dagbag.py", line 479, in _process_modules
    dag.validate()
  File "/home/airflow/.local/lib/python3.12/site-packages/airflow/models/dag.py", line 845, in validate
    self.timetable.validate()
  File "/home/airflow/.local/lib/python3.12/site-packages/airflow/timetables/_cron.py", line 104, in validate
    raise AirflowTimetableInvalid(str(e))
airflow.exceptions.AirflowTimetableInvalid: Exactly 5, 6 or 7 columns has to be specified for iterator expression.
[2025-05-30T04:39:25.154+0000] {processor.py:927} WARNING - No viable dags retrieved from /opt/airflow/dags/data_quality.py
[2025-05-30T04:39:25.201+0000] {processor.py:208} INFO - Processing /opt/airflow/dags/data_quality.py took 1.032 seconds
[2025-05-30T15:11:53.516+0000] {processor.py:186} INFO - Started process (PID=867) to work on /opt/airflow/dags/data_quality.py
[2025-05-30T15:11:53.524+0000] {processor.py:914} INFO - Processing file /opt/airflow/dags/data_quality.py for tasks to queue
[2025-05-30T15:11:53.565+0000] {logging_mixin.py:190} INFO - [2025-05-30T15:11:53.564+0000] {dagbag.py:588} INFO - Filling up the DagBag from /opt/airflow/dags/data_quality.py
[2025-05-30T15:11:57.553+0000] {logging_mixin.py:190} INFO - [2025-05-30T15:11:57.487+0000] {dagbag.py:484} ERROR - Failed to bag_dag: /opt/airflow/dags/data_quality.py
Traceback (most recent call last):
  File "/home/airflow/.local/lib/python3.12/site-packages/airflow/timetables/_cron.py", line 102, in validate
    croniter(self._expression)
  File "/home/airflow/.local/lib/python3.12/site-packages/croniter/croniter.py", line 271, in __init__
    self.expanded, self.nth_weekday_of_month = self.expand(
                                               ^^^^^^^^^^^^
  File "/home/airflow/.local/lib/python3.12/site-packages/croniter/croniter.py", line 1032, in expand
    return cls._expand(expr_format, hash_id=hash_id,
           ^^^^^^^^^^^^^^^^^^^^^^^^^^^^^^^^^^^^^^^^^
  File "/home/airflow/.local/lib/python3.12/site-packages/croniter/croniter.py", line 834, in _expand
    raise CroniterBadCronError(cls.bad_length)
croniter.croniter.CroniterBadCronError: Exactly 5, 6 or 7 columns has to be specified for iterator expression.

During handling of the above exception, another exception occurred:

Traceback (most recent call last):
  File "/home/airflow/.local/lib/python3.12/site-packages/airflow/models/dagbag.py", line 479, in _process_modules
    dag.validate()
  File "/home/airflow/.local/lib/python3.12/site-packages/airflow/models/dag.py", line 845, in validate
    self.timetable.validate()
  File "/home/airflow/.local/lib/python3.12/site-packages/airflow/timetables/_cron.py", line 104, in validate
    raise AirflowTimetableInvalid(str(e))
airflow.exceptions.AirflowTimetableInvalid: Exactly 5, 6 or 7 columns has to be specified for iterator expression.
[2025-05-30T15:11:57.603+0000] {processor.py:927} WARNING - No viable dags retrieved from /opt/airflow/dags/data_quality.py
[2025-05-30T15:11:57.857+0000] {processor.py:208} INFO - Processing /opt/airflow/dags/data_quality.py took 4.460 seconds
[2025-05-30T15:12:28.680+0000] {processor.py:186} INFO - Started process (PID=881) to work on /opt/airflow/dags/data_quality.py
[2025-05-30T15:12:28.696+0000] {processor.py:914} INFO - Processing file /opt/airflow/dags/data_quality.py for tasks to queue
[2025-05-30T15:12:28.721+0000] {logging_mixin.py:190} INFO - [2025-05-30T15:12:28.720+0000] {dagbag.py:588} INFO - Filling up the DagBag from /opt/airflow/dags/data_quality.py
[2025-05-30T15:12:31.152+0000] {logging_mixin.py:190} INFO - [2025-05-30T15:12:31.122+0000] {dagbag.py:484} ERROR - Failed to bag_dag: /opt/airflow/dags/data_quality.py
Traceback (most recent call last):
  File "/home/airflow/.local/lib/python3.12/site-packages/airflow/timetables/_cron.py", line 102, in validate
    croniter(self._expression)
  File "/home/airflow/.local/lib/python3.12/site-packages/croniter/croniter.py", line 271, in __init__
    self.expanded, self.nth_weekday_of_month = self.expand(
                                               ^^^^^^^^^^^^
  File "/home/airflow/.local/lib/python3.12/site-packages/croniter/croniter.py", line 1032, in expand
    return cls._expand(expr_format, hash_id=hash_id,
           ^^^^^^^^^^^^^^^^^^^^^^^^^^^^^^^^^^^^^^^^^
  File "/home/airflow/.local/lib/python3.12/site-packages/croniter/croniter.py", line 834, in _expand
    raise CroniterBadCronError(cls.bad_length)
croniter.croniter.CroniterBadCronError: Exactly 5, 6 or 7 columns has to be specified for iterator expression.

During handling of the above exception, another exception occurred:

Traceback (most recent call last):
  File "/home/airflow/.local/lib/python3.12/site-packages/airflow/models/dagbag.py", line 479, in _process_modules
    dag.validate()
  File "/home/airflow/.local/lib/python3.12/site-packages/airflow/models/dag.py", line 845, in validate
    self.timetable.validate()
  File "/home/airflow/.local/lib/python3.12/site-packages/airflow/timetables/_cron.py", line 104, in validate
    raise AirflowTimetableInvalid(str(e))
airflow.exceptions.AirflowTimetableInvalid: Exactly 5, 6 or 7 columns has to be specified for iterator expression.
[2025-05-30T15:12:31.177+0000] {processor.py:927} WARNING - No viable dags retrieved from /opt/airflow/dags/data_quality.py
[2025-05-30T15:12:31.314+0000] {processor.py:208} INFO - Processing /opt/airflow/dags/data_quality.py took 2.689 seconds
[2025-05-30T15:13:01.797+0000] {processor.py:186} INFO - Started process (PID=902) to work on /opt/airflow/dags/data_quality.py
[2025-05-30T15:13:01.801+0000] {processor.py:914} INFO - Processing file /opt/airflow/dags/data_quality.py for tasks to queue
[2025-05-30T15:13:01.818+0000] {logging_mixin.py:190} INFO - [2025-05-30T15:13:01.816+0000] {dagbag.py:588} INFO - Filling up the DagBag from /opt/airflow/dags/data_quality.py
[2025-05-30T15:13:02.991+0000] {logging_mixin.py:190} INFO - [2025-05-30T15:13:02.983+0000] {dagbag.py:484} ERROR - Failed to bag_dag: /opt/airflow/dags/data_quality.py
Traceback (most recent call last):
  File "/home/airflow/.local/lib/python3.12/site-packages/airflow/timetables/_cron.py", line 102, in validate
    croniter(self._expression)
  File "/home/airflow/.local/lib/python3.12/site-packages/croniter/croniter.py", line 271, in __init__
    self.expanded, self.nth_weekday_of_month = self.expand(
                                               ^^^^^^^^^^^^
  File "/home/airflow/.local/lib/python3.12/site-packages/croniter/croniter.py", line 1032, in expand
    return cls._expand(expr_format, hash_id=hash_id,
           ^^^^^^^^^^^^^^^^^^^^^^^^^^^^^^^^^^^^^^^^^
  File "/home/airflow/.local/lib/python3.12/site-packages/croniter/croniter.py", line 834, in _expand
    raise CroniterBadCronError(cls.bad_length)
croniter.croniter.CroniterBadCronError: Exactly 5, 6 or 7 columns has to be specified for iterator expression.

During handling of the above exception, another exception occurred:

Traceback (most recent call last):
  File "/home/airflow/.local/lib/python3.12/site-packages/airflow/models/dagbag.py", line 479, in _process_modules
    dag.validate()
  File "/home/airflow/.local/lib/python3.12/site-packages/airflow/models/dag.py", line 845, in validate
    self.timetable.validate()
  File "/home/airflow/.local/lib/python3.12/site-packages/airflow/timetables/_cron.py", line 104, in validate
    raise AirflowTimetableInvalid(str(e))
airflow.exceptions.AirflowTimetableInvalid: Exactly 5, 6 or 7 columns has to be specified for iterator expression.
[2025-05-30T15:13:02.992+0000] {processor.py:927} WARNING - No viable dags retrieved from /opt/airflow/dags/data_quality.py
[2025-05-30T15:13:03.043+0000] {processor.py:208} INFO - Processing /opt/airflow/dags/data_quality.py took 1.304 seconds
[2025-05-30T15:13:36.239+0000] {processor.py:186} INFO - Started process (PID=916) to work on /opt/airflow/dags/data_quality.py
[2025-05-30T15:13:36.245+0000] {processor.py:914} INFO - Processing file /opt/airflow/dags/data_quality.py for tasks to queue
[2025-05-30T15:13:36.270+0000] {logging_mixin.py:190} INFO - [2025-05-30T15:13:36.269+0000] {dagbag.py:588} INFO - Filling up the DagBag from /opt/airflow/dags/data_quality.py
[2025-05-30T15:13:38.757+0000] {logging_mixin.py:190} INFO - [2025-05-30T15:13:38.736+0000] {dagbag.py:484} ERROR - Failed to bag_dag: /opt/airflow/dags/data_quality.py
Traceback (most recent call last):
  File "/home/airflow/.local/lib/python3.12/site-packages/airflow/timetables/_cron.py", line 102, in validate
    croniter(self._expression)
  File "/home/airflow/.local/lib/python3.12/site-packages/croniter/croniter.py", line 271, in __init__
    self.expanded, self.nth_weekday_of_month = self.expand(
                                               ^^^^^^^^^^^^
  File "/home/airflow/.local/lib/python3.12/site-packages/croniter/croniter.py", line 1032, in expand
    return cls._expand(expr_format, hash_id=hash_id,
           ^^^^^^^^^^^^^^^^^^^^^^^^^^^^^^^^^^^^^^^^^
  File "/home/airflow/.local/lib/python3.12/site-packages/croniter/croniter.py", line 834, in _expand
    raise CroniterBadCronError(cls.bad_length)
croniter.croniter.CroniterBadCronError: Exactly 5, 6 or 7 columns has to be specified for iterator expression.

During handling of the above exception, another exception occurred:

Traceback (most recent call last):
  File "/home/airflow/.local/lib/python3.12/site-packages/airflow/models/dagbag.py", line 479, in _process_modules
    dag.validate()
  File "/home/airflow/.local/lib/python3.12/site-packages/airflow/models/dag.py", line 845, in validate
    self.timetable.validate()
  File "/home/airflow/.local/lib/python3.12/site-packages/airflow/timetables/_cron.py", line 104, in validate
    raise AirflowTimetableInvalid(str(e))
airflow.exceptions.AirflowTimetableInvalid: Exactly 5, 6 or 7 columns has to be specified for iterator expression.
[2025-05-30T15:13:38.768+0000] {processor.py:927} WARNING - No viable dags retrieved from /opt/airflow/dags/data_quality.py
[2025-05-30T15:13:38.936+0000] {processor.py:208} INFO - Processing /opt/airflow/dags/data_quality.py took 2.751 seconds
[2025-05-30T15:14:16.077+0000] {processor.py:186} INFO - Started process (PID=930) to work on /opt/airflow/dags/data_quality.py
[2025-05-30T15:14:16.091+0000] {processor.py:914} INFO - Processing file /opt/airflow/dags/data_quality.py for tasks to queue
[2025-05-30T15:14:16.114+0000] {logging_mixin.py:190} INFO - [2025-05-30T15:14:16.113+0000] {dagbag.py:588} INFO - Filling up the DagBag from /opt/airflow/dags/data_quality.py
[2025-05-30T15:14:19.892+0000] {logging_mixin.py:190} INFO - [2025-05-30T15:14:19.862+0000] {dagbag.py:484} ERROR - Failed to bag_dag: /opt/airflow/dags/data_quality.py
Traceback (most recent call last):
  File "/home/airflow/.local/lib/python3.12/site-packages/airflow/timetables/_cron.py", line 102, in validate
    croniter(self._expression)
  File "/home/airflow/.local/lib/python3.12/site-packages/croniter/croniter.py", line 271, in __init__
    self.expanded, self.nth_weekday_of_month = self.expand(
                                               ^^^^^^^^^^^^
  File "/home/airflow/.local/lib/python3.12/site-packages/croniter/croniter.py", line 1032, in expand
    return cls._expand(expr_format, hash_id=hash_id,
           ^^^^^^^^^^^^^^^^^^^^^^^^^^^^^^^^^^^^^^^^^
  File "/home/airflow/.local/lib/python3.12/site-packages/croniter/croniter.py", line 834, in _expand
    raise CroniterBadCronError(cls.bad_length)
croniter.croniter.CroniterBadCronError: Exactly 5, 6 or 7 columns has to be specified for iterator expression.

During handling of the above exception, another exception occurred:

Traceback (most recent call last):
  File "/home/airflow/.local/lib/python3.12/site-packages/airflow/models/dagbag.py", line 479, in _process_modules
    dag.validate()
  File "/home/airflow/.local/lib/python3.12/site-packages/airflow/models/dag.py", line 845, in validate
    self.timetable.validate()
  File "/home/airflow/.local/lib/python3.12/site-packages/airflow/timetables/_cron.py", line 104, in validate
    raise AirflowTimetableInvalid(str(e))
airflow.exceptions.AirflowTimetableInvalid: Exactly 5, 6 or 7 columns has to be specified for iterator expression.
[2025-05-30T15:14:19.898+0000] {processor.py:927} WARNING - No viable dags retrieved from /opt/airflow/dags/data_quality.py
[2025-05-30T15:14:20.082+0000] {processor.py:208} INFO - Processing /opt/airflow/dags/data_quality.py took 4.058 seconds
[2025-05-30T15:14:51.148+0000] {processor.py:186} INFO - Started process (PID=943) to work on /opt/airflow/dags/data_quality.py
[2025-05-30T15:14:51.160+0000] {processor.py:914} INFO - Processing file /opt/airflow/dags/data_quality.py for tasks to queue
[2025-05-30T15:14:51.179+0000] {logging_mixin.py:190} INFO - [2025-05-30T15:14:51.178+0000] {dagbag.py:588} INFO - Filling up the DagBag from /opt/airflow/dags/data_quality.py
[2025-05-30T15:14:53.870+0000] {logging_mixin.py:190} INFO - [2025-05-30T15:14:53.852+0000] {dagbag.py:484} ERROR - Failed to bag_dag: /opt/airflow/dags/data_quality.py
Traceback (most recent call last):
  File "/home/airflow/.local/lib/python3.12/site-packages/airflow/timetables/_cron.py", line 102, in validate
    croniter(self._expression)
  File "/home/airflow/.local/lib/python3.12/site-packages/croniter/croniter.py", line 271, in __init__
    self.expanded, self.nth_weekday_of_month = self.expand(
                                               ^^^^^^^^^^^^
  File "/home/airflow/.local/lib/python3.12/site-packages/croniter/croniter.py", line 1032, in expand
    return cls._expand(expr_format, hash_id=hash_id,
           ^^^^^^^^^^^^^^^^^^^^^^^^^^^^^^^^^^^^^^^^^
  File "/home/airflow/.local/lib/python3.12/site-packages/croniter/croniter.py", line 834, in _expand
    raise CroniterBadCronError(cls.bad_length)
croniter.croniter.CroniterBadCronError: Exactly 5, 6 or 7 columns has to be specified for iterator expression.

During handling of the above exception, another exception occurred:

Traceback (most recent call last):
  File "/home/airflow/.local/lib/python3.12/site-packages/airflow/models/dagbag.py", line 479, in _process_modules
    dag.validate()
  File "/home/airflow/.local/lib/python3.12/site-packages/airflow/models/dag.py", line 845, in validate
    self.timetable.validate()
  File "/home/airflow/.local/lib/python3.12/site-packages/airflow/timetables/_cron.py", line 104, in validate
    raise AirflowTimetableInvalid(str(e))
airflow.exceptions.AirflowTimetableInvalid: Exactly 5, 6 or 7 columns has to be specified for iterator expression.
[2025-05-30T15:14:53.874+0000] {processor.py:927} WARNING - No viable dags retrieved from /opt/airflow/dags/data_quality.py
[2025-05-30T15:14:54.001+0000] {processor.py:208} INFO - Processing /opt/airflow/dags/data_quality.py took 2.904 seconds
[2025-05-30T15:15:31.932+0000] {processor.py:186} INFO - Started process (PID=957) to work on /opt/airflow/dags/data_quality.py
[2025-05-30T15:15:31.964+0000] {processor.py:914} INFO - Processing file /opt/airflow/dags/data_quality.py for tasks to queue
[2025-05-30T15:15:31.999+0000] {logging_mixin.py:190} INFO - [2025-05-30T15:15:31.998+0000] {dagbag.py:588} INFO - Filling up the DagBag from /opt/airflow/dags/data_quality.py
[2025-05-30T15:15:37.857+0000] {logging_mixin.py:190} INFO - [2025-05-30T15:15:37.829+0000] {dagbag.py:484} ERROR - Failed to bag_dag: /opt/airflow/dags/data_quality.py
Traceback (most recent call last):
  File "/home/airflow/.local/lib/python3.12/site-packages/airflow/timetables/_cron.py", line 102, in validate
    croniter(self._expression)
  File "/home/airflow/.local/lib/python3.12/site-packages/croniter/croniter.py", line 271, in __init__
    self.expanded, self.nth_weekday_of_month = self.expand(
                                               ^^^^^^^^^^^^
  File "/home/airflow/.local/lib/python3.12/site-packages/croniter/croniter.py", line 1032, in expand
    return cls._expand(expr_format, hash_id=hash_id,
           ^^^^^^^^^^^^^^^^^^^^^^^^^^^^^^^^^^^^^^^^^
  File "/home/airflow/.local/lib/python3.12/site-packages/croniter/croniter.py", line 834, in _expand
    raise CroniterBadCronError(cls.bad_length)
croniter.croniter.CroniterBadCronError: Exactly 5, 6 or 7 columns has to be specified for iterator expression.

During handling of the above exception, another exception occurred:

Traceback (most recent call last):
  File "/home/airflow/.local/lib/python3.12/site-packages/airflow/models/dagbag.py", line 479, in _process_modules
    dag.validate()
  File "/home/airflow/.local/lib/python3.12/site-packages/airflow/models/dag.py", line 845, in validate
    self.timetable.validate()
  File "/home/airflow/.local/lib/python3.12/site-packages/airflow/timetables/_cron.py", line 104, in validate
    raise AirflowTimetableInvalid(str(e))
airflow.exceptions.AirflowTimetableInvalid: Exactly 5, 6 or 7 columns has to be specified for iterator expression.
[2025-05-30T15:15:37.888+0000] {processor.py:927} WARNING - No viable dags retrieved from /opt/airflow/dags/data_quality.py
[2025-05-30T15:15:38.071+0000] {processor.py:208} INFO - Processing /opt/airflow/dags/data_quality.py took 6.196 seconds
[2025-05-30T15:16:10.040+0000] {processor.py:186} INFO - Started process (PID=975) to work on /opt/airflow/dags/data_quality.py
[2025-05-30T15:16:10.051+0000] {processor.py:914} INFO - Processing file /opt/airflow/dags/data_quality.py for tasks to queue
[2025-05-30T15:16:10.074+0000] {logging_mixin.py:190} INFO - [2025-05-30T15:16:10.073+0000] {dagbag.py:588} INFO - Filling up the DagBag from /opt/airflow/dags/data_quality.py
[2025-05-30T15:16:13.029+0000] {logging_mixin.py:190} INFO - [2025-05-30T15:16:13.001+0000] {dagbag.py:484} ERROR - Failed to bag_dag: /opt/airflow/dags/data_quality.py
Traceback (most recent call last):
  File "/home/airflow/.local/lib/python3.12/site-packages/airflow/timetables/_cron.py", line 102, in validate
    croniter(self._expression)
  File "/home/airflow/.local/lib/python3.12/site-packages/croniter/croniter.py", line 271, in __init__
    self.expanded, self.nth_weekday_of_month = self.expand(
                                               ^^^^^^^^^^^^
  File "/home/airflow/.local/lib/python3.12/site-packages/croniter/croniter.py", line 1032, in expand
    return cls._expand(expr_format, hash_id=hash_id,
           ^^^^^^^^^^^^^^^^^^^^^^^^^^^^^^^^^^^^^^^^^
  File "/home/airflow/.local/lib/python3.12/site-packages/croniter/croniter.py", line 834, in _expand
    raise CroniterBadCronError(cls.bad_length)
croniter.croniter.CroniterBadCronError: Exactly 5, 6 or 7 columns has to be specified for iterator expression.

During handling of the above exception, another exception occurred:

Traceback (most recent call last):
  File "/home/airflow/.local/lib/python3.12/site-packages/airflow/models/dagbag.py", line 479, in _process_modules
    dag.validate()
  File "/home/airflow/.local/lib/python3.12/site-packages/airflow/models/dag.py", line 845, in validate
    self.timetable.validate()
  File "/home/airflow/.local/lib/python3.12/site-packages/airflow/timetables/_cron.py", line 104, in validate
    raise AirflowTimetableInvalid(str(e))
airflow.exceptions.AirflowTimetableInvalid: Exactly 5, 6 or 7 columns has to be specified for iterator expression.
[2025-05-30T15:16:13.032+0000] {processor.py:927} WARNING - No viable dags retrieved from /opt/airflow/dags/data_quality.py
[2025-05-30T15:16:13.165+0000] {processor.py:208} INFO - Processing /opt/airflow/dags/data_quality.py took 3.179 seconds
[2025-05-30T15:16:48.093+0000] {processor.py:186} INFO - Started process (PID=987) to work on /opt/airflow/dags/data_quality.py
[2025-05-30T15:16:48.110+0000] {processor.py:914} INFO - Processing file /opt/airflow/dags/data_quality.py for tasks to queue
[2025-05-30T15:16:48.130+0000] {logging_mixin.py:190} INFO - [2025-05-30T15:16:48.129+0000] {dagbag.py:588} INFO - Filling up the DagBag from /opt/airflow/dags/data_quality.py
[2025-05-30T15:16:51.859+0000] {logging_mixin.py:190} INFO - [2025-05-30T15:16:51.842+0000] {dagbag.py:484} ERROR - Failed to bag_dag: /opt/airflow/dags/data_quality.py
Traceback (most recent call last):
  File "/home/airflow/.local/lib/python3.12/site-packages/airflow/timetables/_cron.py", line 102, in validate
    croniter(self._expression)
  File "/home/airflow/.local/lib/python3.12/site-packages/croniter/croniter.py", line 271, in __init__
    self.expanded, self.nth_weekday_of_month = self.expand(
                                               ^^^^^^^^^^^^
  File "/home/airflow/.local/lib/python3.12/site-packages/croniter/croniter.py", line 1032, in expand
    return cls._expand(expr_format, hash_id=hash_id,
           ^^^^^^^^^^^^^^^^^^^^^^^^^^^^^^^^^^^^^^^^^
  File "/home/airflow/.local/lib/python3.12/site-packages/croniter/croniter.py", line 834, in _expand
    raise CroniterBadCronError(cls.bad_length)
croniter.croniter.CroniterBadCronError: Exactly 5, 6 or 7 columns has to be specified for iterator expression.

During handling of the above exception, another exception occurred:

Traceback (most recent call last):
  File "/home/airflow/.local/lib/python3.12/site-packages/airflow/models/dagbag.py", line 479, in _process_modules
    dag.validate()
  File "/home/airflow/.local/lib/python3.12/site-packages/airflow/models/dag.py", line 845, in validate
    self.timetable.validate()
  File "/home/airflow/.local/lib/python3.12/site-packages/airflow/timetables/_cron.py", line 104, in validate
    raise AirflowTimetableInvalid(str(e))
airflow.exceptions.AirflowTimetableInvalid: Exactly 5, 6 or 7 columns has to be specified for iterator expression.
[2025-05-30T15:16:51.870+0000] {processor.py:927} WARNING - No viable dags retrieved from /opt/airflow/dags/data_quality.py
[2025-05-30T15:16:51.986+0000] {processor.py:208} INFO - Processing /opt/airflow/dags/data_quality.py took 3.934 seconds
[2025-05-30T15:17:29.580+0000] {processor.py:186} INFO - Started process (PID=1001) to work on /opt/airflow/dags/data_quality.py
[2025-05-30T15:17:29.603+0000] {processor.py:914} INFO - Processing file /opt/airflow/dags/data_quality.py for tasks to queue
[2025-05-30T15:17:29.624+0000] {logging_mixin.py:190} INFO - [2025-05-30T15:17:29.620+0000] {dagbag.py:588} INFO - Filling up the DagBag from /opt/airflow/dags/data_quality.py
[2025-05-30T15:17:33.697+0000] {logging_mixin.py:190} INFO - [2025-05-30T15:17:33.679+0000] {dagbag.py:484} ERROR - Failed to bag_dag: /opt/airflow/dags/data_quality.py
Traceback (most recent call last):
  File "/home/airflow/.local/lib/python3.12/site-packages/airflow/timetables/_cron.py", line 102, in validate
    croniter(self._expression)
  File "/home/airflow/.local/lib/python3.12/site-packages/croniter/croniter.py", line 271, in __init__
    self.expanded, self.nth_weekday_of_month = self.expand(
                                               ^^^^^^^^^^^^
  File "/home/airflow/.local/lib/python3.12/site-packages/croniter/croniter.py", line 1032, in expand
    return cls._expand(expr_format, hash_id=hash_id,
           ^^^^^^^^^^^^^^^^^^^^^^^^^^^^^^^^^^^^^^^^^
  File "/home/airflow/.local/lib/python3.12/site-packages/croniter/croniter.py", line 834, in _expand
    raise CroniterBadCronError(cls.bad_length)
croniter.croniter.CroniterBadCronError: Exactly 5, 6 or 7 columns has to be specified for iterator expression.

During handling of the above exception, another exception occurred:

Traceback (most recent call last):
  File "/home/airflow/.local/lib/python3.12/site-packages/airflow/models/dagbag.py", line 479, in _process_modules
    dag.validate()
  File "/home/airflow/.local/lib/python3.12/site-packages/airflow/models/dag.py", line 845, in validate
    self.timetable.validate()
  File "/home/airflow/.local/lib/python3.12/site-packages/airflow/timetables/_cron.py", line 104, in validate
    raise AirflowTimetableInvalid(str(e))
airflow.exceptions.AirflowTimetableInvalid: Exactly 5, 6 or 7 columns has to be specified for iterator expression.
[2025-05-30T15:17:33.722+0000] {processor.py:927} WARNING - No viable dags retrieved from /opt/airflow/dags/data_quality.py
[2025-05-30T15:17:34.061+0000] {processor.py:208} INFO - Processing /opt/airflow/dags/data_quality.py took 4.533 seconds
[2025-05-30T15:18:12.526+0000] {processor.py:186} INFO - Started process (PID=1020) to work on /opt/airflow/dags/data_quality.py
[2025-05-30T15:18:12.548+0000] {processor.py:914} INFO - Processing file /opt/airflow/dags/data_quality.py for tasks to queue
[2025-05-30T15:18:12.580+0000] {logging_mixin.py:190} INFO - [2025-05-30T15:18:12.579+0000] {dagbag.py:588} INFO - Filling up the DagBag from /opt/airflow/dags/data_quality.py
[2025-05-30T15:18:16.477+0000] {logging_mixin.py:190} INFO - [2025-05-30T15:18:16.463+0000] {dagbag.py:484} ERROR - Failed to bag_dag: /opt/airflow/dags/data_quality.py
Traceback (most recent call last):
  File "/home/airflow/.local/lib/python3.12/site-packages/airflow/timetables/_cron.py", line 102, in validate
    croniter(self._expression)
  File "/home/airflow/.local/lib/python3.12/site-packages/croniter/croniter.py", line 271, in __init__
    self.expanded, self.nth_weekday_of_month = self.expand(
                                               ^^^^^^^^^^^^
  File "/home/airflow/.local/lib/python3.12/site-packages/croniter/croniter.py", line 1032, in expand
    return cls._expand(expr_format, hash_id=hash_id,
           ^^^^^^^^^^^^^^^^^^^^^^^^^^^^^^^^^^^^^^^^^
  File "/home/airflow/.local/lib/python3.12/site-packages/croniter/croniter.py", line 834, in _expand
    raise CroniterBadCronError(cls.bad_length)
croniter.croniter.CroniterBadCronError: Exactly 5, 6 or 7 columns has to be specified for iterator expression.

During handling of the above exception, another exception occurred:

Traceback (most recent call last):
  File "/home/airflow/.local/lib/python3.12/site-packages/airflow/models/dagbag.py", line 479, in _process_modules
    dag.validate()
  File "/home/airflow/.local/lib/python3.12/site-packages/airflow/models/dag.py", line 845, in validate
    self.timetable.validate()
  File "/home/airflow/.local/lib/python3.12/site-packages/airflow/timetables/_cron.py", line 104, in validate
    raise AirflowTimetableInvalid(str(e))
airflow.exceptions.AirflowTimetableInvalid: Exactly 5, 6 or 7 columns has to be specified for iterator expression.
[2025-05-30T15:18:16.560+0000] {processor.py:927} WARNING - No viable dags retrieved from /opt/airflow/dags/data_quality.py
[2025-05-30T15:18:16.751+0000] {processor.py:208} INFO - Processing /opt/airflow/dags/data_quality.py took 4.275 seconds
[2025-05-30T15:18:53.696+0000] {processor.py:186} INFO - Started process (PID=1033) to work on /opt/airflow/dags/data_quality.py
[2025-05-30T15:18:53.727+0000] {processor.py:914} INFO - Processing file /opt/airflow/dags/data_quality.py for tasks to queue
[2025-05-30T15:18:53.748+0000] {logging_mixin.py:190} INFO - [2025-05-30T15:18:53.747+0000] {dagbag.py:588} INFO - Filling up the DagBag from /opt/airflow/dags/data_quality.py
[2025-05-30T15:18:58.194+0000] {logging_mixin.py:190} INFO - [2025-05-30T15:18:58.177+0000] {dagbag.py:484} ERROR - Failed to bag_dag: /opt/airflow/dags/data_quality.py
Traceback (most recent call last):
  File "/home/airflow/.local/lib/python3.12/site-packages/airflow/timetables/_cron.py", line 102, in validate
    croniter(self._expression)
  File "/home/airflow/.local/lib/python3.12/site-packages/croniter/croniter.py", line 271, in __init__
    self.expanded, self.nth_weekday_of_month = self.expand(
                                               ^^^^^^^^^^^^
  File "/home/airflow/.local/lib/python3.12/site-packages/croniter/croniter.py", line 1032, in expand
    return cls._expand(expr_format, hash_id=hash_id,
           ^^^^^^^^^^^^^^^^^^^^^^^^^^^^^^^^^^^^^^^^^
  File "/home/airflow/.local/lib/python3.12/site-packages/croniter/croniter.py", line 834, in _expand
    raise CroniterBadCronError(cls.bad_length)
croniter.croniter.CroniterBadCronError: Exactly 5, 6 or 7 columns has to be specified for iterator expression.

During handling of the above exception, another exception occurred:

Traceback (most recent call last):
  File "/home/airflow/.local/lib/python3.12/site-packages/airflow/models/dagbag.py", line 479, in _process_modules
    dag.validate()
  File "/home/airflow/.local/lib/python3.12/site-packages/airflow/models/dag.py", line 845, in validate
    self.timetable.validate()
  File "/home/airflow/.local/lib/python3.12/site-packages/airflow/timetables/_cron.py", line 104, in validate
    raise AirflowTimetableInvalid(str(e))
airflow.exceptions.AirflowTimetableInvalid: Exactly 5, 6 or 7 columns has to be specified for iterator expression.
[2025-05-30T15:18:58.196+0000] {processor.py:927} WARNING - No viable dags retrieved from /opt/airflow/dags/data_quality.py
[2025-05-30T15:18:58.366+0000] {processor.py:208} INFO - Processing /opt/airflow/dags/data_quality.py took 4.724 seconds
[2025-05-30T15:19:32.733+0000] {processor.py:186} INFO - Started process (PID=1046) to work on /opt/airflow/dags/data_quality.py
[2025-05-30T15:19:32.762+0000] {processor.py:914} INFO - Processing file /opt/airflow/dags/data_quality.py for tasks to queue
[2025-05-30T15:19:32.945+0000] {logging_mixin.py:190} INFO - [2025-05-30T15:19:32.915+0000] {dagbag.py:588} INFO - Filling up the DagBag from /opt/airflow/dags/data_quality.py
[2025-05-30T15:19:37.896+0000] {logging_mixin.py:190} INFO - [2025-05-30T15:19:37.865+0000] {dagbag.py:484} ERROR - Failed to bag_dag: /opt/airflow/dags/data_quality.py
Traceback (most recent call last):
  File "/home/airflow/.local/lib/python3.12/site-packages/airflow/timetables/_cron.py", line 102, in validate
    croniter(self._expression)
  File "/home/airflow/.local/lib/python3.12/site-packages/croniter/croniter.py", line 271, in __init__
    self.expanded, self.nth_weekday_of_month = self.expand(
                                               ^^^^^^^^^^^^
  File "/home/airflow/.local/lib/python3.12/site-packages/croniter/croniter.py", line 1032, in expand
    return cls._expand(expr_format, hash_id=hash_id,
           ^^^^^^^^^^^^^^^^^^^^^^^^^^^^^^^^^^^^^^^^^
  File "/home/airflow/.local/lib/python3.12/site-packages/croniter/croniter.py", line 834, in _expand
    raise CroniterBadCronError(cls.bad_length)
croniter.croniter.CroniterBadCronError: Exactly 5, 6 or 7 columns has to be specified for iterator expression.

During handling of the above exception, another exception occurred:

Traceback (most recent call last):
  File "/home/airflow/.local/lib/python3.12/site-packages/airflow/models/dagbag.py", line 479, in _process_modules
    dag.validate()
  File "/home/airflow/.local/lib/python3.12/site-packages/airflow/models/dag.py", line 845, in validate
    self.timetable.validate()
  File "/home/airflow/.local/lib/python3.12/site-packages/airflow/timetables/_cron.py", line 104, in validate
    raise AirflowTimetableInvalid(str(e))
airflow.exceptions.AirflowTimetableInvalid: Exactly 5, 6 or 7 columns has to be specified for iterator expression.
[2025-05-30T15:19:37.923+0000] {processor.py:927} WARNING - No viable dags retrieved from /opt/airflow/dags/data_quality.py
[2025-05-30T15:19:38.092+0000] {processor.py:208} INFO - Processing /opt/airflow/dags/data_quality.py took 5.486 seconds
[2025-05-30T15:20:15.677+0000] {processor.py:186} INFO - Started process (PID=1065) to work on /opt/airflow/dags/data_quality.py
[2025-05-30T15:20:15.717+0000] {processor.py:914} INFO - Processing file /opt/airflow/dags/data_quality.py for tasks to queue
[2025-05-30T15:20:15.820+0000] {logging_mixin.py:190} INFO - [2025-05-30T15:20:15.818+0000] {dagbag.py:588} INFO - Filling up the DagBag from /opt/airflow/dags/data_quality.py
[2025-05-30T15:20:19.537+0000] {logging_mixin.py:190} INFO - [2025-05-30T15:20:19.507+0000] {dagbag.py:484} ERROR - Failed to bag_dag: /opt/airflow/dags/data_quality.py
Traceback (most recent call last):
  File "/home/airflow/.local/lib/python3.12/site-packages/airflow/timetables/_cron.py", line 102, in validate
    croniter(self._expression)
  File "/home/airflow/.local/lib/python3.12/site-packages/croniter/croniter.py", line 271, in __init__
    self.expanded, self.nth_weekday_of_month = self.expand(
                                               ^^^^^^^^^^^^
  File "/home/airflow/.local/lib/python3.12/site-packages/croniter/croniter.py", line 1032, in expand
    return cls._expand(expr_format, hash_id=hash_id,
           ^^^^^^^^^^^^^^^^^^^^^^^^^^^^^^^^^^^^^^^^^
  File "/home/airflow/.local/lib/python3.12/site-packages/croniter/croniter.py", line 834, in _expand
    raise CroniterBadCronError(cls.bad_length)
croniter.croniter.CroniterBadCronError: Exactly 5, 6 or 7 columns has to be specified for iterator expression.

During handling of the above exception, another exception occurred:

Traceback (most recent call last):
  File "/home/airflow/.local/lib/python3.12/site-packages/airflow/models/dagbag.py", line 479, in _process_modules
    dag.validate()
  File "/home/airflow/.local/lib/python3.12/site-packages/airflow/models/dag.py", line 845, in validate
    self.timetable.validate()
  File "/home/airflow/.local/lib/python3.12/site-packages/airflow/timetables/_cron.py", line 104, in validate
    raise AirflowTimetableInvalid(str(e))
airflow.exceptions.AirflowTimetableInvalid: Exactly 5, 6 or 7 columns has to be specified for iterator expression.
[2025-05-30T15:20:19.578+0000] {processor.py:927} WARNING - No viable dags retrieved from /opt/airflow/dags/data_quality.py
[2025-05-30T15:20:19.796+0000] {processor.py:208} INFO - Processing /opt/airflow/dags/data_quality.py took 4.184 seconds
[2025-05-30T15:20:56.561+0000] {processor.py:186} INFO - Started process (PID=1078) to work on /opt/airflow/dags/data_quality.py
[2025-05-30T15:20:56.617+0000] {processor.py:914} INFO - Processing file /opt/airflow/dags/data_quality.py for tasks to queue
[2025-05-30T15:20:56.717+0000] {logging_mixin.py:190} INFO - [2025-05-30T15:20:56.716+0000] {dagbag.py:588} INFO - Filling up the DagBag from /opt/airflow/dags/data_quality.py
[2025-05-30T15:21:01.733+0000] {logging_mixin.py:190} INFO - [2025-05-30T15:21:01.701+0000] {dagbag.py:484} ERROR - Failed to bag_dag: /opt/airflow/dags/data_quality.py
Traceback (most recent call last):
  File "/home/airflow/.local/lib/python3.12/site-packages/airflow/timetables/_cron.py", line 102, in validate
    croniter(self._expression)
  File "/home/airflow/.local/lib/python3.12/site-packages/croniter/croniter.py", line 271, in __init__
    self.expanded, self.nth_weekday_of_month = self.expand(
                                               ^^^^^^^^^^^^
  File "/home/airflow/.local/lib/python3.12/site-packages/croniter/croniter.py", line 1032, in expand
    return cls._expand(expr_format, hash_id=hash_id,
           ^^^^^^^^^^^^^^^^^^^^^^^^^^^^^^^^^^^^^^^^^
  File "/home/airflow/.local/lib/python3.12/site-packages/croniter/croniter.py", line 834, in _expand
    raise CroniterBadCronError(cls.bad_length)
croniter.croniter.CroniterBadCronError: Exactly 5, 6 or 7 columns has to be specified for iterator expression.

During handling of the above exception, another exception occurred:

Traceback (most recent call last):
  File "/home/airflow/.local/lib/python3.12/site-packages/airflow/models/dagbag.py", line 479, in _process_modules
    dag.validate()
  File "/home/airflow/.local/lib/python3.12/site-packages/airflow/models/dag.py", line 845, in validate
    self.timetable.validate()
  File "/home/airflow/.local/lib/python3.12/site-packages/airflow/timetables/_cron.py", line 104, in validate
    raise AirflowTimetableInvalid(str(e))
airflow.exceptions.AirflowTimetableInvalid: Exactly 5, 6 or 7 columns has to be specified for iterator expression.
[2025-05-30T15:21:01.770+0000] {processor.py:927} WARNING - No viable dags retrieved from /opt/airflow/dags/data_quality.py
[2025-05-30T15:21:01.995+0000] {processor.py:208} INFO - Processing /opt/airflow/dags/data_quality.py took 5.485 seconds
[2025-05-30T15:21:37.095+0000] {processor.py:186} INFO - Started process (PID=1096) to work on /opt/airflow/dags/data_quality.py
[2025-05-30T15:21:37.134+0000] {processor.py:914} INFO - Processing file /opt/airflow/dags/data_quality.py for tasks to queue
[2025-05-30T15:21:37.160+0000] {logging_mixin.py:190} INFO - [2025-05-30T15:21:37.159+0000] {dagbag.py:588} INFO - Filling up the DagBag from /opt/airflow/dags/data_quality.py
[2025-05-30T15:21:41.661+0000] {logging_mixin.py:190} INFO - [2025-05-30T15:21:41.631+0000] {dagbag.py:484} ERROR - Failed to bag_dag: /opt/airflow/dags/data_quality.py
Traceback (most recent call last):
  File "/home/airflow/.local/lib/python3.12/site-packages/airflow/timetables/_cron.py", line 102, in validate
    croniter(self._expression)
  File "/home/airflow/.local/lib/python3.12/site-packages/croniter/croniter.py", line 271, in __init__
    self.expanded, self.nth_weekday_of_month = self.expand(
                                               ^^^^^^^^^^^^
  File "/home/airflow/.local/lib/python3.12/site-packages/croniter/croniter.py", line 1032, in expand
    return cls._expand(expr_format, hash_id=hash_id,
           ^^^^^^^^^^^^^^^^^^^^^^^^^^^^^^^^^^^^^^^^^
  File "/home/airflow/.local/lib/python3.12/site-packages/croniter/croniter.py", line 834, in _expand
    raise CroniterBadCronError(cls.bad_length)
croniter.croniter.CroniterBadCronError: Exactly 5, 6 or 7 columns has to be specified for iterator expression.

During handling of the above exception, another exception occurred:

Traceback (most recent call last):
  File "/home/airflow/.local/lib/python3.12/site-packages/airflow/models/dagbag.py", line 479, in _process_modules
    dag.validate()
  File "/home/airflow/.local/lib/python3.12/site-packages/airflow/models/dag.py", line 845, in validate
    self.timetable.validate()
  File "/home/airflow/.local/lib/python3.12/site-packages/airflow/timetables/_cron.py", line 104, in validate
    raise AirflowTimetableInvalid(str(e))
airflow.exceptions.AirflowTimetableInvalid: Exactly 5, 6 or 7 columns has to be specified for iterator expression.
[2025-05-30T15:21:41.696+0000] {processor.py:927} WARNING - No viable dags retrieved from /opt/airflow/dags/data_quality.py
[2025-05-30T15:21:41.855+0000] {processor.py:208} INFO - Processing /opt/airflow/dags/data_quality.py took 4.810 seconds
[2025-05-30T15:22:21.696+0000] {processor.py:186} INFO - Started process (PID=1109) to work on /opt/airflow/dags/data_quality.py
[2025-05-30T15:22:21.769+0000] {processor.py:914} INFO - Processing file /opt/airflow/dags/data_quality.py for tasks to queue
[2025-05-30T15:22:21.810+0000] {logging_mixin.py:190} INFO - [2025-05-30T15:22:21.808+0000] {dagbag.py:588} INFO - Filling up the DagBag from /opt/airflow/dags/data_quality.py
[2025-05-30T15:22:26.146+0000] {logging_mixin.py:190} INFO - [2025-05-30T15:22:26.127+0000] {dagbag.py:484} ERROR - Failed to bag_dag: /opt/airflow/dags/data_quality.py
Traceback (most recent call last):
  File "/home/airflow/.local/lib/python3.12/site-packages/airflow/timetables/_cron.py", line 102, in validate
    croniter(self._expression)
  File "/home/airflow/.local/lib/python3.12/site-packages/croniter/croniter.py", line 271, in __init__
    self.expanded, self.nth_weekday_of_month = self.expand(
                                               ^^^^^^^^^^^^
  File "/home/airflow/.local/lib/python3.12/site-packages/croniter/croniter.py", line 1032, in expand
    return cls._expand(expr_format, hash_id=hash_id,
           ^^^^^^^^^^^^^^^^^^^^^^^^^^^^^^^^^^^^^^^^^
  File "/home/airflow/.local/lib/python3.12/site-packages/croniter/croniter.py", line 834, in _expand
    raise CroniterBadCronError(cls.bad_length)
croniter.croniter.CroniterBadCronError: Exactly 5, 6 or 7 columns has to be specified for iterator expression.

During handling of the above exception, another exception occurred:

Traceback (most recent call last):
  File "/home/airflow/.local/lib/python3.12/site-packages/airflow/models/dagbag.py", line 479, in _process_modules
    dag.validate()
  File "/home/airflow/.local/lib/python3.12/site-packages/airflow/models/dag.py", line 845, in validate
    self.timetable.validate()
  File "/home/airflow/.local/lib/python3.12/site-packages/airflow/timetables/_cron.py", line 104, in validate
    raise AirflowTimetableInvalid(str(e))
airflow.exceptions.AirflowTimetableInvalid: Exactly 5, 6 or 7 columns has to be specified for iterator expression.
[2025-05-30T15:22:26.165+0000] {processor.py:927} WARNING - No viable dags retrieved from /opt/airflow/dags/data_quality.py
[2025-05-30T15:22:26.329+0000] {processor.py:208} INFO - Processing /opt/airflow/dags/data_quality.py took 4.696 seconds
[2025-05-30T15:22:57.875+0000] {processor.py:186} INFO - Started process (PID=1123) to work on /opt/airflow/dags/data_quality.py
[2025-05-30T15:22:57.889+0000] {processor.py:914} INFO - Processing file /opt/airflow/dags/data_quality.py for tasks to queue
[2025-05-30T15:22:57.907+0000] {logging_mixin.py:190} INFO - [2025-05-30T15:22:57.906+0000] {dagbag.py:588} INFO - Filling up the DagBag from /opt/airflow/dags/data_quality.py
[2025-05-30T15:23:01.620+0000] {logging_mixin.py:190} INFO - [2025-05-30T15:23:01.601+0000] {dagbag.py:484} ERROR - Failed to bag_dag: /opt/airflow/dags/data_quality.py
Traceback (most recent call last):
  File "/home/airflow/.local/lib/python3.12/site-packages/airflow/timetables/_cron.py", line 102, in validate
    croniter(self._expression)
  File "/home/airflow/.local/lib/python3.12/site-packages/croniter/croniter.py", line 271, in __init__
    self.expanded, self.nth_weekday_of_month = self.expand(
                                               ^^^^^^^^^^^^
  File "/home/airflow/.local/lib/python3.12/site-packages/croniter/croniter.py", line 1032, in expand
    return cls._expand(expr_format, hash_id=hash_id,
           ^^^^^^^^^^^^^^^^^^^^^^^^^^^^^^^^^^^^^^^^^
  File "/home/airflow/.local/lib/python3.12/site-packages/croniter/croniter.py", line 834, in _expand
    raise CroniterBadCronError(cls.bad_length)
croniter.croniter.CroniterBadCronError: Exactly 5, 6 or 7 columns has to be specified for iterator expression.

During handling of the above exception, another exception occurred:

Traceback (most recent call last):
  File "/home/airflow/.local/lib/python3.12/site-packages/airflow/models/dagbag.py", line 479, in _process_modules
    dag.validate()
  File "/home/airflow/.local/lib/python3.12/site-packages/airflow/models/dag.py", line 845, in validate
    self.timetable.validate()
  File "/home/airflow/.local/lib/python3.12/site-packages/airflow/timetables/_cron.py", line 104, in validate
    raise AirflowTimetableInvalid(str(e))
airflow.exceptions.AirflowTimetableInvalid: Exactly 5, 6 or 7 columns has to be specified for iterator expression.
[2025-05-30T15:23:01.631+0000] {processor.py:927} WARNING - No viable dags retrieved from /opt/airflow/dags/data_quality.py
[2025-05-30T15:23:01.829+0000] {processor.py:208} INFO - Processing /opt/airflow/dags/data_quality.py took 4.035 seconds
[2025-05-30T15:23:39.662+0000] {processor.py:186} INFO - Started process (PID=1144) to work on /opt/airflow/dags/data_quality.py
[2025-05-30T15:23:39.718+0000] {processor.py:914} INFO - Processing file /opt/airflow/dags/data_quality.py for tasks to queue
[2025-05-30T15:23:39.802+0000] {logging_mixin.py:190} INFO - [2025-05-30T15:23:39.801+0000] {dagbag.py:588} INFO - Filling up the DagBag from /opt/airflow/dags/data_quality.py
[2025-05-30T15:23:47.033+0000] {logging_mixin.py:190} INFO - [2025-05-30T15:23:46.997+0000] {dagbag.py:484} ERROR - Failed to bag_dag: /opt/airflow/dags/data_quality.py
Traceback (most recent call last):
  File "/home/airflow/.local/lib/python3.12/site-packages/airflow/timetables/_cron.py", line 102, in validate
    croniter(self._expression)
  File "/home/airflow/.local/lib/python3.12/site-packages/croniter/croniter.py", line 271, in __init__
    self.expanded, self.nth_weekday_of_month = self.expand(
                                               ^^^^^^^^^^^^
  File "/home/airflow/.local/lib/python3.12/site-packages/croniter/croniter.py", line 1032, in expand
    return cls._expand(expr_format, hash_id=hash_id,
           ^^^^^^^^^^^^^^^^^^^^^^^^^^^^^^^^^^^^^^^^^
  File "/home/airflow/.local/lib/python3.12/site-packages/croniter/croniter.py", line 834, in _expand
    raise CroniterBadCronError(cls.bad_length)
croniter.croniter.CroniterBadCronError: Exactly 5, 6 or 7 columns has to be specified for iterator expression.

During handling of the above exception, another exception occurred:

Traceback (most recent call last):
  File "/home/airflow/.local/lib/python3.12/site-packages/airflow/models/dagbag.py", line 479, in _process_modules
    dag.validate()
  File "/home/airflow/.local/lib/python3.12/site-packages/airflow/models/dag.py", line 845, in validate
    self.timetable.validate()
  File "/home/airflow/.local/lib/python3.12/site-packages/airflow/timetables/_cron.py", line 104, in validate
    raise AirflowTimetableInvalid(str(e))
airflow.exceptions.AirflowTimetableInvalid: Exactly 5, 6 or 7 columns has to be specified for iterator expression.
[2025-05-30T15:23:47.103+0000] {processor.py:927} WARNING - No viable dags retrieved from /opt/airflow/dags/data_quality.py
[2025-05-30T15:23:47.306+0000] {processor.py:208} INFO - Processing /opt/airflow/dags/data_quality.py took 7.708 seconds
[2025-05-30T15:24:19.288+0000] {processor.py:186} INFO - Started process (PID=1157) to work on /opt/airflow/dags/data_quality.py
[2025-05-30T15:24:19.303+0000] {processor.py:914} INFO - Processing file /opt/airflow/dags/data_quality.py for tasks to queue
[2025-05-30T15:24:19.353+0000] {logging_mixin.py:190} INFO - [2025-05-30T15:24:19.352+0000] {dagbag.py:588} INFO - Filling up the DagBag from /opt/airflow/dags/data_quality.py
[2025-05-30T15:24:22.996+0000] {logging_mixin.py:190} INFO - [2025-05-30T15:24:22.977+0000] {dagbag.py:484} ERROR - Failed to bag_dag: /opt/airflow/dags/data_quality.py
Traceback (most recent call last):
  File "/home/airflow/.local/lib/python3.12/site-packages/airflow/timetables/_cron.py", line 102, in validate
    croniter(self._expression)
  File "/home/airflow/.local/lib/python3.12/site-packages/croniter/croniter.py", line 271, in __init__
    self.expanded, self.nth_weekday_of_month = self.expand(
                                               ^^^^^^^^^^^^
  File "/home/airflow/.local/lib/python3.12/site-packages/croniter/croniter.py", line 1032, in expand
    return cls._expand(expr_format, hash_id=hash_id,
           ^^^^^^^^^^^^^^^^^^^^^^^^^^^^^^^^^^^^^^^^^
  File "/home/airflow/.local/lib/python3.12/site-packages/croniter/croniter.py", line 834, in _expand
    raise CroniterBadCronError(cls.bad_length)
croniter.croniter.CroniterBadCronError: Exactly 5, 6 or 7 columns has to be specified for iterator expression.

During handling of the above exception, another exception occurred:

Traceback (most recent call last):
  File "/home/airflow/.local/lib/python3.12/site-packages/airflow/models/dagbag.py", line 479, in _process_modules
    dag.validate()
  File "/home/airflow/.local/lib/python3.12/site-packages/airflow/models/dag.py", line 845, in validate
    self.timetable.validate()
  File "/home/airflow/.local/lib/python3.12/site-packages/airflow/timetables/_cron.py", line 104, in validate
    raise AirflowTimetableInvalid(str(e))
airflow.exceptions.AirflowTimetableInvalid: Exactly 5, 6 or 7 columns has to be specified for iterator expression.
[2025-05-30T15:24:23.013+0000] {processor.py:927} WARNING - No viable dags retrieved from /opt/airflow/dags/data_quality.py
[2025-05-30T15:24:23.271+0000] {processor.py:208} INFO - Processing /opt/airflow/dags/data_quality.py took 4.034 seconds
[2025-05-30T15:25:01.632+0000] {processor.py:186} INFO - Started process (PID=1169) to work on /opt/airflow/dags/data_quality.py
[2025-05-30T15:25:01.637+0000] {processor.py:914} INFO - Processing file /opt/airflow/dags/data_quality.py for tasks to queue
[2025-05-30T15:25:01.647+0000] {logging_mixin.py:190} INFO - [2025-05-30T15:25:01.646+0000] {dagbag.py:588} INFO - Filling up the DagBag from /opt/airflow/dags/data_quality.py
[2025-05-30T15:25:05.954+0000] {logging_mixin.py:190} INFO - [2025-05-30T15:25:05.920+0000] {dagbag.py:484} ERROR - Failed to bag_dag: /opt/airflow/dags/data_quality.py
Traceback (most recent call last):
  File "/home/airflow/.local/lib/python3.12/site-packages/airflow/timetables/_cron.py", line 102, in validate
    croniter(self._expression)
  File "/home/airflow/.local/lib/python3.12/site-packages/croniter/croniter.py", line 271, in __init__
    self.expanded, self.nth_weekday_of_month = self.expand(
                                               ^^^^^^^^^^^^
  File "/home/airflow/.local/lib/python3.12/site-packages/croniter/croniter.py", line 1032, in expand
    return cls._expand(expr_format, hash_id=hash_id,
           ^^^^^^^^^^^^^^^^^^^^^^^^^^^^^^^^^^^^^^^^^
  File "/home/airflow/.local/lib/python3.12/site-packages/croniter/croniter.py", line 834, in _expand
    raise CroniterBadCronError(cls.bad_length)
croniter.croniter.CroniterBadCronError: Exactly 5, 6 or 7 columns has to be specified for iterator expression.

During handling of the above exception, another exception occurred:

Traceback (most recent call last):
  File "/home/airflow/.local/lib/python3.12/site-packages/airflow/models/dagbag.py", line 479, in _process_modules
    dag.validate()
  File "/home/airflow/.local/lib/python3.12/site-packages/airflow/models/dag.py", line 845, in validate
    self.timetable.validate()
  File "/home/airflow/.local/lib/python3.12/site-packages/airflow/timetables/_cron.py", line 104, in validate
    raise AirflowTimetableInvalid(str(e))
airflow.exceptions.AirflowTimetableInvalid: Exactly 5, 6 or 7 columns has to be specified for iterator expression.
[2025-05-30T15:25:05.963+0000] {processor.py:927} WARNING - No viable dags retrieved from /opt/airflow/dags/data_quality.py
[2025-05-30T15:25:06.112+0000] {processor.py:208} INFO - Processing /opt/airflow/dags/data_quality.py took 4.546 seconds
[2025-05-30T15:25:41.953+0000] {processor.py:186} INFO - Started process (PID=1189) to work on /opt/airflow/dags/data_quality.py
[2025-05-30T15:25:41.966+0000] {processor.py:914} INFO - Processing file /opt/airflow/dags/data_quality.py for tasks to queue
[2025-05-30T15:25:42.034+0000] {logging_mixin.py:190} INFO - [2025-05-30T15:25:42.033+0000] {dagbag.py:588} INFO - Filling up the DagBag from /opt/airflow/dags/data_quality.py
[2025-05-30T15:25:47.098+0000] {logging_mixin.py:190} INFO - [2025-05-30T15:25:47.067+0000] {dagbag.py:484} ERROR - Failed to bag_dag: /opt/airflow/dags/data_quality.py
Traceback (most recent call last):
  File "/home/airflow/.local/lib/python3.12/site-packages/airflow/timetables/_cron.py", line 102, in validate
    croniter(self._expression)
  File "/home/airflow/.local/lib/python3.12/site-packages/croniter/croniter.py", line 271, in __init__
    self.expanded, self.nth_weekday_of_month = self.expand(
                                               ^^^^^^^^^^^^
  File "/home/airflow/.local/lib/python3.12/site-packages/croniter/croniter.py", line 1032, in expand
    return cls._expand(expr_format, hash_id=hash_id,
           ^^^^^^^^^^^^^^^^^^^^^^^^^^^^^^^^^^^^^^^^^
  File "/home/airflow/.local/lib/python3.12/site-packages/croniter/croniter.py", line 834, in _expand
    raise CroniterBadCronError(cls.bad_length)
croniter.croniter.CroniterBadCronError: Exactly 5, 6 or 7 columns has to be specified for iterator expression.

During handling of the above exception, another exception occurred:

Traceback (most recent call last):
  File "/home/airflow/.local/lib/python3.12/site-packages/airflow/models/dagbag.py", line 479, in _process_modules
    dag.validate()
  File "/home/airflow/.local/lib/python3.12/site-packages/airflow/models/dag.py", line 845, in validate
    self.timetable.validate()
  File "/home/airflow/.local/lib/python3.12/site-packages/airflow/timetables/_cron.py", line 104, in validate
    raise AirflowTimetableInvalid(str(e))
airflow.exceptions.AirflowTimetableInvalid: Exactly 5, 6 or 7 columns has to be specified for iterator expression.
[2025-05-30T15:25:47.212+0000] {processor.py:927} WARNING - No viable dags retrieved from /opt/airflow/dags/data_quality.py
[2025-05-30T15:25:47.428+0000] {processor.py:208} INFO - Processing /opt/airflow/dags/data_quality.py took 5.527 seconds
[2025-05-30T15:26:19.534+0000] {processor.py:186} INFO - Started process (PID=1202) to work on /opt/airflow/dags/data_quality.py
[2025-05-30T15:26:19.549+0000] {processor.py:914} INFO - Processing file /opt/airflow/dags/data_quality.py for tasks to queue
[2025-05-30T15:26:19.581+0000] {logging_mixin.py:190} INFO - [2025-05-30T15:26:19.580+0000] {dagbag.py:588} INFO - Filling up the DagBag from /opt/airflow/dags/data_quality.py
[2025-05-30T15:26:23.544+0000] {logging_mixin.py:190} INFO - [2025-05-30T15:26:23.521+0000] {dagbag.py:484} ERROR - Failed to bag_dag: /opt/airflow/dags/data_quality.py
Traceback (most recent call last):
  File "/home/airflow/.local/lib/python3.12/site-packages/airflow/timetables/_cron.py", line 102, in validate
    croniter(self._expression)
  File "/home/airflow/.local/lib/python3.12/site-packages/croniter/croniter.py", line 271, in __init__
    self.expanded, self.nth_weekday_of_month = self.expand(
                                               ^^^^^^^^^^^^
  File "/home/airflow/.local/lib/python3.12/site-packages/croniter/croniter.py", line 1032, in expand
    return cls._expand(expr_format, hash_id=hash_id,
           ^^^^^^^^^^^^^^^^^^^^^^^^^^^^^^^^^^^^^^^^^
  File "/home/airflow/.local/lib/python3.12/site-packages/croniter/croniter.py", line 834, in _expand
    raise CroniterBadCronError(cls.bad_length)
croniter.croniter.CroniterBadCronError: Exactly 5, 6 or 7 columns has to be specified for iterator expression.

During handling of the above exception, another exception occurred:

Traceback (most recent call last):
  File "/home/airflow/.local/lib/python3.12/site-packages/airflow/models/dagbag.py", line 479, in _process_modules
    dag.validate()
  File "/home/airflow/.local/lib/python3.12/site-packages/airflow/models/dag.py", line 845, in validate
    self.timetable.validate()
  File "/home/airflow/.local/lib/python3.12/site-packages/airflow/timetables/_cron.py", line 104, in validate
    raise AirflowTimetableInvalid(str(e))
airflow.exceptions.AirflowTimetableInvalid: Exactly 5, 6 or 7 columns has to be specified for iterator expression.
[2025-05-30T15:26:23.567+0000] {processor.py:927} WARNING - No viable dags retrieved from /opt/airflow/dags/data_quality.py
[2025-05-30T15:26:23.781+0000] {processor.py:208} INFO - Processing /opt/airflow/dags/data_quality.py took 4.312 seconds
[2025-05-30T15:26:58.648+0000] {processor.py:186} INFO - Started process (PID=1215) to work on /opt/airflow/dags/data_quality.py
[2025-05-30T15:26:58.690+0000] {processor.py:914} INFO - Processing file /opt/airflow/dags/data_quality.py for tasks to queue
[2025-05-30T15:26:58.752+0000] {logging_mixin.py:190} INFO - [2025-05-30T15:26:58.751+0000] {dagbag.py:588} INFO - Filling up the DagBag from /opt/airflow/dags/data_quality.py
[2025-05-30T15:27:01.977+0000] {logging_mixin.py:190} INFO - [2025-05-30T15:27:01.957+0000] {dagbag.py:484} ERROR - Failed to bag_dag: /opt/airflow/dags/data_quality.py
Traceback (most recent call last):
  File "/home/airflow/.local/lib/python3.12/site-packages/airflow/timetables/_cron.py", line 102, in validate
    croniter(self._expression)
  File "/home/airflow/.local/lib/python3.12/site-packages/croniter/croniter.py", line 271, in __init__
    self.expanded, self.nth_weekday_of_month = self.expand(
                                               ^^^^^^^^^^^^
  File "/home/airflow/.local/lib/python3.12/site-packages/croniter/croniter.py", line 1032, in expand
    return cls._expand(expr_format, hash_id=hash_id,
           ^^^^^^^^^^^^^^^^^^^^^^^^^^^^^^^^^^^^^^^^^
  File "/home/airflow/.local/lib/python3.12/site-packages/croniter/croniter.py", line 834, in _expand
    raise CroniterBadCronError(cls.bad_length)
croniter.croniter.CroniterBadCronError: Exactly 5, 6 or 7 columns has to be specified for iterator expression.

During handling of the above exception, another exception occurred:

Traceback (most recent call last):
  File "/home/airflow/.local/lib/python3.12/site-packages/airflow/models/dagbag.py", line 479, in _process_modules
    dag.validate()
  File "/home/airflow/.local/lib/python3.12/site-packages/airflow/models/dag.py", line 845, in validate
    self.timetable.validate()
  File "/home/airflow/.local/lib/python3.12/site-packages/airflow/timetables/_cron.py", line 104, in validate
    raise AirflowTimetableInvalid(str(e))
airflow.exceptions.AirflowTimetableInvalid: Exactly 5, 6 or 7 columns has to be specified for iterator expression.
[2025-05-30T15:27:01.996+0000] {processor.py:927} WARNING - No viable dags retrieved from /opt/airflow/dags/data_quality.py
[2025-05-30T15:27:02.184+0000] {processor.py:208} INFO - Processing /opt/airflow/dags/data_quality.py took 3.617 seconds
[2025-05-30T15:27:40.599+0000] {processor.py:186} INFO - Started process (PID=1228) to work on /opt/airflow/dags/data_quality.py
[2025-05-30T15:27:40.609+0000] {processor.py:914} INFO - Processing file /opt/airflow/dags/data_quality.py for tasks to queue
[2025-05-30T15:27:40.632+0000] {logging_mixin.py:190} INFO - [2025-05-30T15:27:40.631+0000] {dagbag.py:588} INFO - Filling up the DagBag from /opt/airflow/dags/data_quality.py
[2025-05-30T15:27:43.696+0000] {logging_mixin.py:190} INFO - [2025-05-30T15:27:43.677+0000] {dagbag.py:484} ERROR - Failed to bag_dag: /opt/airflow/dags/data_quality.py
Traceback (most recent call last):
  File "/home/airflow/.local/lib/python3.12/site-packages/airflow/timetables/_cron.py", line 102, in validate
    croniter(self._expression)
  File "/home/airflow/.local/lib/python3.12/site-packages/croniter/croniter.py", line 271, in __init__
    self.expanded, self.nth_weekday_of_month = self.expand(
                                               ^^^^^^^^^^^^
  File "/home/airflow/.local/lib/python3.12/site-packages/croniter/croniter.py", line 1032, in expand
    return cls._expand(expr_format, hash_id=hash_id,
           ^^^^^^^^^^^^^^^^^^^^^^^^^^^^^^^^^^^^^^^^^
  File "/home/airflow/.local/lib/python3.12/site-packages/croniter/croniter.py", line 834, in _expand
    raise CroniterBadCronError(cls.bad_length)
croniter.croniter.CroniterBadCronError: Exactly 5, 6 or 7 columns has to be specified for iterator expression.

During handling of the above exception, another exception occurred:

Traceback (most recent call last):
  File "/home/airflow/.local/lib/python3.12/site-packages/airflow/models/dagbag.py", line 479, in _process_modules
    dag.validate()
  File "/home/airflow/.local/lib/python3.12/site-packages/airflow/models/dag.py", line 845, in validate
    self.timetable.validate()
  File "/home/airflow/.local/lib/python3.12/site-packages/airflow/timetables/_cron.py", line 104, in validate
    raise AirflowTimetableInvalid(str(e))
airflow.exceptions.AirflowTimetableInvalid: Exactly 5, 6 or 7 columns has to be specified for iterator expression.
[2025-05-30T15:27:43.718+0000] {processor.py:927} WARNING - No viable dags retrieved from /opt/airflow/dags/data_quality.py
[2025-05-30T15:27:43.956+0000] {processor.py:208} INFO - Processing /opt/airflow/dags/data_quality.py took 3.407 seconds
[2025-05-30T15:28:18.866+0000] {processor.py:186} INFO - Started process (PID=1247) to work on /opt/airflow/dags/data_quality.py
[2025-05-30T15:28:18.880+0000] {processor.py:914} INFO - Processing file /opt/airflow/dags/data_quality.py for tasks to queue
[2025-05-30T15:28:18.900+0000] {logging_mixin.py:190} INFO - [2025-05-30T15:28:18.900+0000] {dagbag.py:588} INFO - Filling up the DagBag from /opt/airflow/dags/data_quality.py
[2025-05-30T15:28:22.509+0000] {logging_mixin.py:190} INFO - [2025-05-30T15:28:22.491+0000] {dagbag.py:484} ERROR - Failed to bag_dag: /opt/airflow/dags/data_quality.py
Traceback (most recent call last):
  File "/home/airflow/.local/lib/python3.12/site-packages/airflow/timetables/_cron.py", line 102, in validate
    croniter(self._expression)
  File "/home/airflow/.local/lib/python3.12/site-packages/croniter/croniter.py", line 271, in __init__
    self.expanded, self.nth_weekday_of_month = self.expand(
                                               ^^^^^^^^^^^^
  File "/home/airflow/.local/lib/python3.12/site-packages/croniter/croniter.py", line 1032, in expand
    return cls._expand(expr_format, hash_id=hash_id,
           ^^^^^^^^^^^^^^^^^^^^^^^^^^^^^^^^^^^^^^^^^
  File "/home/airflow/.local/lib/python3.12/site-packages/croniter/croniter.py", line 834, in _expand
    raise CroniterBadCronError(cls.bad_length)
croniter.croniter.CroniterBadCronError: Exactly 5, 6 or 7 columns has to be specified for iterator expression.

During handling of the above exception, another exception occurred:

Traceback (most recent call last):
  File "/home/airflow/.local/lib/python3.12/site-packages/airflow/models/dagbag.py", line 479, in _process_modules
    dag.validate()
  File "/home/airflow/.local/lib/python3.12/site-packages/airflow/models/dag.py", line 845, in validate
    self.timetable.validate()
  File "/home/airflow/.local/lib/python3.12/site-packages/airflow/timetables/_cron.py", line 104, in validate
    raise AirflowTimetableInvalid(str(e))
airflow.exceptions.AirflowTimetableInvalid: Exactly 5, 6 or 7 columns has to be specified for iterator expression.
[2025-05-30T15:28:22.525+0000] {processor.py:927} WARNING - No viable dags retrieved from /opt/airflow/dags/data_quality.py
[2025-05-30T15:28:22.709+0000] {processor.py:208} INFO - Processing /opt/airflow/dags/data_quality.py took 3.896 seconds
[2025-05-30T15:28:55.716+0000] {processor.py:186} INFO - Started process (PID=1260) to work on /opt/airflow/dags/data_quality.py
[2025-05-30T15:28:55.729+0000] {processor.py:914} INFO - Processing file /opt/airflow/dags/data_quality.py for tasks to queue
[2025-05-30T15:28:55.749+0000] {logging_mixin.py:190} INFO - [2025-05-30T15:28:55.748+0000] {dagbag.py:588} INFO - Filling up the DagBag from /opt/airflow/dags/data_quality.py
[2025-05-30T15:28:59.547+0000] {logging_mixin.py:190} INFO - [2025-05-30T15:28:59.530+0000] {dagbag.py:484} ERROR - Failed to bag_dag: /opt/airflow/dags/data_quality.py
Traceback (most recent call last):
  File "/home/airflow/.local/lib/python3.12/site-packages/airflow/timetables/_cron.py", line 102, in validate
    croniter(self._expression)
  File "/home/airflow/.local/lib/python3.12/site-packages/croniter/croniter.py", line 271, in __init__
    self.expanded, self.nth_weekday_of_month = self.expand(
                                               ^^^^^^^^^^^^
  File "/home/airflow/.local/lib/python3.12/site-packages/croniter/croniter.py", line 1032, in expand
    return cls._expand(expr_format, hash_id=hash_id,
           ^^^^^^^^^^^^^^^^^^^^^^^^^^^^^^^^^^^^^^^^^
  File "/home/airflow/.local/lib/python3.12/site-packages/croniter/croniter.py", line 834, in _expand
    raise CroniterBadCronError(cls.bad_length)
croniter.croniter.CroniterBadCronError: Exactly 5, 6 or 7 columns has to be specified for iterator expression.

During handling of the above exception, another exception occurred:

Traceback (most recent call last):
  File "/home/airflow/.local/lib/python3.12/site-packages/airflow/models/dagbag.py", line 479, in _process_modules
    dag.validate()
  File "/home/airflow/.local/lib/python3.12/site-packages/airflow/models/dag.py", line 845, in validate
    self.timetable.validate()
  File "/home/airflow/.local/lib/python3.12/site-packages/airflow/timetables/_cron.py", line 104, in validate
    raise AirflowTimetableInvalid(str(e))
airflow.exceptions.AirflowTimetableInvalid: Exactly 5, 6 or 7 columns has to be specified for iterator expression.
[2025-05-30T15:28:59.558+0000] {processor.py:927} WARNING - No viable dags retrieved from /opt/airflow/dags/data_quality.py
[2025-05-30T15:28:59.719+0000] {processor.py:208} INFO - Processing /opt/airflow/dags/data_quality.py took 4.055 seconds
[2025-05-30T15:35:53.621+0000] {processor.py:186} INFO - Started process (PID=104) to work on /opt/airflow/dags/data_quality.py
[2025-05-30T15:35:53.750+0000] {processor.py:914} INFO - Processing file /opt/airflow/dags/data_quality.py for tasks to queue
[2025-05-30T15:35:53.877+0000] {logging_mixin.py:190} INFO - [2025-05-30T15:35:53.876+0000] {dagbag.py:588} INFO - Filling up the DagBag from /opt/airflow/dags/data_quality.py
[2025-05-30T15:36:08.802+0000] {logging_mixin.py:190} INFO - [2025-05-30T15:36:08.718+0000] {dagbag.py:484} ERROR - Failed to bag_dag: /opt/airflow/dags/data_quality.py
Traceback (most recent call last):
  File "/home/airflow/.local/lib/python3.12/site-packages/airflow/timetables/_cron.py", line 102, in validate
    croniter(self._expression)
  File "/home/airflow/.local/lib/python3.12/site-packages/croniter/croniter.py", line 271, in __init__
    self.expanded, self.nth_weekday_of_month = self.expand(
                                               ^^^^^^^^^^^^
  File "/home/airflow/.local/lib/python3.12/site-packages/croniter/croniter.py", line 1032, in expand
    return cls._expand(expr_format, hash_id=hash_id,
           ^^^^^^^^^^^^^^^^^^^^^^^^^^^^^^^^^^^^^^^^^
  File "/home/airflow/.local/lib/python3.12/site-packages/croniter/croniter.py", line 834, in _expand
    raise CroniterBadCronError(cls.bad_length)
croniter.croniter.CroniterBadCronError: Exactly 5, 6 or 7 columns has to be specified for iterator expression.

During handling of the above exception, another exception occurred:

Traceback (most recent call last):
  File "/home/airflow/.local/lib/python3.12/site-packages/airflow/models/dagbag.py", line 479, in _process_modules
    dag.validate()
  File "/home/airflow/.local/lib/python3.12/site-packages/airflow/models/dag.py", line 845, in validate
    self.timetable.validate()
  File "/home/airflow/.local/lib/python3.12/site-packages/airflow/timetables/_cron.py", line 104, in validate
    raise AirflowTimetableInvalid(str(e))
airflow.exceptions.AirflowTimetableInvalid: Exactly 5, 6 or 7 columns has to be specified for iterator expression.
[2025-05-30T15:36:08.859+0000] {processor.py:927} WARNING - No viable dags retrieved from /opt/airflow/dags/data_quality.py
[2025-05-30T15:36:09.682+0000] {processor.py:208} INFO - Processing /opt/airflow/dags/data_quality.py took 16.269 seconds
[2025-05-30T15:36:43.244+0000] {processor.py:186} INFO - Started process (PID=122) to work on /opt/airflow/dags/data_quality.py
[2025-05-30T15:36:43.275+0000] {processor.py:914} INFO - Processing file /opt/airflow/dags/data_quality.py for tasks to queue
[2025-05-30T15:36:43.329+0000] {logging_mixin.py:190} INFO - [2025-05-30T15:36:43.328+0000] {dagbag.py:588} INFO - Filling up the DagBag from /opt/airflow/dags/data_quality.py
[2025-05-30T15:36:52.937+0000] {logging_mixin.py:190} INFO - [2025-05-30T15:36:52.918+0000] {dagbag.py:484} ERROR - Failed to bag_dag: /opt/airflow/dags/data_quality.py
Traceback (most recent call last):
  File "/home/airflow/.local/lib/python3.12/site-packages/airflow/timetables/_cron.py", line 102, in validate
    croniter(self._expression)
  File "/home/airflow/.local/lib/python3.12/site-packages/croniter/croniter.py", line 271, in __init__
    self.expanded, self.nth_weekday_of_month = self.expand(
                                               ^^^^^^^^^^^^
  File "/home/airflow/.local/lib/python3.12/site-packages/croniter/croniter.py", line 1032, in expand
    return cls._expand(expr_format, hash_id=hash_id,
           ^^^^^^^^^^^^^^^^^^^^^^^^^^^^^^^^^^^^^^^^^
  File "/home/airflow/.local/lib/python3.12/site-packages/croniter/croniter.py", line 834, in _expand
    raise CroniterBadCronError(cls.bad_length)
croniter.croniter.CroniterBadCronError: Exactly 5, 6 or 7 columns has to be specified for iterator expression.

During handling of the above exception, another exception occurred:

Traceback (most recent call last):
  File "/home/airflow/.local/lib/python3.12/site-packages/airflow/models/dagbag.py", line 479, in _process_modules
    dag.validate()
  File "/home/airflow/.local/lib/python3.12/site-packages/airflow/models/dag.py", line 845, in validate
    self.timetable.validate()
  File "/home/airflow/.local/lib/python3.12/site-packages/airflow/timetables/_cron.py", line 104, in validate
    raise AirflowTimetableInvalid(str(e))
airflow.exceptions.AirflowTimetableInvalid: Exactly 5, 6 or 7 columns has to be specified for iterator expression.
[2025-05-30T15:36:52.965+0000] {processor.py:927} WARNING - No viable dags retrieved from /opt/airflow/dags/data_quality.py
[2025-05-30T15:36:53.281+0000] {processor.py:208} INFO - Processing /opt/airflow/dags/data_quality.py took 10.105 seconds
[2025-05-30T15:37:32.016+0000] {processor.py:186} INFO - Started process (PID=134) to work on /opt/airflow/dags/data_quality.py
[2025-05-30T15:37:32.028+0000] {processor.py:914} INFO - Processing file /opt/airflow/dags/data_quality.py for tasks to queue
[2025-05-30T15:37:32.047+0000] {logging_mixin.py:190} INFO - [2025-05-30T15:37:32.046+0000] {dagbag.py:588} INFO - Filling up the DagBag from /opt/airflow/dags/data_quality.py
[2025-05-30T15:37:41.186+0000] {logging_mixin.py:190} INFO - [2025-05-30T15:37:41.156+0000] {dagbag.py:484} ERROR - Failed to bag_dag: /opt/airflow/dags/data_quality.py
Traceback (most recent call last):
  File "/home/airflow/.local/lib/python3.12/site-packages/airflow/timetables/_cron.py", line 102, in validate
    croniter(self._expression)
  File "/home/airflow/.local/lib/python3.12/site-packages/croniter/croniter.py", line 271, in __init__
    self.expanded, self.nth_weekday_of_month = self.expand(
                                               ^^^^^^^^^^^^
  File "/home/airflow/.local/lib/python3.12/site-packages/croniter/croniter.py", line 1032, in expand
    return cls._expand(expr_format, hash_id=hash_id,
           ^^^^^^^^^^^^^^^^^^^^^^^^^^^^^^^^^^^^^^^^^
  File "/home/airflow/.local/lib/python3.12/site-packages/croniter/croniter.py", line 834, in _expand
    raise CroniterBadCronError(cls.bad_length)
croniter.croniter.CroniterBadCronError: Exactly 5, 6 or 7 columns has to be specified for iterator expression.

During handling of the above exception, another exception occurred:

Traceback (most recent call last):
  File "/home/airflow/.local/lib/python3.12/site-packages/airflow/models/dagbag.py", line 479, in _process_modules
    dag.validate()
  File "/home/airflow/.local/lib/python3.12/site-packages/airflow/models/dag.py", line 845, in validate
    self.timetable.validate()
  File "/home/airflow/.local/lib/python3.12/site-packages/airflow/timetables/_cron.py", line 104, in validate
    raise AirflowTimetableInvalid(str(e))
airflow.exceptions.AirflowTimetableInvalid: Exactly 5, 6 or 7 columns has to be specified for iterator expression.
[2025-05-30T15:37:41.202+0000] {processor.py:927} WARNING - No viable dags retrieved from /opt/airflow/dags/data_quality.py
[2025-05-30T15:37:41.585+0000] {processor.py:208} INFO - Processing /opt/airflow/dags/data_quality.py took 9.613 seconds
[2025-05-30T15:38:12.852+0000] {processor.py:186} INFO - Started process (PID=153) to work on /opt/airflow/dags/data_quality.py
[2025-05-30T15:38:12.858+0000] {processor.py:914} INFO - Processing file /opt/airflow/dags/data_quality.py for tasks to queue
[2025-05-30T15:38:12.876+0000] {logging_mixin.py:190} INFO - [2025-05-30T15:38:12.874+0000] {dagbag.py:588} INFO - Filling up the DagBag from /opt/airflow/dags/data_quality.py
[2025-05-30T15:38:16.990+0000] {logging_mixin.py:190} INFO - [2025-05-30T15:38:16.961+0000] {dagbag.py:484} ERROR - Failed to bag_dag: /opt/airflow/dags/data_quality.py
Traceback (most recent call last):
  File "/home/airflow/.local/lib/python3.12/site-packages/airflow/timetables/_cron.py", line 102, in validate
    croniter(self._expression)
  File "/home/airflow/.local/lib/python3.12/site-packages/croniter/croniter.py", line 271, in __init__
    self.expanded, self.nth_weekday_of_month = self.expand(
                                               ^^^^^^^^^^^^
  File "/home/airflow/.local/lib/python3.12/site-packages/croniter/croniter.py", line 1032, in expand
    return cls._expand(expr_format, hash_id=hash_id,
           ^^^^^^^^^^^^^^^^^^^^^^^^^^^^^^^^^^^^^^^^^
  File "/home/airflow/.local/lib/python3.12/site-packages/croniter/croniter.py", line 834, in _expand
    raise CroniterBadCronError(cls.bad_length)
croniter.croniter.CroniterBadCronError: Exactly 5, 6 or 7 columns has to be specified for iterator expression.

During handling of the above exception, another exception occurred:

Traceback (most recent call last):
  File "/home/airflow/.local/lib/python3.12/site-packages/airflow/models/dagbag.py", line 479, in _process_modules
    dag.validate()
  File "/home/airflow/.local/lib/python3.12/site-packages/airflow/models/dag.py", line 845, in validate
    self.timetable.validate()
  File "/home/airflow/.local/lib/python3.12/site-packages/airflow/timetables/_cron.py", line 104, in validate
    raise AirflowTimetableInvalid(str(e))
airflow.exceptions.AirflowTimetableInvalid: Exactly 5, 6 or 7 columns has to be specified for iterator expression.
[2025-05-30T15:38:16.999+0000] {processor.py:927} WARNING - No viable dags retrieved from /opt/airflow/dags/data_quality.py
[2025-05-30T15:38:17.089+0000] {processor.py:208} INFO - Processing /opt/airflow/dags/data_quality.py took 4.286 seconds
[2025-05-30T15:38:47.530+0000] {processor.py:186} INFO - Started process (PID=167) to work on /opt/airflow/dags/data_quality.py
[2025-05-30T15:38:47.533+0000] {processor.py:914} INFO - Processing file /opt/airflow/dags/data_quality.py for tasks to queue
[2025-05-30T15:38:47.541+0000] {logging_mixin.py:190} INFO - [2025-05-30T15:38:47.540+0000] {dagbag.py:588} INFO - Filling up the DagBag from /opt/airflow/dags/data_quality.py
[2025-05-30T15:38:48.956+0000] {logging_mixin.py:190} INFO - [2025-05-30T15:38:48.946+0000] {dagbag.py:484} ERROR - Failed to bag_dag: /opt/airflow/dags/data_quality.py
Traceback (most recent call last):
  File "/home/airflow/.local/lib/python3.12/site-packages/airflow/timetables/_cron.py", line 102, in validate
    croniter(self._expression)
  File "/home/airflow/.local/lib/python3.12/site-packages/croniter/croniter.py", line 271, in __init__
    self.expanded, self.nth_weekday_of_month = self.expand(
                                               ^^^^^^^^^^^^
  File "/home/airflow/.local/lib/python3.12/site-packages/croniter/croniter.py", line 1032, in expand
    return cls._expand(expr_format, hash_id=hash_id,
           ^^^^^^^^^^^^^^^^^^^^^^^^^^^^^^^^^^^^^^^^^
  File "/home/airflow/.local/lib/python3.12/site-packages/croniter/croniter.py", line 834, in _expand
    raise CroniterBadCronError(cls.bad_length)
croniter.croniter.CroniterBadCronError: Exactly 5, 6 or 7 columns has to be specified for iterator expression.

During handling of the above exception, another exception occurred:

Traceback (most recent call last):
  File "/home/airflow/.local/lib/python3.12/site-packages/airflow/models/dagbag.py", line 479, in _process_modules
    dag.validate()
  File "/home/airflow/.local/lib/python3.12/site-packages/airflow/models/dag.py", line 845, in validate
    self.timetable.validate()
  File "/home/airflow/.local/lib/python3.12/site-packages/airflow/timetables/_cron.py", line 104, in validate
    raise AirflowTimetableInvalid(str(e))
airflow.exceptions.AirflowTimetableInvalid: Exactly 5, 6 or 7 columns has to be specified for iterator expression.
[2025-05-30T15:38:48.958+0000] {processor.py:927} WARNING - No viable dags retrieved from /opt/airflow/dags/data_quality.py
[2025-05-30T15:38:49.014+0000] {processor.py:208} INFO - Processing /opt/airflow/dags/data_quality.py took 1.508 seconds
[2025-05-30T15:39:19.822+0000] {processor.py:186} INFO - Started process (PID=180) to work on /opt/airflow/dags/data_quality.py
[2025-05-30T15:39:19.833+0000] {processor.py:914} INFO - Processing file /opt/airflow/dags/data_quality.py for tasks to queue
[2025-05-30T15:39:19.851+0000] {logging_mixin.py:190} INFO - [2025-05-30T15:39:19.849+0000] {dagbag.py:588} INFO - Filling up the DagBag from /opt/airflow/dags/data_quality.py
[2025-05-30T15:39:20.667+0000] {logging_mixin.py:190} INFO - [2025-05-30T15:39:20.663+0000] {dagbag.py:484} ERROR - Failed to bag_dag: /opt/airflow/dags/data_quality.py
Traceback (most recent call last):
  File "/home/airflow/.local/lib/python3.12/site-packages/airflow/timetables/_cron.py", line 102, in validate
    croniter(self._expression)
  File "/home/airflow/.local/lib/python3.12/site-packages/croniter/croniter.py", line 271, in __init__
    self.expanded, self.nth_weekday_of_month = self.expand(
                                               ^^^^^^^^^^^^
  File "/home/airflow/.local/lib/python3.12/site-packages/croniter/croniter.py", line 1032, in expand
    return cls._expand(expr_format, hash_id=hash_id,
           ^^^^^^^^^^^^^^^^^^^^^^^^^^^^^^^^^^^^^^^^^
  File "/home/airflow/.local/lib/python3.12/site-packages/croniter/croniter.py", line 834, in _expand
    raise CroniterBadCronError(cls.bad_length)
croniter.croniter.CroniterBadCronError: Exactly 5, 6 or 7 columns has to be specified for iterator expression.

During handling of the above exception, another exception occurred:

Traceback (most recent call last):
  File "/home/airflow/.local/lib/python3.12/site-packages/airflow/models/dagbag.py", line 479, in _process_modules
    dag.validate()
  File "/home/airflow/.local/lib/python3.12/site-packages/airflow/models/dag.py", line 845, in validate
    self.timetable.validate()
  File "/home/airflow/.local/lib/python3.12/site-packages/airflow/timetables/_cron.py", line 104, in validate
    raise AirflowTimetableInvalid(str(e))
airflow.exceptions.AirflowTimetableInvalid: Exactly 5, 6 or 7 columns has to be specified for iterator expression.
[2025-05-30T15:39:20.668+0000] {processor.py:927} WARNING - No viable dags retrieved from /opt/airflow/dags/data_quality.py
[2025-05-30T15:39:20.711+0000] {processor.py:208} INFO - Processing /opt/airflow/dags/data_quality.py took 0.932 seconds
[2025-05-30T15:39:51.416+0000] {processor.py:186} INFO - Started process (PID=193) to work on /opt/airflow/dags/data_quality.py
[2025-05-30T15:39:51.420+0000] {processor.py:914} INFO - Processing file /opt/airflow/dags/data_quality.py for tasks to queue
[2025-05-30T15:39:51.431+0000] {logging_mixin.py:190} INFO - [2025-05-30T15:39:51.430+0000] {dagbag.py:588} INFO - Filling up the DagBag from /opt/airflow/dags/data_quality.py
[2025-05-30T15:39:52.163+0000] {logging_mixin.py:190} INFO - [2025-05-30T15:39:52.159+0000] {dagbag.py:484} ERROR - Failed to bag_dag: /opt/airflow/dags/data_quality.py
Traceback (most recent call last):
  File "/home/airflow/.local/lib/python3.12/site-packages/airflow/timetables/_cron.py", line 102, in validate
    croniter(self._expression)
  File "/home/airflow/.local/lib/python3.12/site-packages/croniter/croniter.py", line 271, in __init__
    self.expanded, self.nth_weekday_of_month = self.expand(
                                               ^^^^^^^^^^^^
  File "/home/airflow/.local/lib/python3.12/site-packages/croniter/croniter.py", line 1032, in expand
    return cls._expand(expr_format, hash_id=hash_id,
           ^^^^^^^^^^^^^^^^^^^^^^^^^^^^^^^^^^^^^^^^^
  File "/home/airflow/.local/lib/python3.12/site-packages/croniter/croniter.py", line 834, in _expand
    raise CroniterBadCronError(cls.bad_length)
croniter.croniter.CroniterBadCronError: Exactly 5, 6 or 7 columns has to be specified for iterator expression.

During handling of the above exception, another exception occurred:

Traceback (most recent call last):
  File "/home/airflow/.local/lib/python3.12/site-packages/airflow/models/dagbag.py", line 479, in _process_modules
    dag.validate()
  File "/home/airflow/.local/lib/python3.12/site-packages/airflow/models/dag.py", line 845, in validate
    self.timetable.validate()
  File "/home/airflow/.local/lib/python3.12/site-packages/airflow/timetables/_cron.py", line 104, in validate
    raise AirflowTimetableInvalid(str(e))
airflow.exceptions.AirflowTimetableInvalid: Exactly 5, 6 or 7 columns has to be specified for iterator expression.
[2025-05-30T15:39:52.164+0000] {processor.py:927} WARNING - No viable dags retrieved from /opt/airflow/dags/data_quality.py
[2025-05-30T15:39:52.202+0000] {processor.py:208} INFO - Processing /opt/airflow/dags/data_quality.py took 0.810 seconds
[2025-05-30T15:40:22.361+0000] {processor.py:186} INFO - Started process (PID=206) to work on /opt/airflow/dags/data_quality.py
[2025-05-30T15:40:22.364+0000] {processor.py:914} INFO - Processing file /opt/airflow/dags/data_quality.py for tasks to queue
[2025-05-30T15:40:22.372+0000] {logging_mixin.py:190} INFO - [2025-05-30T15:40:22.371+0000] {dagbag.py:588} INFO - Filling up the DagBag from /opt/airflow/dags/data_quality.py
[2025-05-30T15:40:23.356+0000] {logging_mixin.py:190} INFO - [2025-05-30T15:40:23.347+0000] {dagbag.py:484} ERROR - Failed to bag_dag: /opt/airflow/dags/data_quality.py
Traceback (most recent call last):
  File "/home/airflow/.local/lib/python3.12/site-packages/airflow/timetables/_cron.py", line 102, in validate
    croniter(self._expression)
  File "/home/airflow/.local/lib/python3.12/site-packages/croniter/croniter.py", line 271, in __init__
    self.expanded, self.nth_weekday_of_month = self.expand(
                                               ^^^^^^^^^^^^
  File "/home/airflow/.local/lib/python3.12/site-packages/croniter/croniter.py", line 1032, in expand
    return cls._expand(expr_format, hash_id=hash_id,
           ^^^^^^^^^^^^^^^^^^^^^^^^^^^^^^^^^^^^^^^^^
  File "/home/airflow/.local/lib/python3.12/site-packages/croniter/croniter.py", line 834, in _expand
    raise CroniterBadCronError(cls.bad_length)
croniter.croniter.CroniterBadCronError: Exactly 5, 6 or 7 columns has to be specified for iterator expression.

During handling of the above exception, another exception occurred:

Traceback (most recent call last):
  File "/home/airflow/.local/lib/python3.12/site-packages/airflow/models/dagbag.py", line 479, in _process_modules
    dag.validate()
  File "/home/airflow/.local/lib/python3.12/site-packages/airflow/models/dag.py", line 845, in validate
    self.timetable.validate()
  File "/home/airflow/.local/lib/python3.12/site-packages/airflow/timetables/_cron.py", line 104, in validate
    raise AirflowTimetableInvalid(str(e))
airflow.exceptions.AirflowTimetableInvalid: Exactly 5, 6 or 7 columns has to be specified for iterator expression.
[2025-05-30T15:40:23.357+0000] {processor.py:927} WARNING - No viable dags retrieved from /opt/airflow/dags/data_quality.py
[2025-05-30T15:40:23.411+0000] {processor.py:208} INFO - Processing /opt/airflow/dags/data_quality.py took 1.066 seconds
[2025-05-30T15:40:53.908+0000] {processor.py:186} INFO - Started process (PID=219) to work on /opt/airflow/dags/data_quality.py
[2025-05-30T15:40:53.912+0000] {processor.py:914} INFO - Processing file /opt/airflow/dags/data_quality.py for tasks to queue
[2025-05-30T15:40:53.923+0000] {logging_mixin.py:190} INFO - [2025-05-30T15:40:53.922+0000] {dagbag.py:588} INFO - Filling up the DagBag from /opt/airflow/dags/data_quality.py
[2025-05-30T15:40:55.120+0000] {logging_mixin.py:190} INFO - [2025-05-30T15:40:55.113+0000] {dagbag.py:484} ERROR - Failed to bag_dag: /opt/airflow/dags/data_quality.py
Traceback (most recent call last):
  File "/home/airflow/.local/lib/python3.12/site-packages/airflow/timetables/_cron.py", line 102, in validate
    croniter(self._expression)
  File "/home/airflow/.local/lib/python3.12/site-packages/croniter/croniter.py", line 271, in __init__
    self.expanded, self.nth_weekday_of_month = self.expand(
                                               ^^^^^^^^^^^^
  File "/home/airflow/.local/lib/python3.12/site-packages/croniter/croniter.py", line 1032, in expand
    return cls._expand(expr_format, hash_id=hash_id,
           ^^^^^^^^^^^^^^^^^^^^^^^^^^^^^^^^^^^^^^^^^
  File "/home/airflow/.local/lib/python3.12/site-packages/croniter/croniter.py", line 834, in _expand
    raise CroniterBadCronError(cls.bad_length)
croniter.croniter.CroniterBadCronError: Exactly 5, 6 or 7 columns has to be specified for iterator expression.

During handling of the above exception, another exception occurred:

Traceback (most recent call last):
  File "/home/airflow/.local/lib/python3.12/site-packages/airflow/models/dagbag.py", line 479, in _process_modules
    dag.validate()
  File "/home/airflow/.local/lib/python3.12/site-packages/airflow/models/dag.py", line 845, in validate
    self.timetable.validate()
  File "/home/airflow/.local/lib/python3.12/site-packages/airflow/timetables/_cron.py", line 104, in validate
    raise AirflowTimetableInvalid(str(e))
airflow.exceptions.AirflowTimetableInvalid: Exactly 5, 6 or 7 columns has to be specified for iterator expression.
[2025-05-30T15:40:55.121+0000] {processor.py:927} WARNING - No viable dags retrieved from /opt/airflow/dags/data_quality.py
[2025-05-30T15:40:55.178+0000] {processor.py:208} INFO - Processing /opt/airflow/dags/data_quality.py took 1.295 seconds
[2025-05-30T19:12:45.649+0000] {processor.py:186} INFO - Started process (PID=231) to work on /opt/airflow/dags/data_quality.py
[2025-05-30T19:12:45.674+0000] {processor.py:914} INFO - Processing file /opt/airflow/dags/data_quality.py for tasks to queue
[2025-05-30T19:12:45.711+0000] {logging_mixin.py:190} INFO - [2025-05-30T19:12:45.710+0000] {dagbag.py:588} INFO - Filling up the DagBag from /opt/airflow/dags/data_quality.py
[2025-05-30T19:12:49.683+0000] {logging_mixin.py:190} INFO - [2025-05-30T19:12:49.664+0000] {dagbag.py:484} ERROR - Failed to bag_dag: /opt/airflow/dags/data_quality.py
Traceback (most recent call last):
  File "/home/airflow/.local/lib/python3.12/site-packages/airflow/timetables/_cron.py", line 102, in validate
    croniter(self._expression)
  File "/home/airflow/.local/lib/python3.12/site-packages/croniter/croniter.py", line 271, in __init__
    self.expanded, self.nth_weekday_of_month = self.expand(
                                               ^^^^^^^^^^^^
  File "/home/airflow/.local/lib/python3.12/site-packages/croniter/croniter.py", line 1032, in expand
    return cls._expand(expr_format, hash_id=hash_id,
           ^^^^^^^^^^^^^^^^^^^^^^^^^^^^^^^^^^^^^^^^^
  File "/home/airflow/.local/lib/python3.12/site-packages/croniter/croniter.py", line 834, in _expand
    raise CroniterBadCronError(cls.bad_length)
croniter.croniter.CroniterBadCronError: Exactly 5, 6 or 7 columns has to be specified for iterator expression.

During handling of the above exception, another exception occurred:

Traceback (most recent call last):
  File "/home/airflow/.local/lib/python3.12/site-packages/airflow/models/dagbag.py", line 479, in _process_modules
    dag.validate()
  File "/home/airflow/.local/lib/python3.12/site-packages/airflow/models/dag.py", line 845, in validate
    self.timetable.validate()
  File "/home/airflow/.local/lib/python3.12/site-packages/airflow/timetables/_cron.py", line 104, in validate
    raise AirflowTimetableInvalid(str(e))
airflow.exceptions.AirflowTimetableInvalid: Exactly 5, 6 or 7 columns has to be specified for iterator expression.
[2025-05-30T19:12:49.691+0000] {processor.py:927} WARNING - No viable dags retrieved from /opt/airflow/dags/data_quality.py
[2025-05-30T19:12:49.800+0000] {processor.py:208} INFO - Processing /opt/airflow/dags/data_quality.py took 4.191 seconds
[2025-05-30T19:13:27.539+0000] {processor.py:186} INFO - Started process (PID=245) to work on /opt/airflow/dags/data_quality.py
[2025-05-30T19:13:27.562+0000] {processor.py:914} INFO - Processing file /opt/airflow/dags/data_quality.py for tasks to queue
[2025-05-30T19:13:27.582+0000] {logging_mixin.py:190} INFO - [2025-05-30T19:13:27.581+0000] {dagbag.py:588} INFO - Filling up the DagBag from /opt/airflow/dags/data_quality.py
[2025-05-30T19:13:32.985+0000] {logging_mixin.py:190} INFO - [2025-05-30T19:13:32.969+0000] {dagbag.py:484} ERROR - Failed to bag_dag: /opt/airflow/dags/data_quality.py
Traceback (most recent call last):
  File "/home/airflow/.local/lib/python3.12/site-packages/airflow/timetables/_cron.py", line 102, in validate
    croniter(self._expression)
  File "/home/airflow/.local/lib/python3.12/site-packages/croniter/croniter.py", line 271, in __init__
    self.expanded, self.nth_weekday_of_month = self.expand(
                                               ^^^^^^^^^^^^
  File "/home/airflow/.local/lib/python3.12/site-packages/croniter/croniter.py", line 1032, in expand
    return cls._expand(expr_format, hash_id=hash_id,
           ^^^^^^^^^^^^^^^^^^^^^^^^^^^^^^^^^^^^^^^^^
  File "/home/airflow/.local/lib/python3.12/site-packages/croniter/croniter.py", line 834, in _expand
    raise CroniterBadCronError(cls.bad_length)
croniter.croniter.CroniterBadCronError: Exactly 5, 6 or 7 columns has to be specified for iterator expression.

During handling of the above exception, another exception occurred:

Traceback (most recent call last):
  File "/home/airflow/.local/lib/python3.12/site-packages/airflow/models/dagbag.py", line 479, in _process_modules
    dag.validate()
  File "/home/airflow/.local/lib/python3.12/site-packages/airflow/models/dag.py", line 845, in validate
    self.timetable.validate()
  File "/home/airflow/.local/lib/python3.12/site-packages/airflow/timetables/_cron.py", line 104, in validate
    raise AirflowTimetableInvalid(str(e))
airflow.exceptions.AirflowTimetableInvalid: Exactly 5, 6 or 7 columns has to be specified for iterator expression.
[2025-05-30T19:13:33.002+0000] {processor.py:927} WARNING - No viable dags retrieved from /opt/airflow/dags/data_quality.py
[2025-05-30T19:13:33.149+0000] {processor.py:208} INFO - Processing /opt/airflow/dags/data_quality.py took 5.657 seconds
[2025-05-30T19:14:04.863+0000] {processor.py:186} INFO - Started process (PID=258) to work on /opt/airflow/dags/data_quality.py
[2025-05-30T19:14:04.897+0000] {processor.py:914} INFO - Processing file /opt/airflow/dags/data_quality.py for tasks to queue
[2025-05-30T19:14:04.953+0000] {logging_mixin.py:190} INFO - [2025-05-30T19:14:04.947+0000] {dagbag.py:588} INFO - Filling up the DagBag from /opt/airflow/dags/data_quality.py
[2025-05-30T19:14:08.582+0000] {logging_mixin.py:190} INFO - [2025-05-30T19:14:08.563+0000] {dagbag.py:484} ERROR - Failed to bag_dag: /opt/airflow/dags/data_quality.py
Traceback (most recent call last):
  File "/home/airflow/.local/lib/python3.12/site-packages/airflow/timetables/_cron.py", line 102, in validate
    croniter(self._expression)
  File "/home/airflow/.local/lib/python3.12/site-packages/croniter/croniter.py", line 271, in __init__
    self.expanded, self.nth_weekday_of_month = self.expand(
                                               ^^^^^^^^^^^^
  File "/home/airflow/.local/lib/python3.12/site-packages/croniter/croniter.py", line 1032, in expand
    return cls._expand(expr_format, hash_id=hash_id,
           ^^^^^^^^^^^^^^^^^^^^^^^^^^^^^^^^^^^^^^^^^
  File "/home/airflow/.local/lib/python3.12/site-packages/croniter/croniter.py", line 834, in _expand
    raise CroniterBadCronError(cls.bad_length)
croniter.croniter.CroniterBadCronError: Exactly 5, 6 or 7 columns has to be specified for iterator expression.

During handling of the above exception, another exception occurred:

Traceback (most recent call last):
  File "/home/airflow/.local/lib/python3.12/site-packages/airflow/models/dagbag.py", line 479, in _process_modules
    dag.validate()
  File "/home/airflow/.local/lib/python3.12/site-packages/airflow/models/dag.py", line 845, in validate
    self.timetable.validate()
  File "/home/airflow/.local/lib/python3.12/site-packages/airflow/timetables/_cron.py", line 104, in validate
    raise AirflowTimetableInvalid(str(e))
airflow.exceptions.AirflowTimetableInvalid: Exactly 5, 6 or 7 columns has to be specified for iterator expression.
[2025-05-30T19:14:08.595+0000] {processor.py:927} WARNING - No viable dags retrieved from /opt/airflow/dags/data_quality.py
[2025-05-30T19:14:08.690+0000] {processor.py:208} INFO - Processing /opt/airflow/dags/data_quality.py took 3.889 seconds
[2025-05-30T19:14:39.645+0000] {processor.py:186} INFO - Started process (PID=271) to work on /opt/airflow/dags/data_quality.py
[2025-05-30T19:14:39.649+0000] {processor.py:914} INFO - Processing file /opt/airflow/dags/data_quality.py for tasks to queue
[2025-05-30T19:14:39.681+0000] {logging_mixin.py:190} INFO - [2025-05-30T19:14:39.680+0000] {dagbag.py:588} INFO - Filling up the DagBag from /opt/airflow/dags/data_quality.py
[2025-05-30T19:14:43.059+0000] {logging_mixin.py:190} INFO - [2025-05-30T19:14:43.031+0000] {dagbag.py:484} ERROR - Failed to bag_dag: /opt/airflow/dags/data_quality.py
Traceback (most recent call last):
  File "/home/airflow/.local/lib/python3.12/site-packages/airflow/timetables/_cron.py", line 102, in validate
    croniter(self._expression)
  File "/home/airflow/.local/lib/python3.12/site-packages/croniter/croniter.py", line 271, in __init__
    self.expanded, self.nth_weekday_of_month = self.expand(
                                               ^^^^^^^^^^^^
  File "/home/airflow/.local/lib/python3.12/site-packages/croniter/croniter.py", line 1032, in expand
    return cls._expand(expr_format, hash_id=hash_id,
           ^^^^^^^^^^^^^^^^^^^^^^^^^^^^^^^^^^^^^^^^^
  File "/home/airflow/.local/lib/python3.12/site-packages/croniter/croniter.py", line 834, in _expand
    raise CroniterBadCronError(cls.bad_length)
croniter.croniter.CroniterBadCronError: Exactly 5, 6 or 7 columns has to be specified for iterator expression.

During handling of the above exception, another exception occurred:

Traceback (most recent call last):
  File "/home/airflow/.local/lib/python3.12/site-packages/airflow/models/dagbag.py", line 479, in _process_modules
    dag.validate()
  File "/home/airflow/.local/lib/python3.12/site-packages/airflow/models/dag.py", line 845, in validate
    self.timetable.validate()
  File "/home/airflow/.local/lib/python3.12/site-packages/airflow/timetables/_cron.py", line 104, in validate
    raise AirflowTimetableInvalid(str(e))
airflow.exceptions.AirflowTimetableInvalid: Exactly 5, 6 or 7 columns has to be specified for iterator expression.
[2025-05-30T19:14:43.061+0000] {processor.py:927} WARNING - No viable dags retrieved from /opt/airflow/dags/data_quality.py
[2025-05-30T19:14:43.187+0000] {processor.py:208} INFO - Processing /opt/airflow/dags/data_quality.py took 3.605 seconds
[2025-05-30T19:15:14.862+0000] {processor.py:186} INFO - Started process (PID=290) to work on /opt/airflow/dags/data_quality.py
[2025-05-30T19:15:14.866+0000] {processor.py:914} INFO - Processing file /opt/airflow/dags/data_quality.py for tasks to queue
[2025-05-30T19:15:14.913+0000] {logging_mixin.py:190} INFO - [2025-05-30T19:15:14.912+0000] {dagbag.py:588} INFO - Filling up the DagBag from /opt/airflow/dags/data_quality.py
[2025-05-30T19:15:18.314+0000] {logging_mixin.py:190} INFO - [2025-05-30T19:15:18.283+0000] {dagbag.py:484} ERROR - Failed to bag_dag: /opt/airflow/dags/data_quality.py
Traceback (most recent call last):
  File "/home/airflow/.local/lib/python3.12/site-packages/airflow/timetables/_cron.py", line 102, in validate
    croniter(self._expression)
  File "/home/airflow/.local/lib/python3.12/site-packages/croniter/croniter.py", line 271, in __init__
    self.expanded, self.nth_weekday_of_month = self.expand(
                                               ^^^^^^^^^^^^
  File "/home/airflow/.local/lib/python3.12/site-packages/croniter/croniter.py", line 1032, in expand
    return cls._expand(expr_format, hash_id=hash_id,
           ^^^^^^^^^^^^^^^^^^^^^^^^^^^^^^^^^^^^^^^^^
  File "/home/airflow/.local/lib/python3.12/site-packages/croniter/croniter.py", line 834, in _expand
    raise CroniterBadCronError(cls.bad_length)
croniter.croniter.CroniterBadCronError: Exactly 5, 6 or 7 columns has to be specified for iterator expression.

During handling of the above exception, another exception occurred:

Traceback (most recent call last):
  File "/home/airflow/.local/lib/python3.12/site-packages/airflow/models/dagbag.py", line 479, in _process_modules
    dag.validate()
  File "/home/airflow/.local/lib/python3.12/site-packages/airflow/models/dag.py", line 845, in validate
    self.timetable.validate()
  File "/home/airflow/.local/lib/python3.12/site-packages/airflow/timetables/_cron.py", line 104, in validate
    raise AirflowTimetableInvalid(str(e))
airflow.exceptions.AirflowTimetableInvalid: Exactly 5, 6 or 7 columns has to be specified for iterator expression.
[2025-05-30T19:15:18.319+0000] {processor.py:927} WARNING - No viable dags retrieved from /opt/airflow/dags/data_quality.py
[2025-05-30T19:15:18.480+0000] {processor.py:208} INFO - Processing /opt/airflow/dags/data_quality.py took 3.709 seconds
[2025-05-30T19:15:50.795+0000] {processor.py:186} INFO - Started process (PID=303) to work on /opt/airflow/dags/data_quality.py
[2025-05-30T19:15:50.809+0000] {processor.py:914} INFO - Processing file /opt/airflow/dags/data_quality.py for tasks to queue
[2025-05-30T19:15:50.829+0000] {logging_mixin.py:190} INFO - [2025-05-30T19:15:50.828+0000] {dagbag.py:588} INFO - Filling up the DagBag from /opt/airflow/dags/data_quality.py
[2025-05-30T19:15:53.849+0000] {logging_mixin.py:190} INFO - [2025-05-30T19:15:53.830+0000] {dagbag.py:484} ERROR - Failed to bag_dag: /opt/airflow/dags/data_quality.py
Traceback (most recent call last):
  File "/home/airflow/.local/lib/python3.12/site-packages/airflow/timetables/_cron.py", line 102, in validate
    croniter(self._expression)
  File "/home/airflow/.local/lib/python3.12/site-packages/croniter/croniter.py", line 271, in __init__
    self.expanded, self.nth_weekday_of_month = self.expand(
                                               ^^^^^^^^^^^^
  File "/home/airflow/.local/lib/python3.12/site-packages/croniter/croniter.py", line 1032, in expand
    return cls._expand(expr_format, hash_id=hash_id,
           ^^^^^^^^^^^^^^^^^^^^^^^^^^^^^^^^^^^^^^^^^
  File "/home/airflow/.local/lib/python3.12/site-packages/croniter/croniter.py", line 834, in _expand
    raise CroniterBadCronError(cls.bad_length)
croniter.croniter.CroniterBadCronError: Exactly 5, 6 or 7 columns has to be specified for iterator expression.

During handling of the above exception, another exception occurred:

Traceback (most recent call last):
  File "/home/airflow/.local/lib/python3.12/site-packages/airflow/models/dagbag.py", line 479, in _process_modules
    dag.validate()
  File "/home/airflow/.local/lib/python3.12/site-packages/airflow/models/dag.py", line 845, in validate
    self.timetable.validate()
  File "/home/airflow/.local/lib/python3.12/site-packages/airflow/timetables/_cron.py", line 104, in validate
    raise AirflowTimetableInvalid(str(e))
airflow.exceptions.AirflowTimetableInvalid: Exactly 5, 6 or 7 columns has to be specified for iterator expression.
[2025-05-30T19:15:53.862+0000] {processor.py:927} WARNING - No viable dags retrieved from /opt/airflow/dags/data_quality.py
[2025-05-30T19:15:54.073+0000] {processor.py:208} INFO - Processing /opt/airflow/dags/data_quality.py took 3.340 seconds
[2025-05-30T19:16:25.684+0000] {processor.py:186} INFO - Started process (PID=317) to work on /opt/airflow/dags/data_quality.py
[2025-05-30T19:16:25.700+0000] {processor.py:914} INFO - Processing file /opt/airflow/dags/data_quality.py for tasks to queue
[2025-05-30T19:16:25.719+0000] {logging_mixin.py:190} INFO - [2025-05-30T19:16:25.717+0000] {dagbag.py:588} INFO - Filling up the DagBag from /opt/airflow/dags/data_quality.py
[2025-05-30T19:16:28.390+0000] {logging_mixin.py:190} INFO - [2025-05-30T19:16:28.372+0000] {dagbag.py:484} ERROR - Failed to bag_dag: /opt/airflow/dags/data_quality.py
Traceback (most recent call last):
  File "/home/airflow/.local/lib/python3.12/site-packages/airflow/timetables/_cron.py", line 102, in validate
    croniter(self._expression)
  File "/home/airflow/.local/lib/python3.12/site-packages/croniter/croniter.py", line 271, in __init__
    self.expanded, self.nth_weekday_of_month = self.expand(
                                               ^^^^^^^^^^^^
  File "/home/airflow/.local/lib/python3.12/site-packages/croniter/croniter.py", line 1032, in expand
    return cls._expand(expr_format, hash_id=hash_id,
           ^^^^^^^^^^^^^^^^^^^^^^^^^^^^^^^^^^^^^^^^^
  File "/home/airflow/.local/lib/python3.12/site-packages/croniter/croniter.py", line 834, in _expand
    raise CroniterBadCronError(cls.bad_length)
croniter.croniter.CroniterBadCronError: Exactly 5, 6 or 7 columns has to be specified for iterator expression.

During handling of the above exception, another exception occurred:

Traceback (most recent call last):
  File "/home/airflow/.local/lib/python3.12/site-packages/airflow/models/dagbag.py", line 479, in _process_modules
    dag.validate()
  File "/home/airflow/.local/lib/python3.12/site-packages/airflow/models/dag.py", line 845, in validate
    self.timetable.validate()
  File "/home/airflow/.local/lib/python3.12/site-packages/airflow/timetables/_cron.py", line 104, in validate
    raise AirflowTimetableInvalid(str(e))
airflow.exceptions.AirflowTimetableInvalid: Exactly 5, 6 or 7 columns has to be specified for iterator expression.
[2025-05-30T19:16:28.418+0000] {processor.py:927} WARNING - No viable dags retrieved from /opt/airflow/dags/data_quality.py
[2025-05-30T19:16:28.579+0000] {processor.py:208} INFO - Processing /opt/airflow/dags/data_quality.py took 2.934 seconds
[2025-05-30T19:16:59.149+0000] {processor.py:186} INFO - Started process (PID=330) to work on /opt/airflow/dags/data_quality.py
[2025-05-30T19:16:59.153+0000] {processor.py:914} INFO - Processing file /opt/airflow/dags/data_quality.py for tasks to queue
[2025-05-30T19:16:59.170+0000] {logging_mixin.py:190} INFO - [2025-05-30T19:16:59.165+0000] {dagbag.py:588} INFO - Filling up the DagBag from /opt/airflow/dags/data_quality.py
[2025-05-30T19:17:00.999+0000] {logging_mixin.py:190} INFO - [2025-05-30T19:17:00.988+0000] {dagbag.py:484} ERROR - Failed to bag_dag: /opt/airflow/dags/data_quality.py
Traceback (most recent call last):
  File "/home/airflow/.local/lib/python3.12/site-packages/airflow/timetables/_cron.py", line 102, in validate
    croniter(self._expression)
  File "/home/airflow/.local/lib/python3.12/site-packages/croniter/croniter.py", line 271, in __init__
    self.expanded, self.nth_weekday_of_month = self.expand(
                                               ^^^^^^^^^^^^
  File "/home/airflow/.local/lib/python3.12/site-packages/croniter/croniter.py", line 1032, in expand
    return cls._expand(expr_format, hash_id=hash_id,
           ^^^^^^^^^^^^^^^^^^^^^^^^^^^^^^^^^^^^^^^^^
  File "/home/airflow/.local/lib/python3.12/site-packages/croniter/croniter.py", line 834, in _expand
    raise CroniterBadCronError(cls.bad_length)
croniter.croniter.CroniterBadCronError: Exactly 5, 6 or 7 columns has to be specified for iterator expression.

During handling of the above exception, another exception occurred:

Traceback (most recent call last):
  File "/home/airflow/.local/lib/python3.12/site-packages/airflow/models/dagbag.py", line 479, in _process_modules
    dag.validate()
  File "/home/airflow/.local/lib/python3.12/site-packages/airflow/models/dag.py", line 845, in validate
    self.timetable.validate()
  File "/home/airflow/.local/lib/python3.12/site-packages/airflow/timetables/_cron.py", line 104, in validate
    raise AirflowTimetableInvalid(str(e))
airflow.exceptions.AirflowTimetableInvalid: Exactly 5, 6 or 7 columns has to be specified for iterator expression.
[2025-05-30T19:17:01.001+0000] {processor.py:927} WARNING - No viable dags retrieved from /opt/airflow/dags/data_quality.py
[2025-05-30T19:17:01.099+0000] {processor.py:208} INFO - Processing /opt/airflow/dags/data_quality.py took 1.992 seconds
[2025-05-30T19:17:34.110+0000] {processor.py:186} INFO - Started process (PID=343) to work on /opt/airflow/dags/data_quality.py
[2025-05-30T19:17:34.124+0000] {processor.py:914} INFO - Processing file /opt/airflow/dags/data_quality.py for tasks to queue
[2025-05-30T19:17:34.144+0000] {logging_mixin.py:190} INFO - [2025-05-30T19:17:34.142+0000] {dagbag.py:588} INFO - Filling up the DagBag from /opt/airflow/dags/data_quality.py
[2025-05-30T19:17:37.379+0000] {logging_mixin.py:190} INFO - [2025-05-30T19:17:37.360+0000] {dagbag.py:484} ERROR - Failed to bag_dag: /opt/airflow/dags/data_quality.py
Traceback (most recent call last):
  File "/home/airflow/.local/lib/python3.12/site-packages/airflow/timetables/_cron.py", line 102, in validate
    croniter(self._expression)
  File "/home/airflow/.local/lib/python3.12/site-packages/croniter/croniter.py", line 271, in __init__
    self.expanded, self.nth_weekday_of_month = self.expand(
                                               ^^^^^^^^^^^^
  File "/home/airflow/.local/lib/python3.12/site-packages/croniter/croniter.py", line 1032, in expand
    return cls._expand(expr_format, hash_id=hash_id,
           ^^^^^^^^^^^^^^^^^^^^^^^^^^^^^^^^^^^^^^^^^
  File "/home/airflow/.local/lib/python3.12/site-packages/croniter/croniter.py", line 834, in _expand
    raise CroniterBadCronError(cls.bad_length)
croniter.croniter.CroniterBadCronError: Exactly 5, 6 or 7 columns has to be specified for iterator expression.

During handling of the above exception, another exception occurred:

Traceback (most recent call last):
  File "/home/airflow/.local/lib/python3.12/site-packages/airflow/models/dagbag.py", line 479, in _process_modules
    dag.validate()
  File "/home/airflow/.local/lib/python3.12/site-packages/airflow/models/dag.py", line 845, in validate
    self.timetable.validate()
  File "/home/airflow/.local/lib/python3.12/site-packages/airflow/timetables/_cron.py", line 104, in validate
    raise AirflowTimetableInvalid(str(e))
airflow.exceptions.AirflowTimetableInvalid: Exactly 5, 6 or 7 columns has to be specified for iterator expression.
[2025-05-30T19:17:37.483+0000] {processor.py:927} WARNING - No viable dags retrieved from /opt/airflow/dags/data_quality.py
[2025-05-30T19:17:37.860+0000] {processor.py:208} INFO - Processing /opt/airflow/dags/data_quality.py took 3.809 seconds
[2025-05-30T19:18:10.432+0000] {processor.py:186} INFO - Started process (PID=356) to work on /opt/airflow/dags/data_quality.py
[2025-05-30T19:18:10.438+0000] {processor.py:914} INFO - Processing file /opt/airflow/dags/data_quality.py for tasks to queue
[2025-05-30T19:18:10.454+0000] {logging_mixin.py:190} INFO - [2025-05-30T19:18:10.453+0000] {dagbag.py:588} INFO - Filling up the DagBag from /opt/airflow/dags/data_quality.py
[2025-05-30T19:18:13.266+0000] {logging_mixin.py:190} INFO - [2025-05-30T19:18:13.238+0000] {dagbag.py:484} ERROR - Failed to bag_dag: /opt/airflow/dags/data_quality.py
Traceback (most recent call last):
  File "/home/airflow/.local/lib/python3.12/site-packages/airflow/timetables/_cron.py", line 102, in validate
    croniter(self._expression)
  File "/home/airflow/.local/lib/python3.12/site-packages/croniter/croniter.py", line 271, in __init__
    self.expanded, self.nth_weekday_of_month = self.expand(
                                               ^^^^^^^^^^^^
  File "/home/airflow/.local/lib/python3.12/site-packages/croniter/croniter.py", line 1032, in expand
    return cls._expand(expr_format, hash_id=hash_id,
           ^^^^^^^^^^^^^^^^^^^^^^^^^^^^^^^^^^^^^^^^^
  File "/home/airflow/.local/lib/python3.12/site-packages/croniter/croniter.py", line 834, in _expand
    raise CroniterBadCronError(cls.bad_length)
croniter.croniter.CroniterBadCronError: Exactly 5, 6 or 7 columns has to be specified for iterator expression.

During handling of the above exception, another exception occurred:

Traceback (most recent call last):
  File "/home/airflow/.local/lib/python3.12/site-packages/airflow/models/dagbag.py", line 479, in _process_modules
    dag.validate()
  File "/home/airflow/.local/lib/python3.12/site-packages/airflow/models/dag.py", line 845, in validate
    self.timetable.validate()
  File "/home/airflow/.local/lib/python3.12/site-packages/airflow/timetables/_cron.py", line 104, in validate
    raise AirflowTimetableInvalid(str(e))
airflow.exceptions.AirflowTimetableInvalid: Exactly 5, 6 or 7 columns has to be specified for iterator expression.
[2025-05-30T19:18:13.286+0000] {processor.py:927} WARNING - No viable dags retrieved from /opt/airflow/dags/data_quality.py
[2025-05-30T19:18:13.415+0000] {processor.py:208} INFO - Processing /opt/airflow/dags/data_quality.py took 3.033 seconds
[2025-05-30T19:18:48.287+0000] {processor.py:186} INFO - Started process (PID=373) to work on /opt/airflow/dags/data_quality.py
[2025-05-30T19:18:48.301+0000] {processor.py:914} INFO - Processing file /opt/airflow/dags/data_quality.py for tasks to queue
[2025-05-30T19:18:48.333+0000] {logging_mixin.py:190} INFO - [2025-05-30T19:18:48.322+0000] {dagbag.py:588} INFO - Filling up the DagBag from /opt/airflow/dags/data_quality.py
[2025-05-30T19:18:51.062+0000] {logging_mixin.py:190} INFO - [2025-05-30T19:18:51.045+0000] {dagbag.py:484} ERROR - Failed to bag_dag: /opt/airflow/dags/data_quality.py
Traceback (most recent call last):
  File "/home/airflow/.local/lib/python3.12/site-packages/airflow/timetables/_cron.py", line 102, in validate
    croniter(self._expression)
  File "/home/airflow/.local/lib/python3.12/site-packages/croniter/croniter.py", line 271, in __init__
    self.expanded, self.nth_weekday_of_month = self.expand(
                                               ^^^^^^^^^^^^
  File "/home/airflow/.local/lib/python3.12/site-packages/croniter/croniter.py", line 1032, in expand
    return cls._expand(expr_format, hash_id=hash_id,
           ^^^^^^^^^^^^^^^^^^^^^^^^^^^^^^^^^^^^^^^^^
  File "/home/airflow/.local/lib/python3.12/site-packages/croniter/croniter.py", line 834, in _expand
    raise CroniterBadCronError(cls.bad_length)
croniter.croniter.CroniterBadCronError: Exactly 5, 6 or 7 columns has to be specified for iterator expression.

During handling of the above exception, another exception occurred:

Traceback (most recent call last):
  File "/home/airflow/.local/lib/python3.12/site-packages/airflow/models/dagbag.py", line 479, in _process_modules
    dag.validate()
  File "/home/airflow/.local/lib/python3.12/site-packages/airflow/models/dag.py", line 845, in validate
    self.timetable.validate()
  File "/home/airflow/.local/lib/python3.12/site-packages/airflow/timetables/_cron.py", line 104, in validate
    raise AirflowTimetableInvalid(str(e))
airflow.exceptions.AirflowTimetableInvalid: Exactly 5, 6 or 7 columns has to be specified for iterator expression.
[2025-05-30T19:18:51.064+0000] {processor.py:927} WARNING - No viable dags retrieved from /opt/airflow/dags/data_quality.py
[2025-05-30T19:18:51.185+0000] {processor.py:208} INFO - Processing /opt/airflow/dags/data_quality.py took 2.977 seconds
[2025-05-30T19:19:25.435+0000] {processor.py:186} INFO - Started process (PID=387) to work on /opt/airflow/dags/data_quality.py
[2025-05-30T19:19:25.449+0000] {processor.py:914} INFO - Processing file /opt/airflow/dags/data_quality.py for tasks to queue
[2025-05-30T19:19:25.469+0000] {logging_mixin.py:190} INFO - [2025-05-30T19:19:25.468+0000] {dagbag.py:588} INFO - Filling up the DagBag from /opt/airflow/dags/data_quality.py
[2025-05-30T19:19:27.795+0000] {logging_mixin.py:190} INFO - [2025-05-30T19:19:27.766+0000] {dagbag.py:484} ERROR - Failed to bag_dag: /opt/airflow/dags/data_quality.py
Traceback (most recent call last):
  File "/home/airflow/.local/lib/python3.12/site-packages/airflow/timetables/_cron.py", line 102, in validate
    croniter(self._expression)
  File "/home/airflow/.local/lib/python3.12/site-packages/croniter/croniter.py", line 271, in __init__
    self.expanded, self.nth_weekday_of_month = self.expand(
                                               ^^^^^^^^^^^^
  File "/home/airflow/.local/lib/python3.12/site-packages/croniter/croniter.py", line 1032, in expand
    return cls._expand(expr_format, hash_id=hash_id,
           ^^^^^^^^^^^^^^^^^^^^^^^^^^^^^^^^^^^^^^^^^
  File "/home/airflow/.local/lib/python3.12/site-packages/croniter/croniter.py", line 834, in _expand
    raise CroniterBadCronError(cls.bad_length)
croniter.croniter.CroniterBadCronError: Exactly 5, 6 or 7 columns has to be specified for iterator expression.

During handling of the above exception, another exception occurred:

Traceback (most recent call last):
  File "/home/airflow/.local/lib/python3.12/site-packages/airflow/models/dagbag.py", line 479, in _process_modules
    dag.validate()
  File "/home/airflow/.local/lib/python3.12/site-packages/airflow/models/dag.py", line 845, in validate
    self.timetable.validate()
  File "/home/airflow/.local/lib/python3.12/site-packages/airflow/timetables/_cron.py", line 104, in validate
    raise AirflowTimetableInvalid(str(e))
airflow.exceptions.AirflowTimetableInvalid: Exactly 5, 6 or 7 columns has to be specified for iterator expression.
[2025-05-30T19:19:27.804+0000] {processor.py:927} WARNING - No viable dags retrieved from /opt/airflow/dags/data_quality.py
[2025-05-30T19:19:27.953+0000] {processor.py:208} INFO - Processing /opt/airflow/dags/data_quality.py took 2.564 seconds
[2025-05-30T19:20:03.474+0000] {processor.py:186} INFO - Started process (PID=400) to work on /opt/airflow/dags/data_quality.py
[2025-05-30T19:20:03.489+0000] {processor.py:914} INFO - Processing file /opt/airflow/dags/data_quality.py for tasks to queue
[2025-05-30T19:20:03.521+0000] {logging_mixin.py:190} INFO - [2025-05-30T19:20:03.520+0000] {dagbag.py:588} INFO - Filling up the DagBag from /opt/airflow/dags/data_quality.py
[2025-05-30T19:20:08.381+0000] {logging_mixin.py:190} INFO - [2025-05-30T19:20:08.352+0000] {dagbag.py:484} ERROR - Failed to bag_dag: /opt/airflow/dags/data_quality.py
Traceback (most recent call last):
  File "/home/airflow/.local/lib/python3.12/site-packages/airflow/timetables/_cron.py", line 102, in validate
    croniter(self._expression)
  File "/home/airflow/.local/lib/python3.12/site-packages/croniter/croniter.py", line 271, in __init__
    self.expanded, self.nth_weekday_of_month = self.expand(
                                               ^^^^^^^^^^^^
  File "/home/airflow/.local/lib/python3.12/site-packages/croniter/croniter.py", line 1032, in expand
    return cls._expand(expr_format, hash_id=hash_id,
           ^^^^^^^^^^^^^^^^^^^^^^^^^^^^^^^^^^^^^^^^^
  File "/home/airflow/.local/lib/python3.12/site-packages/croniter/croniter.py", line 834, in _expand
    raise CroniterBadCronError(cls.bad_length)
croniter.croniter.CroniterBadCronError: Exactly 5, 6 or 7 columns has to be specified for iterator expression.

During handling of the above exception, another exception occurred:

Traceback (most recent call last):
  File "/home/airflow/.local/lib/python3.12/site-packages/airflow/models/dagbag.py", line 479, in _process_modules
    dag.validate()
  File "/home/airflow/.local/lib/python3.12/site-packages/airflow/models/dag.py", line 845, in validate
    self.timetable.validate()
  File "/home/airflow/.local/lib/python3.12/site-packages/airflow/timetables/_cron.py", line 104, in validate
    raise AirflowTimetableInvalid(str(e))
airflow.exceptions.AirflowTimetableInvalid: Exactly 5, 6 or 7 columns has to be specified for iterator expression.
[2025-05-30T19:20:08.403+0000] {processor.py:927} WARNING - No viable dags retrieved from /opt/airflow/dags/data_quality.py
[2025-05-30T19:20:08.585+0000] {processor.py:208} INFO - Processing /opt/airflow/dags/data_quality.py took 5.238 seconds
[2025-05-30T19:20:40.062+0000] {processor.py:186} INFO - Started process (PID=413) to work on /opt/airflow/dags/data_quality.py
[2025-05-30T19:20:40.074+0000] {processor.py:914} INFO - Processing file /opt/airflow/dags/data_quality.py for tasks to queue
[2025-05-30T19:20:40.119+0000] {logging_mixin.py:190} INFO - [2025-05-30T19:20:40.118+0000] {dagbag.py:588} INFO - Filling up the DagBag from /opt/airflow/dags/data_quality.py
[2025-05-30T19:20:45.984+0000] {logging_mixin.py:190} INFO - [2025-05-30T19:20:45.955+0000] {dagbag.py:484} ERROR - Failed to bag_dag: /opt/airflow/dags/data_quality.py
Traceback (most recent call last):
  File "/home/airflow/.local/lib/python3.12/site-packages/airflow/timetables/_cron.py", line 102, in validate
    croniter(self._expression)
  File "/home/airflow/.local/lib/python3.12/site-packages/croniter/croniter.py", line 271, in __init__
    self.expanded, self.nth_weekday_of_month = self.expand(
                                               ^^^^^^^^^^^^
  File "/home/airflow/.local/lib/python3.12/site-packages/croniter/croniter.py", line 1032, in expand
    return cls._expand(expr_format, hash_id=hash_id,
           ^^^^^^^^^^^^^^^^^^^^^^^^^^^^^^^^^^^^^^^^^
  File "/home/airflow/.local/lib/python3.12/site-packages/croniter/croniter.py", line 834, in _expand
    raise CroniterBadCronError(cls.bad_length)
croniter.croniter.CroniterBadCronError: Exactly 5, 6 or 7 columns has to be specified for iterator expression.

During handling of the above exception, another exception occurred:

Traceback (most recent call last):
  File "/home/airflow/.local/lib/python3.12/site-packages/airflow/models/dagbag.py", line 479, in _process_modules
    dag.validate()
  File "/home/airflow/.local/lib/python3.12/site-packages/airflow/models/dag.py", line 845, in validate
    self.timetable.validate()
  File "/home/airflow/.local/lib/python3.12/site-packages/airflow/timetables/_cron.py", line 104, in validate
    raise AirflowTimetableInvalid(str(e))
airflow.exceptions.AirflowTimetableInvalid: Exactly 5, 6 or 7 columns has to be specified for iterator expression.
[2025-05-30T19:20:45.987+0000] {processor.py:927} WARNING - No viable dags retrieved from /opt/airflow/dags/data_quality.py
[2025-05-30T19:20:46.175+0000] {processor.py:208} INFO - Processing /opt/airflow/dags/data_quality.py took 6.165 seconds
[2025-05-30T19:21:16.861+0000] {processor.py:186} INFO - Started process (PID=432) to work on /opt/airflow/dags/data_quality.py
[2025-05-30T19:21:16.864+0000] {processor.py:914} INFO - Processing file /opt/airflow/dags/data_quality.py for tasks to queue
[2025-05-30T19:21:16.883+0000] {logging_mixin.py:190} INFO - [2025-05-30T19:21:16.882+0000] {dagbag.py:588} INFO - Filling up the DagBag from /opt/airflow/dags/data_quality.py
[2025-05-30T19:21:19.395+0000] {logging_mixin.py:190} INFO - [2025-05-30T19:21:19.363+0000] {dagbag.py:484} ERROR - Failed to bag_dag: /opt/airflow/dags/data_quality.py
Traceback (most recent call last):
  File "/home/airflow/.local/lib/python3.12/site-packages/airflow/timetables/_cron.py", line 102, in validate
    croniter(self._expression)
  File "/home/airflow/.local/lib/python3.12/site-packages/croniter/croniter.py", line 271, in __init__
    self.expanded, self.nth_weekday_of_month = self.expand(
                                               ^^^^^^^^^^^^
  File "/home/airflow/.local/lib/python3.12/site-packages/croniter/croniter.py", line 1032, in expand
    return cls._expand(expr_format, hash_id=hash_id,
           ^^^^^^^^^^^^^^^^^^^^^^^^^^^^^^^^^^^^^^^^^
  File "/home/airflow/.local/lib/python3.12/site-packages/croniter/croniter.py", line 834, in _expand
    raise CroniterBadCronError(cls.bad_length)
croniter.croniter.CroniterBadCronError: Exactly 5, 6 or 7 columns has to be specified for iterator expression.

During handling of the above exception, another exception occurred:

Traceback (most recent call last):
  File "/home/airflow/.local/lib/python3.12/site-packages/airflow/models/dagbag.py", line 479, in _process_modules
    dag.validate()
  File "/home/airflow/.local/lib/python3.12/site-packages/airflow/models/dag.py", line 845, in validate
    self.timetable.validate()
  File "/home/airflow/.local/lib/python3.12/site-packages/airflow/timetables/_cron.py", line 104, in validate
    raise AirflowTimetableInvalid(str(e))
airflow.exceptions.AirflowTimetableInvalid: Exactly 5, 6 or 7 columns has to be specified for iterator expression.
[2025-05-30T19:21:19.410+0000] {processor.py:927} WARNING - No viable dags retrieved from /opt/airflow/dags/data_quality.py
[2025-05-30T19:21:19.543+0000] {processor.py:208} INFO - Processing /opt/airflow/dags/data_quality.py took 2.724 seconds
[2025-05-30T19:21:51.079+0000] {processor.py:186} INFO - Started process (PID=445) to work on /opt/airflow/dags/data_quality.py
[2025-05-30T19:21:51.098+0000] {processor.py:914} INFO - Processing file /opt/airflow/dags/data_quality.py for tasks to queue
[2025-05-30T19:21:51.145+0000] {logging_mixin.py:190} INFO - [2025-05-30T19:21:51.144+0000] {dagbag.py:588} INFO - Filling up the DagBag from /opt/airflow/dags/data_quality.py
[2025-05-30T19:21:54.994+0000] {logging_mixin.py:190} INFO - [2025-05-30T19:21:54.964+0000] {dagbag.py:484} ERROR - Failed to bag_dag: /opt/airflow/dags/data_quality.py
Traceback (most recent call last):
  File "/home/airflow/.local/lib/python3.12/site-packages/airflow/timetables/_cron.py", line 102, in validate
    croniter(self._expression)
  File "/home/airflow/.local/lib/python3.12/site-packages/croniter/croniter.py", line 271, in __init__
    self.expanded, self.nth_weekday_of_month = self.expand(
                                               ^^^^^^^^^^^^
  File "/home/airflow/.local/lib/python3.12/site-packages/croniter/croniter.py", line 1032, in expand
    return cls._expand(expr_format, hash_id=hash_id,
           ^^^^^^^^^^^^^^^^^^^^^^^^^^^^^^^^^^^^^^^^^
  File "/home/airflow/.local/lib/python3.12/site-packages/croniter/croniter.py", line 834, in _expand
    raise CroniterBadCronError(cls.bad_length)
croniter.croniter.CroniterBadCronError: Exactly 5, 6 or 7 columns has to be specified for iterator expression.

During handling of the above exception, another exception occurred:

Traceback (most recent call last):
  File "/home/airflow/.local/lib/python3.12/site-packages/airflow/models/dagbag.py", line 479, in _process_modules
    dag.validate()
  File "/home/airflow/.local/lib/python3.12/site-packages/airflow/models/dag.py", line 845, in validate
    self.timetable.validate()
  File "/home/airflow/.local/lib/python3.12/site-packages/airflow/timetables/_cron.py", line 104, in validate
    raise AirflowTimetableInvalid(str(e))
airflow.exceptions.AirflowTimetableInvalid: Exactly 5, 6 or 7 columns has to be specified for iterator expression.
[2025-05-30T19:21:54.995+0000] {processor.py:927} WARNING - No viable dags retrieved from /opt/airflow/dags/data_quality.py
[2025-05-30T19:21:55.155+0000] {processor.py:208} INFO - Processing /opt/airflow/dags/data_quality.py took 4.175 seconds
[2025-05-30T19:22:25.574+0000] {processor.py:186} INFO - Started process (PID=459) to work on /opt/airflow/dags/data_quality.py
[2025-05-30T19:22:25.577+0000] {processor.py:914} INFO - Processing file /opt/airflow/dags/data_quality.py for tasks to queue
[2025-05-30T19:22:25.608+0000] {logging_mixin.py:190} INFO - [2025-05-30T19:22:25.606+0000] {dagbag.py:588} INFO - Filling up the DagBag from /opt/airflow/dags/data_quality.py
[2025-05-30T19:22:27.668+0000] {logging_mixin.py:190} INFO - [2025-05-30T19:22:27.630+0000] {dagbag.py:484} ERROR - Failed to bag_dag: /opt/airflow/dags/data_quality.py
Traceback (most recent call last):
  File "/home/airflow/.local/lib/python3.12/site-packages/airflow/timetables/_cron.py", line 102, in validate
    croniter(self._expression)
  File "/home/airflow/.local/lib/python3.12/site-packages/croniter/croniter.py", line 271, in __init__
    self.expanded, self.nth_weekday_of_month = self.expand(
                                               ^^^^^^^^^^^^
  File "/home/airflow/.local/lib/python3.12/site-packages/croniter/croniter.py", line 1032, in expand
    return cls._expand(expr_format, hash_id=hash_id,
           ^^^^^^^^^^^^^^^^^^^^^^^^^^^^^^^^^^^^^^^^^
  File "/home/airflow/.local/lib/python3.12/site-packages/croniter/croniter.py", line 834, in _expand
    raise CroniterBadCronError(cls.bad_length)
croniter.croniter.CroniterBadCronError: Exactly 5, 6 or 7 columns has to be specified for iterator expression.

During handling of the above exception, another exception occurred:

Traceback (most recent call last):
  File "/home/airflow/.local/lib/python3.12/site-packages/airflow/models/dagbag.py", line 479, in _process_modules
    dag.validate()
  File "/home/airflow/.local/lib/python3.12/site-packages/airflow/models/dag.py", line 845, in validate
    self.timetable.validate()
  File "/home/airflow/.local/lib/python3.12/site-packages/airflow/timetables/_cron.py", line 104, in validate
    raise AirflowTimetableInvalid(str(e))
airflow.exceptions.AirflowTimetableInvalid: Exactly 5, 6 or 7 columns has to be specified for iterator expression.
[2025-05-30T19:22:27.670+0000] {processor.py:927} WARNING - No viable dags retrieved from /opt/airflow/dags/data_quality.py
[2025-05-30T19:22:27.802+0000] {processor.py:208} INFO - Processing /opt/airflow/dags/data_quality.py took 2.270 seconds
[2025-05-30T19:22:58.557+0000] {processor.py:186} INFO - Started process (PID=471) to work on /opt/airflow/dags/data_quality.py
[2025-05-30T19:22:58.560+0000] {processor.py:914} INFO - Processing file /opt/airflow/dags/data_quality.py for tasks to queue
[2025-05-30T19:22:58.570+0000] {logging_mixin.py:190} INFO - [2025-05-30T19:22:58.567+0000] {dagbag.py:588} INFO - Filling up the DagBag from /opt/airflow/dags/data_quality.py
[2025-05-30T19:23:00.803+0000] {logging_mixin.py:190} INFO - [2025-05-30T19:23:00.784+0000] {dagbag.py:484} ERROR - Failed to bag_dag: /opt/airflow/dags/data_quality.py
Traceback (most recent call last):
  File "/home/airflow/.local/lib/python3.12/site-packages/airflow/timetables/_cron.py", line 102, in validate
    croniter(self._expression)
  File "/home/airflow/.local/lib/python3.12/site-packages/croniter/croniter.py", line 271, in __init__
    self.expanded, self.nth_weekday_of_month = self.expand(
                                               ^^^^^^^^^^^^
  File "/home/airflow/.local/lib/python3.12/site-packages/croniter/croniter.py", line 1032, in expand
    return cls._expand(expr_format, hash_id=hash_id,
           ^^^^^^^^^^^^^^^^^^^^^^^^^^^^^^^^^^^^^^^^^
  File "/home/airflow/.local/lib/python3.12/site-packages/croniter/croniter.py", line 834, in _expand
    raise CroniterBadCronError(cls.bad_length)
croniter.croniter.CroniterBadCronError: Exactly 5, 6 or 7 columns has to be specified for iterator expression.

During handling of the above exception, another exception occurred:

Traceback (most recent call last):
  File "/home/airflow/.local/lib/python3.12/site-packages/airflow/models/dagbag.py", line 479, in _process_modules
    dag.validate()
  File "/home/airflow/.local/lib/python3.12/site-packages/airflow/models/dag.py", line 845, in validate
    self.timetable.validate()
  File "/home/airflow/.local/lib/python3.12/site-packages/airflow/timetables/_cron.py", line 104, in validate
    raise AirflowTimetableInvalid(str(e))
airflow.exceptions.AirflowTimetableInvalid: Exactly 5, 6 or 7 columns has to be specified for iterator expression.
[2025-05-30T19:23:00.805+0000] {processor.py:927} WARNING - No viable dags retrieved from /opt/airflow/dags/data_quality.py
[2025-05-30T19:23:00.904+0000] {processor.py:208} INFO - Processing /opt/airflow/dags/data_quality.py took 2.391 seconds
[2025-05-30T19:23:34.461+0000] {processor.py:186} INFO - Started process (PID=484) to work on /opt/airflow/dags/data_quality.py
[2025-05-30T19:23:34.482+0000] {processor.py:914} INFO - Processing file /opt/airflow/dags/data_quality.py for tasks to queue
[2025-05-30T19:23:34.506+0000] {logging_mixin.py:190} INFO - [2025-05-30T19:23:34.499+0000] {dagbag.py:588} INFO - Filling up the DagBag from /opt/airflow/dags/data_quality.py
[2025-05-30T19:23:37.079+0000] {logging_mixin.py:190} INFO - [2025-05-30T19:23:37.059+0000] {dagbag.py:484} ERROR - Failed to bag_dag: /opt/airflow/dags/data_quality.py
Traceback (most recent call last):
  File "/home/airflow/.local/lib/python3.12/site-packages/airflow/timetables/_cron.py", line 102, in validate
    croniter(self._expression)
  File "/home/airflow/.local/lib/python3.12/site-packages/croniter/croniter.py", line 271, in __init__
    self.expanded, self.nth_weekday_of_month = self.expand(
                                               ^^^^^^^^^^^^
  File "/home/airflow/.local/lib/python3.12/site-packages/croniter/croniter.py", line 1032, in expand
    return cls._expand(expr_format, hash_id=hash_id,
           ^^^^^^^^^^^^^^^^^^^^^^^^^^^^^^^^^^^^^^^^^
  File "/home/airflow/.local/lib/python3.12/site-packages/croniter/croniter.py", line 834, in _expand
    raise CroniterBadCronError(cls.bad_length)
croniter.croniter.CroniterBadCronError: Exactly 5, 6 or 7 columns has to be specified for iterator expression.

During handling of the above exception, another exception occurred:

Traceback (most recent call last):
  File "/home/airflow/.local/lib/python3.12/site-packages/airflow/models/dagbag.py", line 479, in _process_modules
    dag.validate()
  File "/home/airflow/.local/lib/python3.12/site-packages/airflow/models/dag.py", line 845, in validate
    self.timetable.validate()
  File "/home/airflow/.local/lib/python3.12/site-packages/airflow/timetables/_cron.py", line 104, in validate
    raise AirflowTimetableInvalid(str(e))
airflow.exceptions.AirflowTimetableInvalid: Exactly 5, 6 or 7 columns has to be specified for iterator expression.
[2025-05-30T19:23:37.096+0000] {processor.py:927} WARNING - No viable dags retrieved from /opt/airflow/dags/data_quality.py
[2025-05-30T19:23:37.240+0000] {processor.py:208} INFO - Processing /opt/airflow/dags/data_quality.py took 2.837 seconds
[2025-05-30T19:24:07.936+0000] {processor.py:186} INFO - Started process (PID=497) to work on /opt/airflow/dags/data_quality.py
[2025-05-30T19:24:07.939+0000] {processor.py:914} INFO - Processing file /opt/airflow/dags/data_quality.py for tasks to queue
[2025-05-30T19:24:07.955+0000] {logging_mixin.py:190} INFO - [2025-05-30T19:24:07.954+0000] {dagbag.py:588} INFO - Filling up the DagBag from /opt/airflow/dags/data_quality.py
[2025-05-30T19:24:09.830+0000] {logging_mixin.py:190} INFO - [2025-05-30T19:24:09.801+0000] {dagbag.py:484} ERROR - Failed to bag_dag: /opt/airflow/dags/data_quality.py
Traceback (most recent call last):
  File "/home/airflow/.local/lib/python3.12/site-packages/airflow/timetables/_cron.py", line 102, in validate
    croniter(self._expression)
  File "/home/airflow/.local/lib/python3.12/site-packages/croniter/croniter.py", line 271, in __init__
    self.expanded, self.nth_weekday_of_month = self.expand(
                                               ^^^^^^^^^^^^
  File "/home/airflow/.local/lib/python3.12/site-packages/croniter/croniter.py", line 1032, in expand
    return cls._expand(expr_format, hash_id=hash_id,
           ^^^^^^^^^^^^^^^^^^^^^^^^^^^^^^^^^^^^^^^^^
  File "/home/airflow/.local/lib/python3.12/site-packages/croniter/croniter.py", line 834, in _expand
    raise CroniterBadCronError(cls.bad_length)
croniter.croniter.CroniterBadCronError: Exactly 5, 6 or 7 columns has to be specified for iterator expression.

During handling of the above exception, another exception occurred:

Traceback (most recent call last):
  File "/home/airflow/.local/lib/python3.12/site-packages/airflow/models/dagbag.py", line 479, in _process_modules
    dag.validate()
  File "/home/airflow/.local/lib/python3.12/site-packages/airflow/models/dag.py", line 845, in validate
    self.timetable.validate()
  File "/home/airflow/.local/lib/python3.12/site-packages/airflow/timetables/_cron.py", line 104, in validate
    raise AirflowTimetableInvalid(str(e))
airflow.exceptions.AirflowTimetableInvalid: Exactly 5, 6 or 7 columns has to be specified for iterator expression.
[2025-05-30T19:24:09.845+0000] {processor.py:927} WARNING - No viable dags retrieved from /opt/airflow/dags/data_quality.py
[2025-05-30T19:24:10.005+0000] {processor.py:208} INFO - Processing /opt/airflow/dags/data_quality.py took 2.097 seconds
[2025-05-30T19:24:44.006+0000] {processor.py:186} INFO - Started process (PID=511) to work on /opt/airflow/dags/data_quality.py
[2025-05-30T19:24:44.010+0000] {processor.py:914} INFO - Processing file /opt/airflow/dags/data_quality.py for tasks to queue
[2025-05-30T19:24:44.042+0000] {logging_mixin.py:190} INFO - [2025-05-30T19:24:44.041+0000] {dagbag.py:588} INFO - Filling up the DagBag from /opt/airflow/dags/data_quality.py
[2025-05-30T19:24:46.218+0000] {logging_mixin.py:190} INFO - [2025-05-30T19:24:46.201+0000] {dagbag.py:484} ERROR - Failed to bag_dag: /opt/airflow/dags/data_quality.py
Traceback (most recent call last):
  File "/home/airflow/.local/lib/python3.12/site-packages/airflow/timetables/_cron.py", line 102, in validate
    croniter(self._expression)
  File "/home/airflow/.local/lib/python3.12/site-packages/croniter/croniter.py", line 271, in __init__
    self.expanded, self.nth_weekday_of_month = self.expand(
                                               ^^^^^^^^^^^^
  File "/home/airflow/.local/lib/python3.12/site-packages/croniter/croniter.py", line 1032, in expand
    return cls._expand(expr_format, hash_id=hash_id,
           ^^^^^^^^^^^^^^^^^^^^^^^^^^^^^^^^^^^^^^^^^
  File "/home/airflow/.local/lib/python3.12/site-packages/croniter/croniter.py", line 834, in _expand
    raise CroniterBadCronError(cls.bad_length)
croniter.croniter.CroniterBadCronError: Exactly 5, 6 or 7 columns has to be specified for iterator expression.

During handling of the above exception, another exception occurred:

Traceback (most recent call last):
  File "/home/airflow/.local/lib/python3.12/site-packages/airflow/models/dagbag.py", line 479, in _process_modules
    dag.validate()
  File "/home/airflow/.local/lib/python3.12/site-packages/airflow/models/dag.py", line 845, in validate
    self.timetable.validate()
  File "/home/airflow/.local/lib/python3.12/site-packages/airflow/timetables/_cron.py", line 104, in validate
    raise AirflowTimetableInvalid(str(e))
airflow.exceptions.AirflowTimetableInvalid: Exactly 5, 6 or 7 columns has to be specified for iterator expression.
[2025-05-30T19:24:46.219+0000] {processor.py:927} WARNING - No viable dags retrieved from /opt/airflow/dags/data_quality.py
[2025-05-30T19:24:46.305+0000] {processor.py:208} INFO - Processing /opt/airflow/dags/data_quality.py took 2.358 seconds
[2025-05-30T19:25:20.479+0000] {processor.py:186} INFO - Started process (PID=530) to work on /opt/airflow/dags/data_quality.py
[2025-05-30T19:25:20.483+0000] {processor.py:914} INFO - Processing file /opt/airflow/dags/data_quality.py for tasks to queue
[2025-05-30T19:25:20.512+0000] {logging_mixin.py:190} INFO - [2025-05-30T19:25:20.500+0000] {dagbag.py:588} INFO - Filling up the DagBag from /opt/airflow/dags/data_quality.py
[2025-05-30T19:25:23.178+0000] {logging_mixin.py:190} INFO - [2025-05-30T19:25:23.150+0000] {dagbag.py:484} ERROR - Failed to bag_dag: /opt/airflow/dags/data_quality.py
Traceback (most recent call last):
  File "/home/airflow/.local/lib/python3.12/site-packages/airflow/timetables/_cron.py", line 102, in validate
    croniter(self._expression)
  File "/home/airflow/.local/lib/python3.12/site-packages/croniter/croniter.py", line 271, in __init__
    self.expanded, self.nth_weekday_of_month = self.expand(
                                               ^^^^^^^^^^^^
  File "/home/airflow/.local/lib/python3.12/site-packages/croniter/croniter.py", line 1032, in expand
    return cls._expand(expr_format, hash_id=hash_id,
           ^^^^^^^^^^^^^^^^^^^^^^^^^^^^^^^^^^^^^^^^^
  File "/home/airflow/.local/lib/python3.12/site-packages/croniter/croniter.py", line 834, in _expand
    raise CroniterBadCronError(cls.bad_length)
croniter.croniter.CroniterBadCronError: Exactly 5, 6 or 7 columns has to be specified for iterator expression.

During handling of the above exception, another exception occurred:

Traceback (most recent call last):
  File "/home/airflow/.local/lib/python3.12/site-packages/airflow/models/dagbag.py", line 479, in _process_modules
    dag.validate()
  File "/home/airflow/.local/lib/python3.12/site-packages/airflow/models/dag.py", line 845, in validate
    self.timetable.validate()
  File "/home/airflow/.local/lib/python3.12/site-packages/airflow/timetables/_cron.py", line 104, in validate
    raise AirflowTimetableInvalid(str(e))
airflow.exceptions.AirflowTimetableInvalid: Exactly 5, 6 or 7 columns has to be specified for iterator expression.
[2025-05-30T19:25:23.181+0000] {processor.py:927} WARNING - No viable dags retrieved from /opt/airflow/dags/data_quality.py
[2025-05-30T19:25:23.311+0000] {processor.py:208} INFO - Processing /opt/airflow/dags/data_quality.py took 2.894 seconds
[2025-05-30T19:25:58.296+0000] {processor.py:186} INFO - Started process (PID=544) to work on /opt/airflow/dags/data_quality.py
[2025-05-30T19:25:58.311+0000] {processor.py:914} INFO - Processing file /opt/airflow/dags/data_quality.py for tasks to queue
[2025-05-30T19:25:58.331+0000] {logging_mixin.py:190} INFO - [2025-05-30T19:25:58.330+0000] {dagbag.py:588} INFO - Filling up the DagBag from /opt/airflow/dags/data_quality.py
[2025-05-30T19:26:01.417+0000] {logging_mixin.py:190} INFO - [2025-05-30T19:26:01.402+0000] {dagbag.py:484} ERROR - Failed to bag_dag: /opt/airflow/dags/data_quality.py
Traceback (most recent call last):
  File "/home/airflow/.local/lib/python3.12/site-packages/airflow/timetables/_cron.py", line 102, in validate
    croniter(self._expression)
  File "/home/airflow/.local/lib/python3.12/site-packages/croniter/croniter.py", line 271, in __init__
    self.expanded, self.nth_weekday_of_month = self.expand(
                                               ^^^^^^^^^^^^
  File "/home/airflow/.local/lib/python3.12/site-packages/croniter/croniter.py", line 1032, in expand
    return cls._expand(expr_format, hash_id=hash_id,
           ^^^^^^^^^^^^^^^^^^^^^^^^^^^^^^^^^^^^^^^^^
  File "/home/airflow/.local/lib/python3.12/site-packages/croniter/croniter.py", line 834, in _expand
    raise CroniterBadCronError(cls.bad_length)
croniter.croniter.CroniterBadCronError: Exactly 5, 6 or 7 columns has to be specified for iterator expression.

During handling of the above exception, another exception occurred:

Traceback (most recent call last):
  File "/home/airflow/.local/lib/python3.12/site-packages/airflow/models/dagbag.py", line 479, in _process_modules
    dag.validate()
  File "/home/airflow/.local/lib/python3.12/site-packages/airflow/models/dag.py", line 845, in validate
    self.timetable.validate()
  File "/home/airflow/.local/lib/python3.12/site-packages/airflow/timetables/_cron.py", line 104, in validate
    raise AirflowTimetableInvalid(str(e))
airflow.exceptions.AirflowTimetableInvalid: Exactly 5, 6 or 7 columns has to be specified for iterator expression.
[2025-05-30T19:26:01.434+0000] {processor.py:927} WARNING - No viable dags retrieved from /opt/airflow/dags/data_quality.py
[2025-05-30T19:26:01.555+0000] {processor.py:208} INFO - Processing /opt/airflow/dags/data_quality.py took 3.310 seconds
[2025-05-30T19:26:33.602+0000] {processor.py:186} INFO - Started process (PID=557) to work on /opt/airflow/dags/data_quality.py
[2025-05-30T19:26:33.616+0000] {processor.py:914} INFO - Processing file /opt/airflow/dags/data_quality.py for tasks to queue
[2025-05-30T19:26:33.639+0000] {logging_mixin.py:190} INFO - [2025-05-30T19:26:33.637+0000] {dagbag.py:588} INFO - Filling up the DagBag from /opt/airflow/dags/data_quality.py
[2025-05-30T19:26:37.314+0000] {logging_mixin.py:190} INFO - [2025-05-30T19:26:37.281+0000] {dagbag.py:484} ERROR - Failed to bag_dag: /opt/airflow/dags/data_quality.py
Traceback (most recent call last):
  File "/home/airflow/.local/lib/python3.12/site-packages/airflow/timetables/_cron.py", line 102, in validate
    croniter(self._expression)
  File "/home/airflow/.local/lib/python3.12/site-packages/croniter/croniter.py", line 271, in __init__
    self.expanded, self.nth_weekday_of_month = self.expand(
                                               ^^^^^^^^^^^^
  File "/home/airflow/.local/lib/python3.12/site-packages/croniter/croniter.py", line 1032, in expand
    return cls._expand(expr_format, hash_id=hash_id,
           ^^^^^^^^^^^^^^^^^^^^^^^^^^^^^^^^^^^^^^^^^
  File "/home/airflow/.local/lib/python3.12/site-packages/croniter/croniter.py", line 834, in _expand
    raise CroniterBadCronError(cls.bad_length)
croniter.croniter.CroniterBadCronError: Exactly 5, 6 or 7 columns has to be specified for iterator expression.

During handling of the above exception, another exception occurred:

Traceback (most recent call last):
  File "/home/airflow/.local/lib/python3.12/site-packages/airflow/models/dagbag.py", line 479, in _process_modules
    dag.validate()
  File "/home/airflow/.local/lib/python3.12/site-packages/airflow/models/dag.py", line 845, in validate
    self.timetable.validate()
  File "/home/airflow/.local/lib/python3.12/site-packages/airflow/timetables/_cron.py", line 104, in validate
    raise AirflowTimetableInvalid(str(e))
airflow.exceptions.AirflowTimetableInvalid: Exactly 5, 6 or 7 columns has to be specified for iterator expression.
[2025-05-30T19:26:37.359+0000] {processor.py:927} WARNING - No viable dags retrieved from /opt/airflow/dags/data_quality.py
[2025-05-30T19:26:37.771+0000] {processor.py:208} INFO - Processing /opt/airflow/dags/data_quality.py took 4.220 seconds
[2025-05-30T19:27:08.698+0000] {processor.py:186} INFO - Started process (PID=570) to work on /opt/airflow/dags/data_quality.py
[2025-05-30T19:27:08.701+0000] {processor.py:914} INFO - Processing file /opt/airflow/dags/data_quality.py for tasks to queue
[2025-05-30T19:27:08.710+0000] {logging_mixin.py:190} INFO - [2025-05-30T19:27:08.709+0000] {dagbag.py:588} INFO - Filling up the DagBag from /opt/airflow/dags/data_quality.py
[2025-05-30T19:27:10.207+0000] {logging_mixin.py:190} INFO - [2025-05-30T19:27:10.199+0000] {dagbag.py:484} ERROR - Failed to bag_dag: /opt/airflow/dags/data_quality.py
Traceback (most recent call last):
  File "/home/airflow/.local/lib/python3.12/site-packages/airflow/timetables/_cron.py", line 102, in validate
    croniter(self._expression)
  File "/home/airflow/.local/lib/python3.12/site-packages/croniter/croniter.py", line 271, in __init__
    self.expanded, self.nth_weekday_of_month = self.expand(
                                               ^^^^^^^^^^^^
  File "/home/airflow/.local/lib/python3.12/site-packages/croniter/croniter.py", line 1032, in expand
    return cls._expand(expr_format, hash_id=hash_id,
           ^^^^^^^^^^^^^^^^^^^^^^^^^^^^^^^^^^^^^^^^^
  File "/home/airflow/.local/lib/python3.12/site-packages/croniter/croniter.py", line 834, in _expand
    raise CroniterBadCronError(cls.bad_length)
croniter.croniter.CroniterBadCronError: Exactly 5, 6 or 7 columns has to be specified for iterator expression.

During handling of the above exception, another exception occurred:

Traceback (most recent call last):
  File "/home/airflow/.local/lib/python3.12/site-packages/airflow/models/dagbag.py", line 479, in _process_modules
    dag.validate()
  File "/home/airflow/.local/lib/python3.12/site-packages/airflow/models/dag.py", line 845, in validate
    self.timetable.validate()
  File "/home/airflow/.local/lib/python3.12/site-packages/airflow/timetables/_cron.py", line 104, in validate
    raise AirflowTimetableInvalid(str(e))
airflow.exceptions.AirflowTimetableInvalid: Exactly 5, 6 or 7 columns has to be specified for iterator expression.
[2025-05-30T19:27:10.208+0000] {processor.py:927} WARNING - No viable dags retrieved from /opt/airflow/dags/data_quality.py
[2025-05-30T19:27:10.323+0000] {processor.py:208} INFO - Processing /opt/airflow/dags/data_quality.py took 1.650 seconds
[2025-05-30T19:27:40.809+0000] {processor.py:186} INFO - Started process (PID=583) to work on /opt/airflow/dags/data_quality.py
[2025-05-30T19:27:40.812+0000] {processor.py:914} INFO - Processing file /opt/airflow/dags/data_quality.py for tasks to queue
[2025-05-30T19:27:40.820+0000] {logging_mixin.py:190} INFO - [2025-05-30T19:27:40.819+0000] {dagbag.py:588} INFO - Filling up the DagBag from /opt/airflow/dags/data_quality.py
[2025-05-30T19:27:42.140+0000] {logging_mixin.py:190} INFO - [2025-05-30T19:27:42.134+0000] {dagbag.py:484} ERROR - Failed to bag_dag: /opt/airflow/dags/data_quality.py
Traceback (most recent call last):
  File "/home/airflow/.local/lib/python3.12/site-packages/airflow/timetables/_cron.py", line 102, in validate
    croniter(self._expression)
  File "/home/airflow/.local/lib/python3.12/site-packages/croniter/croniter.py", line 271, in __init__
    self.expanded, self.nth_weekday_of_month = self.expand(
                                               ^^^^^^^^^^^^
  File "/home/airflow/.local/lib/python3.12/site-packages/croniter/croniter.py", line 1032, in expand
    return cls._expand(expr_format, hash_id=hash_id,
           ^^^^^^^^^^^^^^^^^^^^^^^^^^^^^^^^^^^^^^^^^
  File "/home/airflow/.local/lib/python3.12/site-packages/croniter/croniter.py", line 834, in _expand
    raise CroniterBadCronError(cls.bad_length)
croniter.croniter.CroniterBadCronError: Exactly 5, 6 or 7 columns has to be specified for iterator expression.

During handling of the above exception, another exception occurred:

Traceback (most recent call last):
  File "/home/airflow/.local/lib/python3.12/site-packages/airflow/models/dagbag.py", line 479, in _process_modules
    dag.validate()
  File "/home/airflow/.local/lib/python3.12/site-packages/airflow/models/dag.py", line 845, in validate
    self.timetable.validate()
  File "/home/airflow/.local/lib/python3.12/site-packages/airflow/timetables/_cron.py", line 104, in validate
    raise AirflowTimetableInvalid(str(e))
airflow.exceptions.AirflowTimetableInvalid: Exactly 5, 6 or 7 columns has to be specified for iterator expression.
[2025-05-30T19:27:42.142+0000] {processor.py:927} WARNING - No viable dags retrieved from /opt/airflow/dags/data_quality.py
[2025-05-30T19:27:42.186+0000] {processor.py:208} INFO - Processing /opt/airflow/dags/data_quality.py took 1.393 seconds
[2025-05-30T19:28:13.327+0000] {processor.py:186} INFO - Started process (PID=596) to work on /opt/airflow/dags/data_quality.py
[2025-05-30T19:28:13.330+0000] {processor.py:914} INFO - Processing file /opt/airflow/dags/data_quality.py for tasks to queue
[2025-05-30T19:28:13.340+0000] {logging_mixin.py:190} INFO - [2025-05-30T19:28:13.338+0000] {dagbag.py:588} INFO - Filling up the DagBag from /opt/airflow/dags/data_quality.py
[2025-05-30T19:28:14.132+0000] {logging_mixin.py:190} INFO - [2025-05-30T19:28:14.124+0000] {dagbag.py:484} ERROR - Failed to bag_dag: /opt/airflow/dags/data_quality.py
Traceback (most recent call last):
  File "/home/airflow/.local/lib/python3.12/site-packages/airflow/timetables/_cron.py", line 102, in validate
    croniter(self._expression)
  File "/home/airflow/.local/lib/python3.12/site-packages/croniter/croniter.py", line 271, in __init__
    self.expanded, self.nth_weekday_of_month = self.expand(
                                               ^^^^^^^^^^^^
  File "/home/airflow/.local/lib/python3.12/site-packages/croniter/croniter.py", line 1032, in expand
    return cls._expand(expr_format, hash_id=hash_id,
           ^^^^^^^^^^^^^^^^^^^^^^^^^^^^^^^^^^^^^^^^^
  File "/home/airflow/.local/lib/python3.12/site-packages/croniter/croniter.py", line 834, in _expand
    raise CroniterBadCronError(cls.bad_length)
croniter.croniter.CroniterBadCronError: Exactly 5, 6 or 7 columns has to be specified for iterator expression.

During handling of the above exception, another exception occurred:

Traceback (most recent call last):
  File "/home/airflow/.local/lib/python3.12/site-packages/airflow/models/dagbag.py", line 479, in _process_modules
    dag.validate()
  File "/home/airflow/.local/lib/python3.12/site-packages/airflow/models/dag.py", line 845, in validate
    self.timetable.validate()
  File "/home/airflow/.local/lib/python3.12/site-packages/airflow/timetables/_cron.py", line 104, in validate
    raise AirflowTimetableInvalid(str(e))
airflow.exceptions.AirflowTimetableInvalid: Exactly 5, 6 or 7 columns has to be specified for iterator expression.
[2025-05-30T19:28:14.133+0000] {processor.py:927} WARNING - No viable dags retrieved from /opt/airflow/dags/data_quality.py
[2025-05-30T19:28:14.198+0000] {processor.py:208} INFO - Processing /opt/airflow/dags/data_quality.py took 0.889 seconds
[2025-05-30T19:28:45.117+0000] {processor.py:186} INFO - Started process (PID=609) to work on /opt/airflow/dags/data_quality.py
[2025-05-30T19:28:45.119+0000] {processor.py:914} INFO - Processing file /opt/airflow/dags/data_quality.py for tasks to queue
[2025-05-30T19:28:45.132+0000] {logging_mixin.py:190} INFO - [2025-05-30T19:28:45.131+0000] {dagbag.py:588} INFO - Filling up the DagBag from /opt/airflow/dags/data_quality.py
[2025-05-30T19:28:46.131+0000] {logging_mixin.py:190} INFO - [2025-05-30T19:28:46.123+0000] {dagbag.py:484} ERROR - Failed to bag_dag: /opt/airflow/dags/data_quality.py
Traceback (most recent call last):
  File "/home/airflow/.local/lib/python3.12/site-packages/airflow/timetables/_cron.py", line 102, in validate
    croniter(self._expression)
  File "/home/airflow/.local/lib/python3.12/site-packages/croniter/croniter.py", line 271, in __init__
    self.expanded, self.nth_weekday_of_month = self.expand(
                                               ^^^^^^^^^^^^
  File "/home/airflow/.local/lib/python3.12/site-packages/croniter/croniter.py", line 1032, in expand
    return cls._expand(expr_format, hash_id=hash_id,
           ^^^^^^^^^^^^^^^^^^^^^^^^^^^^^^^^^^^^^^^^^
  File "/home/airflow/.local/lib/python3.12/site-packages/croniter/croniter.py", line 834, in _expand
    raise CroniterBadCronError(cls.bad_length)
croniter.croniter.CroniterBadCronError: Exactly 5, 6 or 7 columns has to be specified for iterator expression.

During handling of the above exception, another exception occurred:

Traceback (most recent call last):
  File "/home/airflow/.local/lib/python3.12/site-packages/airflow/models/dagbag.py", line 479, in _process_modules
    dag.validate()
  File "/home/airflow/.local/lib/python3.12/site-packages/airflow/models/dag.py", line 845, in validate
    self.timetable.validate()
  File "/home/airflow/.local/lib/python3.12/site-packages/airflow/timetables/_cron.py", line 104, in validate
    raise AirflowTimetableInvalid(str(e))
airflow.exceptions.AirflowTimetableInvalid: Exactly 5, 6 or 7 columns has to be specified for iterator expression.
[2025-05-30T19:28:46.132+0000] {processor.py:927} WARNING - No viable dags retrieved from /opt/airflow/dags/data_quality.py
[2025-05-30T19:28:46.195+0000] {processor.py:208} INFO - Processing /opt/airflow/dags/data_quality.py took 1.103 seconds
